Workbook

Sheet Data 
A1: Product_ID | B1: Product_Name | C1: Category | D1: Sub_Category | E1: Brand | F1: Cost | G1: Stock
A2: PROD0 | B2: Brother Laser Printer | C2: Electronics | D2: Computer | E2: Hunt Inc | F2: 112.42 | G2: 416
A3: PROD1 | B3: Men's Graphic T-Shirt | C3: Clothing | D3: Tops | E3: Terry-Moore | F3: 342.56 | G3: 181
A4: PROD2 | B4: Women's Casual Hoodie | C4: Clothing | D4: Outerwear | E4: Sims Inc | G4: 352
A5: P-3 | B5: Men's Running Jacket | C5: Clothing | D5: Outerwear | E5: Pineda Ltd | F5: 364.67 | G5: 452
A6: PROD4 | B6: Women's Yoga Pants | C6: Clothing | D6: Bottoms | E6: Gonzales-Davis | F6: 306.46 | G6: 487
A7: PROD5 | B7: Men's Leather Belt | C7: Clothing | D7: Accessories | E7: Baldwin, Garza and Gonzalez | F7: 261 | G7: 59
A8: PROD6 | B8: Herbal Face Moisturizer | C8: Beauty | D8: Skincare | E8: Davidson PLC | F8: 312.8 | G8: 350
A9: PROD7 | B9: LED Table Lamp | C9: Home | D9: Lighting | E9: Harrell LLC | F9: 218.86 | G9: 170
A10: PROD8 | B10: Wireless Bluetooth Earbuds | C10: Electronics | D10: Audio | E10: Perez-Johnston | F10: 439.07 | G10: 142
A11: PROD9 | B11: Adjustable Dumbbell Set | C11: Sports | D11: Fitness | E11: Hill PLC | F11: 495.72 | G11: 323
A12: PROD10 | B12: Ceramic Kitchen Bowl Set | C12: Home | D12: Kitchen | E12: Hamilton Group | F12: 298.86 | G12: 308
A13: PROD11 | B13: HD Smart TV Stick | C13: Electronics | D13: Accessories | E13: Gibson, Hobbs and Weaver | F13: 449.4
A14: PROD12 | B14: Hair Strengthening Shampoo | C14: Beauty | D14: Haircare | E14: Rice LLC | F14: 115.82 | G14: 460
A15: PROD13 | B15: USB-C Fast Charger | C15: Electronics | D15: Accessories | E15: Dawson-Perkins | F15: 242.23 | G15: 453
A16: PROD14 | B16: Decorative Wall Mirror | C16: Home | D16: Decor | E16: Luna, Anderson and Bowman | F16: 48.01 | G16: 439
A17: PROD15 | B17: 4K Home Projector | C17: Electronics | D17: Appliances | E17: Thomas LLC | F17: 465.34 | G17: 301
A18: P-16 | B18: Beard Grooming Kit | C18: Beauty | D18: Grooming | E18: Erickson-Green | F18: 337.42 | G18: 256
A19: PROD17 | B19: Soccer Training Cone Set | C19: Sports | D19: Accessories | E19: Ford, Murphy and Wilson | F19: 144.53 | G19: 367
A20: PROD18 | B20: Women's Denim Jeans | C20: Clothing | D20: Bottoms | E20: Guerra-Hendrix | G20: 343
A21: PROD19 | B21: Knee Support Brace | C21: Sports | D21: Equipment | E21: May-Reese | F21: 21.34 | G21: 65
A22: PROD20 | B22: Outdoor Sports Water Bottle | C22: Sports | D22: Accessories | E22: Soto-Ellis | F22: 131.51
A23: PROD21 | B23: Multi-Purpose Storage Box | C23: Home | D23: Storage | E23: Gardner-Montes | F23: 123.46 | G23: 76
A24: PROD22 | B24: Carbon Fiber Tennis Racket | C24: Sports | D24: Equipment | E24: Flores, Pineda and Rodriguez | F24: 484.62 | G24: 432
A25: PROD23 | B25: Men's Formal Shirt | C25: Clothing | D25: Tops | E25: Moon, Mora and Santos | G25: 360
A26: PROD24 | B26: Foldable Camping Chair | C26: Sports | D26: Outdoor | E26: Cook Ltd | F26: 166.06 | G26: 340
A27: PROD25 | B27: Women's Scarf Set | C27: Clothing | D27: Accessories | E27: Brown and Sons | F27: 174.02 | G27: 268
A28: PROD26 | B28: Wireless Bluetooth Speaker | C28: Electronics | D28: Audio | E28: Reed-Schmidt | F28: 322.41 | G28: 213
A29: PROD27 | B29: Decorative Floor Vase | C29: Home | D29: Decor | E29: Khan, Jones and Paul | G29: 378
A30: PROD28 | B30: Sports Stopwatch Timer | C30: Sports | D30: Accessories | E30: Burns-Hansen | F30: 38.76 | G30: 137
A31: PROD29 | B31: Fabric Sofa Throw Blanket | C31: Home | D31: Decor | E31: Hoffman Group | F31: 218.48 | G31: 276
A32: PROD30 | B32: Stainless Steel Cutlery Set | C32: Home | D32: Kitchen | E32: Stevens, Fernandez and Martin | F32: 19.52 | G32: 57
A33: PROD31 | B33: Basketball | C33: Sports | D33: Team Sports | E33: Nolan-Snow | F33: 204.39 | G33: 281
A34: PROD32 | B34: Vitamin C Face Serum | C34: Beauty | D34: Skincare | E34: Griffin Ltd | F34: 283.83 | G34: 244
A35: PROD33 | B35: Modern Wall Clock | C35: Home | D35: Decor | E35: Weiss-Watson | F35: 179.77 | G35: 305
A36: PROD34 | B36: Gaming Mechanical Keyboard | C36: Electronics | D36: Computer | E36: Lucero LLC | F36: 419.28 | G36: 86
A37: PROD35 | B37: Bedroom Table Lamp | C37: Home | D37: Lighting | E37: Jones LLC | F37: 382.22 | G37: 329
A38: PROD36 | B38: Women's Summer Dress | C38: Clothing | D38: Tops | E38: Smith-Mills | F38: 223.43 | G38: 154
A39: PROD37 | B39: Men's Casual Sneakers | C39: Clothing | D39: Footwear | E39: Hogan-Lee | F39: 353.47 | G39: 214
A40: PROD38 | B40: Sports Water Hydration Pack | C40: Sports | D40: Outdoor | E40: Sims-Smith | F40: 135.61 | G40: 394
...

Sheet Data cleaning
A1: 2 | B1: find/remove duplicates - No duplicate / 1 replaced | F1: validate data | G1: handle missing/inconsistent data
A3: Product_ID | B3: Product_Name | C3: Category | D3: Sub_Category | E3: Brand | F3: Cost | G3: Stock | I3: {=TRIM(Table13[#All])} -> Product_ID | J3: Product_Name | K3: Category | L3: Sub_Category | M3: Brand | N3: Cost | O3: Stock | Q3: {=UPPER(Table13[#All])} -> PRODUCT_ID | R3: PRODUCT_NAME | S3: CATEGORY | T3: SUB_CATEGORY | U3: BRAND | V3: COST | W3: STOCK | Y3: {=PROPER(Table13[#All])} -> Product_Id | Z3: Product_Name | AA3: Category | AB3: Sub_Category | AC3: Brand | AD3: Cost | AE3: Stock
A4: PROD0 | B4: Brother Laser Printer | C4: Electronics | D4: Computer | E4: Hunt Inc | F4: 112.42 | G4: 416 | I4: PROD0 | J4: Brother Laser Printer | K4: Electronics | L4: Computer | M4: Hunt Inc | N4: 112.42 | O4: 416 | Q4: PROD0 | R4: BROTHER LASER PRINTER | S4: ELECTRONICS | T4: COMPUTER | U4: HUNT INC | V4: 112.42 | W4: 416 | Y4: Prod0 | Z4: Brother Laser Printer | AA4: Electronics | AB4: Computer | AC4: Hunt Inc | AD4: 112.42 | AE4: 416
A5: PROD1 | B5: Men's Graphic T-Shirt | C5: Clothing | D5: Tops | E5: Terry-Moore | F5: 342.56 | G5: 181 | I5: PROD1 | J5: Men's Graphic T-Shirt | K5: Clothing | L5: Tops | M5: Terry-Moore | N5: 342.56 | O5: 181 | Q5: PROD1 | R5: MEN'S GRAPHIC T-SHIRT | S5: CLOTHING | T5: TOPS | U5: TERRY-MOORE | V5: 342.56 | W5: 181 | Y5: Prod1 | Z5: Men'S Graphic T-Shirt | AA5: Clothing | AB5: Tops | AC5: Terry-Moore | AD5: 342.56 | AE5: 181
A6: PROD2 | B6: Women's Casual Hoodie | C6: Clothing | D6: Outerwear | E6: Sims Inc | G6: 352 | I6: PROD2 | J6: Women's Casual Hoodie | K6: Clothing | L6: Outerwear | M6: Sims Inc | O6: 352 | Q6: PROD2 | R6: WOMEN'S CASUAL HOODIE | S6: CLOTHING | T6: OUTERWEAR | U6: SIMS INC | W6: 352 | Y6: Prod2 | Z6: Women'S Casual Hoodie | AA6: Clothing | AB6: Outerwear | AC6: Sims Inc | AE6: 352
A7: PROD3 | B7: Men's Running Jacket | C7: Clothing | D7: Outerwear | E7: Pineda Ltd | F7: 364.67 | G7: 452 | I7: PROD3 | J7: Men's Running Jacket | K7: Clothing | L7: Outerwear | M7: Pineda Ltd | N7: 364.67 | O7: 452 | Q7: PROD3 | R7: MEN'S RUNNING JACKET | S7: CLOTHING | T7: OUTERWEAR | U7: PINEDA LTD | V7: 364.67 | W7: 452 | Y7: Prod3 | Z7: Men'S Running Jacket | AA7: Clothing | AB7: Outerwear | AC7: Pineda Ltd | AD7: 364.67 | AE7: 452
A8: PROD4 | B8: Women's Yoga Pants | C8: Clothing | D8: Bottoms | E8: Gonzales-Davis | F8: 306.46 | G8: 487 | I8: PROD4 | J8: Women's Yoga Pants | K8: Clothing | L8: Bottoms | M8: Gonzales-Davis | N8: 306.46 | O8: 487 | Q8: PROD4 | R8: WOMEN'S YOGA PANTS | S8: CLOTHING | T8: BOTTOMS | U8: GONZALES-DAVIS | V8: 306.46 | W8: 487 | Y8: Prod4 | Z8: Women'S Yoga Pants | AA8: Clothing | AB8: Bottoms | AC8: Gonzales-Davis | AD8: 306.46 | AE8: 487
A9: PROD5 | B9: Men's Leather Belt | C9: Clothing | D9: Accessories | E9: Baldwin, Garza and Gonzalez | F9: 261 | G9: 59 | I9: PROD5 | J9: Men's Leather Belt | K9: Clothing | L9: Accessories | M9: Baldwin, Garza and Gonzalez | N9: 261 | O9: 59 | Q9: PROD5 | R9: MEN'S LEATHER BELT | S9: CLOTHING | T9: ACCESSORIES | U9: BALDWIN, GARZA AND GONZALEZ | V9: 261 | W9: 59 | Y9: Prod5 | Z9: Men'S Leather Belt | AA9: Clothing | AB9: Accessories | AC9: Baldwin, Garza And Gonzalez | AD9: 261 | AE9: 59
A10: PROD6 | B10: Herbal Face Moisturizer | C10: Beauty | D10: Skincare | E10: Davidson PLC | F10: 312.8 | G10: 350 | I10: PROD6 | J10: Herbal Face Moisturizer | K10: Beauty | L10: Skincare | M10: Davidson PLC | N10: 312.8 | O10: 350 | Q10: PROD6 | R10: HERBAL FACE MOISTURIZER | S10: BEAUTY | T10: SKINCARE | U10: DAVIDSON PLC | V10: 312.8 | W10: 350 | Y10: Prod6 | Z10: Herbal Face Moisturizer | AA10: Beauty | AB10: Skincare | AC10: Davidson Plc | AD10: 312.8 | AE10: 350
A11: PROD7 | B11: LED Table Lamp | C11: Home | D11: Lighting | E11: Harrell LLC | F11: 218.86 | G11: 170 | I11: PROD7 | J11: LED Table Lamp | K11: Home | L11: Lighting | M11: Harrell LLC | N11: 218.86 | O11: 170 | Q11: PROD7 | R11: LED TABLE LAMP | S11: HOME | T11: LIGHTING | U11: HARRELL LLC | V11: 218.86 | W11: 170 | Y11: Prod7 | Z11: Led Table Lamp | AA11: Home | AB11: Lighting | AC11: Harrell Llc | AD11: 218.86 | AE11: 170
A12: PROD8 | B12: Wireless Bluetooth Earbuds | C12: Electronics | D12: Audio | E12: Perez-Johnston | F12: 439.07 | G12: 142 | I12: PROD8 | J12: Wireless Bluetooth Earbuds | K12: Electronics | L12: Audio | M12: Perez-Johnston | N12: 439.07 | O12: 142 | Q12: PROD8 | R12: WIRELESS BLUETOOTH EARBUDS | S12: ELECTRONICS | T12: AUDIO | U12: PEREZ-JOHNSTON | V12: 439.07 | W12: 142 | Y12: Prod8 | Z12: Wireless Bluetooth Earbuds | AA12: Electronics | AB12: Audio | AC12: Perez-Johnston | AD12: 439.07 | AE12: 142
A13: PROD9 | B13: Adjustable Dumbbell Set | C13: Sports | D13: Fitness | E13: Hill PLC | F13: 495.72 | G13: 323 | I13: PROD9 | J13: Adjustable Dumbbell Set | K13: Sports | L13: Fitness | M13: Hill PLC | N13: 495.72 | O13: 323 | Q13: PROD9 | R13: ADJUSTABLE DUMBBELL SET | S13: SPORTS | T13: FITNESS | U13: HILL PLC | V13: 495.72 | W13: 323 | Y13: Prod9 | Z13: Adjustable Dumbbell Set | AA13: Sports | AB13: Fitness | AC13: Hill Plc | AD13: 495.72 | AE13: 323
A14: PROD10 | B14: Ceramic Kitchen Bowl Set | C14: Home | D14: Kitchen | E14: Hamilton Group | F14: 298.86 | G14: 308 | I14: PROD10 | J14: Ceramic Kitchen Bowl Set | K14: Home | L14: Kitchen | M14: Hamilton Group | N14: 298.86 | O14: 308 | Q14: PROD10 | R14: CERAMIC KITCHEN BOWL SET | S14: HOME | T14: KITCHEN | U14: HAMILTON GROUP | V14: 298.86 | W14: 308 | Y14: Prod10 | Z14: Ceramic Kitchen Bowl Set | AA14: Home | AB14: Kitchen | AC14: Hamilton Group | AD14: 298.86 | AE14: 308
A15: PROD11 | B15: HD Smart TV Stick | C15: Electronics | D15: Accessories | E15: Gibson, Hobbs and Weaver | F15: 449.4 | I15: PROD11 | J15: HD Smart TV Stick | K15: Electronics | L15: Accessories | M15: Gibson, Hobbs and Weaver | N15: 449.4 | Q15: PROD11 | R15: HD SMART TV STICK | S15: ELECTRONICS | T15: ACCESSORIES | U15: GIBSON, HOBBS AND WEAVER | V15: 449.4 | Y15: Prod11 | Z15: Hd Smart Tv Stick | AA15: Electronics | AB15: Accessories | AC15: Gibson, Hobbs And Weaver | AD15: 449.4
A16: PROD12 | B16: Hair Strengthening Shampoo | C16: Beauty | D16: Haircare | E16: Rice LLC | F16: 115.82 | G16: 460 | I16: PROD12 | J16: Hair Strengthening Shampoo | K16: Beauty | L16: Haircare | M16: Rice LLC | N16: 115.82 | O16: 460 | Q16: PROD12 | R16: HAIR STRENGTHENING SHAMPOO | S16: BEAUTY | T16: HAIRCARE | U16: RICE LLC | V16: 115.82 | W16: 460 | Y16: Prod12 | Z16: Hair Strengthening Shampoo | AA16: Beauty | AB16: Haircare | AC16: Rice Llc | AD16: 115.82 | AE16: 460
A17: PROD13 | B17: USB-C Fast Charger | C17: Electronics | D17: Accessories | E17: Dawson-Perkins | F17: 242.23 | G17: 453 | I17: PROD13 | J17: USB-C Fast Charger | K17: Electronics | L17: Accessories | M17: Dawson-Perkins | N17: 242.23 | O17: 453 | Q17: PROD13 | R17: USB-C FAST CHARGER | S17: ELECTRONICS | T17: ACCESSORIES | U17: DAWSON-PERKINS | V17: 242.23 | W17: 453 | Y17: Prod13 | Z17: Usb-C Fast Charger | AA17: Electronics | AB17: Accessories | AC17: Dawson-Perkins | AD17: 242.23 | AE17: 453
A18: PROD14 | B18: Decorative Wall Mirror | C18: Home | D18: Decor | E18: Luna, Anderson and Bowman | F18: 48.01 | G18: 439 | I18: PROD14 | J18: Decorative Wall Mirror | K18: Home | L18: Decor | M18: Luna, Anderson and Bowman | N18: 48.01 | O18: 439 | Q18: PROD14 | R18: DECORATIVE WALL MIRROR | S18: HOME | T18: DECOR | U18: LUNA, ANDERSON AND BOWMAN | V18: 48.01 | W18: 439 | Y18: Prod14 | Z18: Decorative Wall Mirror | AA18: Home | AB18: Decor | AC18: Luna, Anderson And Bowman | AD18: 48.01 | AE18: 439
A19: PROD15 | B19: 4K Home Projector | C19: Electronics | D19: Appliances | E19: Thomas LLC | F19: 465.34 | G19: 301 | I19: PROD15 | J19: 4K Home Projector | K19: Electronics | L19: Appliances | M19: Thomas LLC | N19: 465.34 | O19: 301 | Q19: PROD15 | R19: 4K HOME PROJECTOR | S19: ELECTRONICS | T19: APPLIANCES | U19: THOMAS LLC | V19: 465.34 | W19: 301 | Y19: Prod15 | Z19: 4K Home Projector | AA19: Electronics | AB19: Appliances | AC19: Thomas Llc | AD19: 465.34 | AE19: 301
A20: PROD16 | B20: Beard Grooming Kit | C20: Beauty | D20: Grooming | E20: Erickson-Green | F20: 337.42 | G20: 256 | I20: PROD16 | J20: Beard Grooming Kit | K20: Beauty | L20: Grooming | M20: Erickson-Green | N20: 337.42 | O20: 256 | Q20: PROD16 | R20: BEARD GROOMING KIT | S20: BEAUTY | T20: GROOMING | U20: ERICKSON-GREEN | V20: 337.42 | W20: 256 | Y20: Prod16 | Z20: Beard Grooming Kit | AA20: Beauty | AB20: Grooming | AC20: Erickson-Green | AD20: 337.42 | AE20: 256
A21: PROD17 | B21: Soccer Training Cone Set | C21: Sports | D21: Accessories | E21: Ford, Murphy and Wilson | F21: 144.53 | G21: 367 | I21: PROD17 | J21: Soccer Training Cone Set | K21: Sports | L21: Accessories | M21: Ford, Murphy and Wilson | N21: 144.53 | O21: 367 | Q21: PROD17 | R21: SOCCER TRAINING CONE SET | S21: SPORTS | T21: ACCESSORIES | U21: FORD, MURPHY AND WILSON | V21: 144.53 | W21: 367 | Y21: Prod17 | Z21: Soccer Training Cone Set | AA21: Sports | AB21: Accessories | AC21: Ford, Murphy And Wilson | AD21: 144.53 | AE21: 367
A22: PROD18 | B22: Women's Denim Jeans | C22: Clothing | D22: Bottoms | E22: Guerra-Hendrix | G22: 343 | I22: PROD18 | J22: Women's Denim Jeans | K22: Clothing | L22: Bottoms | M22: Guerra-Hendrix | O22: 343 | Q22: PROD18 | R22: WOMEN'S DENIM JEANS | S22: CLOTHING | T22: BOTTOMS | U22: GUERRA-HENDRIX | W22: 343 | Y22: Prod18 | Z22: Women'S Denim Jeans | AA22: Clothing | AB22: Bottoms | AC22: Guerra-Hendrix | AE22: 343
A23: PROD19 | B23: Knee Support Brace | C23: Sports | D23: Equipment | E23: May-Reese | F23: 21.34 | G23: 65 | I23: PROD19 | J23: Knee Support Brace | K23: Sports | L23: Equipment | M23: May-Reese | N23: 21.34 | O23: 65 | Q23: PROD19 | R23: KNEE SUPPORT BRACE | S23: SPORTS | T23: EQUIPMENT | U23: MAY-REESE | V23: 21.34 | W23: 65 | Y23: Prod19 | Z23: Knee Support Brace | AA23: Sports | AB23: Equipment | AC23: May-Reese | AD23: 21.34 | AE23: 65
A24: PROD20 | B24: Outdoor Sports Water Bottle | C24: Sports | D24: Accessories | E24: Soto-Ellis | F24: 131.51 | I24: PROD20 | J24: Outdoor Sports Water Bottle | K24: Sports | L24: Accessories | M24: Soto-Ellis | N24: 131.51 | Q24: PROD20 | R24: OUTDOOR SPORTS WATER BOTTLE | S24: SPORTS | T24: ACCESSORIES | U24: SOTO-ELLIS | V24: 131.51 | Y24: Prod20 | Z24: Outdoor Sports Water Bottle | AA24: Sports | AB24: Accessories | AC24: Soto-Ellis | AD24: 131.51
A25: PROD21 | B25: Multi-Purpose Storage Box | C25: Home | D25: Storage | E25: Gardner-Montes | F25: 123.46 | G25: 76 | I25: PROD21 | J25: Multi-Purpose Storage Box | K25: Home | L25: Storage | M25: Gardner-Montes | N25: 123.46 | O25: 76 | Q25: PROD21 | R25: MULTI-PURPOSE STORAGE BOX | S25: HOME | T25: STORAGE | U25: GARDNER-MONTES | V25: 123.46 | W25: 76 | Y25: Prod21 | Z25: Multi-Purpose Storage Box | AA25: Home | AB25: Storage | AC25: Gardner-Montes | AD25: 123.46 | AE25: 76
A26: PROD22 | B26: Carbon Fiber Tennis Racket | C26: Sports | D26: Equipment | E26: Flores, Pineda and Rodriguez | F26: 484.62 | G26: 432 | I26: PROD22 | J26: Carbon Fiber Tennis Racket | K26: Sports | L26: Equipment | M26: Flores, Pineda and Rodriguez | N26: 484.62 | O26: 432 | Q26: PROD22 | R26: CARBON FIBER TENNIS RACKET | S26: SPORTS | T26: EQUIPMENT | U26: FLORES, PINEDA AND RODRIGUEZ | V26: 484.62 | W26: 432 | Y26: Prod22 | Z26: Carbon Fiber Tennis Racket | AA26: Sports | AB26: Equipment | AC26: Flores, Pineda And Rodriguez | AD26: 484.62 | AE26: 432
A27: PROD23 | B27: Men's Formal Shirt | C27: Clothing | D27: Tops | E27: Moon, Mora and Santos | G27: 360 | I27: PROD23 | J27: Men's Formal Shirt | K27: Clothing | L27: Tops | M27: Moon, Mora and Santos | O27: 360 | Q27: PROD23 | R27: MEN'S FORMAL SHIRT | S27: CLOTHING | T27: TOPS | U27: MOON, MORA AND SANTOS | W27: 360 | Y27: Prod23 | Z27: Men'S Formal Shirt | AA27: Clothing | AB27: Tops | AC27: Moon, Mora And Santos | AE27: 360
A28: PROD24 | B28: Foldable Camping Chair | C28: Sports | D28: Outdoor | E28: Cook Ltd | F28: 166.06 | G28: 340 | I28: PROD24 | J28: Foldable Camping Chair | K28: Sports | L28: Outdoor | M28: Cook Ltd | N28: 166.06 | O28: 340 | Q28: PROD24 | R28: FOLDABLE CAMPING CHAIR | S28: SPORTS | T28: OUTDOOR | U28: COOK LTD | V28: 166.06 | W28: 340 | Y28: Prod24 | Z28: Foldable Camping Chair | AA28: Sports | AB28: Outdoor | AC28: Cook Ltd | AD28: 166.06 | AE28: 340
A29: PROD25 | B29: Women's Scarf Set | C29: Clothing | D29: Accessories | E29: Brown and Sons | F29: 174.02 | G29: 268 | I29: PROD25 | J29: Women's Scarf Set | K29: Clothing | L29: Accessories | M29: Brown and Sons | N29: 174.02 | O29: 268 | Q29: PROD25 | R29: WOMEN'S SCARF SET | S29: CLOTHING | T29: ACCESSORIES | U29: BROWN AND SONS | V29: 174.02 | W29: 268 | Y29: Prod25 | Z29: Women'S Scarf Set | AA29: Clothing | AB29: Accessories | AC29: Brown And Sons | AD29: 174.02 | AE29: 268
A30: PROD26 | B30: Wireless Bluetooth Speaker | C30: Electronics | D30: Audio | E30: Reed-Schmidt | F30: 322.41 | G30: 213 | I30: PROD26 | J30: Wireless Bluetooth Speaker | K30: Electronics | L30: Audio | M30: Reed-Schmidt | N30: 322.41 | O30: 213 | Q30: PROD26 | R30: WIRELESS BLUETOOTH SPEAKER | S30: ELECTRONICS | T30: AUDIO | U30: REED-SCHMIDT | V30: 322.41 | W30: 213 | Y30: Prod26 | Z30: Wireless Bluetooth Speaker | AA30: Electronics | AB30: Audio | AC30: Reed-Schmidt | AD30: 322.41 | AE30: 213
A31: PROD27 | B31: Decorative Floor Vase | C31: Home | D31: Decor | E31: Khan, Jones and Paul | G31: 378 | I31: PROD27 | J31: Decorative Floor Vase | K31: Home | L31: Decor | M31: Khan, Jones and Paul | O31: 378 | Q31: PROD27 | R31: DECORATIVE FLOOR VASE | S31: HOME | T31: DECOR | U31: KHAN, JONES AND PAUL | W31: 378 | Y31: Prod27 | Z31: Decorative Floor Vase | AA31: Home | AB31: Decor | AC31: Khan, Jones And Paul | AE31: 378
A32: PROD28 | B32: Sports Stopwatch Timer | C32: Sports | D32: Accessories | E32: Burns-Hansen | F32: 38.76 | G32: 137 | I32: PROD28 | J32: Sports Stopwatch Timer | K32: Sports | L32: Accessories | M32: Burns-Hansen | N32: 38.76 | O32: 137 | Q32: PROD28 | R32: SPORTS STOPWATCH TIMER | S32: SPORTS | T32: ACCESSORIES | U32: BURNS-HANSEN | V32: 38.76 | W32: 137 | Y32: Prod28 | Z32: Sports Stopwatch Timer | AA32: Sports | AB32: Accessories | AC32: Burns-Hansen | AD32: 38.76 | AE32: 137
A33: PROD29 | B33: Fabric Sofa Throw Blanket | C33: Home | D33: Decor | E33: Hoffman Group | F33: 218.48 | G33: 276 | I33: PROD29 | J33: Fabric Sofa Throw Blanket | K33: Home | L33: Decor | M33: Hoffman Group | N33: 218.48 | O33: 276 | Q33: PROD29 | R33: FABRIC SOFA THROW BLANKET | S33: HOME | T33: DECOR | U33: HOFFMAN GROUP | V33: 218.48 | W33: 276 | Y33: Prod29 | Z33: Fabric Sofa Throw Blanket | AA33: Home | AB33: Decor | AC33: Hoffman Group | AD33: 218.48 | AE33: 276
A34: PROD30 | B34: Stainless Steel Cutlery Set | C34: Home | D34: Kitchen | E34: Stevens, Fernandez and Martin | F34: 19.52 | G34: 57 | I34: PROD30 | J34: Stainless Steel Cutlery Set | K34: Home | L34: Kitchen | M34: Stevens, Fernandez and Martin | N34: 19.52 | O34: 57 | Q34: PROD30 | R34: STAINLESS STEEL CUTLERY SET | S34: HOME | T34: KITCHEN | U34: STEVENS, FERNANDEZ AND MARTIN | V34: 19.52 | W34: 57 | Y34: Prod30 | Z34: Stainless Steel Cutlery Set | AA34: Home | AB34: Kitchen | AC34: Stevens, Fernandez And Martin | AD34: 19.52 | AE34: 57
A35: PROD31 | B35: Basketball | C35: Sports | D35: Team Sports | E35: Nolan-Snow | F35: 204.39 | G35: 281 | I35: PROD31 | J35: Basketball | K35: Sports | L35: Team Sports | M35: Nolan-Snow | N35: 204.39 | O35: 281 | Q35: PROD31 | R35: BASKETBALL | S35: SPORTS | T35: TEAM SPORTS | U35: NOLAN-SNOW | V35: 204.39 | W35: 281 | Y35: Prod31 | Z35: Basketball | AA35: Sports | AB35: Team Sports | AC35: Nolan-Snow | AD35: 204.39 | AE35: 281
A36: PROD32 | B36: Vitamin C Face Serum | C36: Beauty | D36: Skincare | E36: Griffin Ltd | F36: 283.83 | G36: 244 | I36: PROD32 | J36: Vitamin C Face Serum | K36: Beauty | L36: Skincare | M36: Griffin Ltd | N36: 283.83 | O36: 244 | Q36: PROD32 | R36: VITAMIN C FACE SERUM | S36: BEAUTY | T36: SKINCARE | U36: GRIFFIN LTD | V36: 283.83 | W36: 244 | Y36: Prod32 | Z36: Vitamin C Face Serum | AA36: Beauty | AB36: Skincare | AC36: Griffin Ltd | AD36: 283.83 | AE36: 244
A37: PROD33 | B37: Modern Wall Clock | C37: Home | D37: Decor | E37: Weiss-Watson | F37: 179.77 | G37: 305 | I37: PROD33 | J37: Modern Wall Clock | K37: Home | L37: Decor | M37: Weiss-Watson | N37: 179.77 | O37: 305 | Q37: PROD33 | R37: MODERN WALL CLOCK | S37: HOME | T37: DECOR | U37: WEISS-WATSON | V37: 179.77 | W37: 305 | Y37: Prod33 | Z37: Modern Wall Clock | AA37: Home | AB37: Decor | AC37: Weiss-Watson | AD37: 179.77 | AE37: 305
A38: PROD34 | B38: Gaming Mechanical Keyboard | C38: Electronics | D38: Computer | E38: Lucero LLC | F38: 419.28 | G38: 86 | I38: PROD34 | J38: Gaming Mechanical Keyboard | K38: Electronics | L38: Computer | M38: Lucero LLC | N38: 419.28 | O38: 86 | Q38: PROD34 | R38: GAMING MECHANICAL KEYBOARD | S38: ELECTRONICS | T38: COMPUTER | U38: LUCERO LLC | V38: 419.28 | W38: 86 | Y38: Prod34 | Z38: Gaming Mechanical Keyboard | AA38: Electronics | AB38: Computer | AC38: Lucero Llc | AD38: 419.28 | AE38: 86
A39: PROD35 | B39: Bedroom Table Lamp | C39: Home | D39: Lighting | E39: Jones LLC | F39: 382.22 | G39: 329 | I39: PROD35 | J39: Bedroom Table Lamp | K39: Home | L39: Lighting | M39: Jones LLC | N39: 382.22 | O39: 329 | Q39: PROD35 | R39: BEDROOM TABLE LAMP | S39: HOME | T39: LIGHTING | U39: JONES LLC | V39: 382.22 | W39: 329 | Y39: Prod35 | Z39: Bedroom Table Lamp | AA39: Home | AB39: Lighting | AC39: Jones Llc | AD39: 382.22 | AE39: 329
A40: PROD36 | B40: Women's Summer Dress | C40: Clothing | D40: Tops | E40: Smith-Mills | F40: 223.43 | G40: 154 | I40: PROD36 | J40: Women's Summer Dress | K40: Clothing | L40: Tops | M40: Smith-Mills | N40: 223.43 | O40: 154 | Q40: PROD36 | R40: WOMEN'S SUMMER DRESS | S40: CLOTHING | T40: TOPS | U40: SMITH-MILLS | V40: 223.43 | W40: 154 | Y40: Prod36 | Z40: Women'S Summer Dress | AA40: Clothing | AB40: Tops | AC40: Smith-Mills | AD40: 223.43 | AE40: 154
A41: PROD37 | B41: Men's Casual Sneakers | C41: Clothing | D41: Footwear | E41: Hogan-Lee | F41: 353.47 | G41: 214 | I41: PROD37 | J41: Men's Casual Sneakers | K41: Clothing | L41: Footwear | M41: Hogan-Lee | N41: 353.47 | O41: 214 | Q41: PROD37 | R41: MEN'S CASUAL SNEAKERS | S41: CLOTHING | T41: FOOTWEAR | U41: HOGAN-LEE | V41: 353.47 | W41: 214 | Y41: Prod37 | Z41: Men'S Casual Sneakers | AA41: Clothing | AB41: Footwear | AC41: Hogan-Lee | AD41: 353.47 | AE41: 214
...

Sheet f Excel formulas for calculatio
A1: Product_ID | B1: Product_Name | C1: Category | D1: Sub_Category | E1: Brand | F1: Cost | G1: Stock
A2: PROD0 | B2: Brother Laser Printer | C2: Electronics | D2: Computer | E2: Hunt Inc | F2: 112.42 | G2: 416
A3: PROD1 | B3: Men's Graphic T-Shirt | C3: Clothing | D3: Tops | E3: Terry-Moore | F3: 342.56 | G3: 181
A4: PROD2 | B4: Women's Casual Hoodie | C4: Clothing | D4: Outerwear | E4: Sims Inc | G4: 352
A5: PROD3 | B5: Men's Running Jacket | C5: Clothing | D5: Outerwear | E5: Pineda Ltd | F5: 364.67 | G5: 452
A6: PROD4 | B6: Women's Yoga Pants | C6: Clothing | D6: Bottoms | E6: Gonzales-Davis | F6: 306.46 | G6: 487
A7: PROD5 | B7: Men's Leather Belt | C7: Clothing | D7: Accessories | E7: Baldwin, Garza and Gonzalez | F7: 261 | G7: 59
A8: PROD6 | B8: Herbal Face Moisturizer | C8: Beauty | D8: Skincare | E8: Davidson PLC | F8: 312.8 | G8: 350
A9: PROD7 | B9: LED Table Lamp | C9: Home | D9: Lighting | E9: Harrell LLC | F9: 218.86 | G9: 170
A10: PROD8 | B10: Wireless Bluetooth Earbuds | C10: Electronics | D10: Audio | E10: Perez-Johnston | F10: 439.07 | G10: 142
A11: PROD9 | B11: Adjustable Dumbbell Set | C11: Sports | D11: Fitness | E11: Hill PLC | F11: 495.72 | G11: 323
A12: PROD10 | B12: Ceramic Kitchen Bowl Set | C12: Home | D12: Kitchen | E12: Hamilton Group | F12: 298.86 | G12: 308
A13: PROD11 | B13: HD Smart TV Stick | C13: Electronics | D13: Accessories | E13: Gibson, Hobbs and Weaver | F13: 449.4
A14: PROD12 | B14: Hair Strengthening Shampoo | C14: Beauty | D14: Haircare | E14: Rice LLC | F14: 115.82 | G14: 460
A15: PROD13 | B15: USB-C Fast Charger | C15: Electronics | D15: Accessories | E15: Dawson-Perkins | F15: 242.23 | G15: 453
A16: PROD14 | B16: Decorative Wall Mirror | C16: Home | D16: Decor | E16: Luna, Anderson and Bowman | F16: 48.01 | G16: 439
A17: PROD15 | B17: 4K Home Projector | C17: Electronics | D17: Appliances | E17: Thomas LLC | F17: 465.34 | G17: 301
A18: PROD16 | B18: Beard Grooming Kit | C18: Beauty | D18: Grooming | E18: Erickson-Green | F18: 337.42 | G18: 256
A19: PROD17 | B19: Soccer Training Cone Set | C19: Sports | D19: Accessories | E19: Ford, Murphy and Wilson | F19: 144.53 | G19: 367
A20: PROD18 | B20: Women's Denim Jeans | C20: Clothing | D20: Bottoms | E20: Guerra-Hendrix | G20: 343
A21: PROD19 | B21: Knee Support Brace | C21: Sports | D21: Equipment | E21: May-Reese | F21: 21.34 | G21: 65
A22: PROD20 | B22: Outdoor Sports Water Bottle | C22: Sports | D22: Accessories | E22: Soto-Ellis | F22: 131.51
A23: PROD21 | B23: Multi-Purpose Storage Box | C23: Home | D23: Storage | E23: Gardner-Montes | F23: 123.46 | G23: 76
A24: PROD22 | B24: Carbon Fiber Tennis Racket | C24: Sports | D24: Equipment | E24: Flores, Pineda and Rodriguez | F24: 484.62 | G24: 432
A25: PROD23 | B25: Men's Formal Shirt | C25: Clothing | D25: Tops | E25: Moon, Mora and Santos | G25: 360
A26: PROD24 | B26: Foldable Camping Chair | C26: Sports | D26: Outdoor | E26: Cook Ltd | F26: 166.06 | G26: 340
A27: PROD25 | B27: Women's Scarf Set | C27: Clothing | D27: Accessories | E27: Brown and Sons | F27: 174.02 | G27: 268
A28: PROD26 | B28: Wireless Bluetooth Speaker | C28: Electronics | D28: Audio | E28: Reed-Schmidt | F28: 322.41 | G28: 213
A29: PROD27 | B29: Decorative Floor Vase | C29: Home | D29: Decor | E29: Khan, Jones and Paul | G29: 378
A30: PROD28 | B30: Sports Stopwatch Timer | C30: Sports | D30: Accessories | E30: Burns-Hansen | F30: 38.76 | G30: 137
A31: PROD29 | B31: Fabric Sofa Throw Blanket | C31: Home | D31: Decor | E31: Hoffman Group | F31: 218.48 | G31: 276
A32: PROD30 | B32: Stainless Steel Cutlery Set | C32: Home | D32: Kitchen | E32: Stevens, Fernandez and Martin | F32: 19.52 | G32: 57
A33: PROD31 | B33: Basketball | C33: Sports | D33: Team Sports | E33: Nolan-Snow | F33: 204.39 | G33: 281
A34: PROD32 | B34: Vitamin C Face Serum | C34: Beauty | D34: Skincare | E34: Griffin Ltd | F34: 283.83 | G34: 244
A35: PROD33 | B35: Modern Wall Clock | C35: Home | D35: Decor | E35: Weiss-Watson | F35: 179.77 | G35: 305
A36: PROD34 | B36: Gaming Mechanical Keyboard | C36: Electronics | D36: Computer | E36: Lucero LLC | F36: 419.28 | G36: 86
A37: PROD35 | B37: Bedroom Table Lamp | C37: Home | D37: Lighting | E37: Jones LLC | F37: 382.22 | G37: 329
A38: PROD36 | B38: Women's Summer Dress | C38: Clothing | D38: Tops | E38: Smith-Mills | F38: 223.43 | G38: 154
A39: PROD37 | B39: Men's Casual Sneakers | C39: Clothing | D39: Footwear | E39: Hogan-Lee | F39: 353.47 | G39: 214
A40: PROD38 | B40: Sports Water Hydration Pack | C40: Sports | D40: Outdoor | E40: Sims-Smith | F40: 135.61 | G40: 394
...

Sheet  XLOOKUP VLOOKUP 
A1: Vlookup | I1: Xlookup
A2: Product_ID | B2: Product_Name | C2: Category | D2: Sub_Category | E2: Brand | F2: Cost | G2: Stock | I2: Product_ID | J2: Product_Name | K2: Category | L2: Sub_Category | M2: Brand | N2: Cost | O2: Stock
A3: PROD0 | B3: =VLOOKUP(A3,'f Excel formulas for calculatio'!A:G,2,FALSE) -> Brother Laser Printer | C3: =VLOOKUP(A3,'f Excel formulas for calculatio'!A:G,3,FALSE) -> Electronics | D3: =VLOOKUP(A3,'f Excel formulas for calculatio'!A:G,4,FALSE) -> Computer | E3: =VLOOKUP(A3,'f Excel formulas for calculatio'!A:G,5,FALSE) -> Hunt Inc | F3: =VLOOKUP(A3,'f Excel formulas for calculatio'!A:G,6,FALSE) -> 112.42 | G3: =VLOOKUP(A3,'f Excel formulas for calculatio'!A:G,7,FALSE) -> 416 | I3: PROD0 | J3: =_xlfn.XLOOKUP(I3,A3,B3) -> Brother Laser Printer | K3: =_xlfn.XLOOKUP(J3,B3,C3) -> Electronics | L3: =_xlfn.XLOOKUP(K3,C3,D3) -> Computer | M3: =_xlfn.XLOOKUP(L3,D3,E3) -> Hunt Inc | N3: =_xlfn.XLOOKUP(M3,E3,F3) -> 112.42 | O3: =_xlfn.XLOOKUP(N3,F3,G3) -> 416
A4: PROD1 | B4: =VLOOKUP(A4,'f Excel formulas for calculatio'!A:G,2,FALSE) -> Men's Graphic T-Shirt | C4: =VLOOKUP(A4,'f Excel formulas for calculatio'!A:G,3,FALSE) -> Clothing | D4: =VLOOKUP(A4,'f Excel formulas for calculatio'!A:G,4,FALSE) -> Tops | E4: =VLOOKUP(A4,'f Excel formulas for calculatio'!A:G,5,FALSE) -> Terry-Moore | F4: =VLOOKUP(A4,'f Excel formulas for calculatio'!A:G,6,FALSE) -> 342.56 | G4: =VLOOKUP(A4,'f Excel formulas for calculatio'!A:G,7,FALSE) -> 181 | I4: PROD1 | J4: =_xlfn.XLOOKUP(I4,A4,B4) -> Men's Graphic T-Shirt | K4: =_xlfn.XLOOKUP(J4,B4,C4) -> Clothing | L4: =_xlfn.XLOOKUP(K4,C4,D4) -> Tops | M4: =_xlfn.XLOOKUP(L4,D4,E4) -> Terry-Moore | N4: =_xlfn.XLOOKUP(M4,E4,F4) -> 342.56 | O4: =_xlfn.XLOOKUP(N4,F4,G4) -> 181
A5: PROD2 | B5: =VLOOKUP(A5,'f Excel formulas for calculatio'!A:G,2,FALSE) -> Women's Casual Hoodie | C5: =VLOOKUP(A5,'f Excel formulas for calculatio'!A:G,3,FALSE) -> Clothing | D5: =VLOOKUP(A5,'f Excel formulas for calculatio'!A:G,4,FALSE) -> Outerwear | E5: =VLOOKUP(A5,'f Excel formulas for calculatio'!A:G,5,FALSE) -> Sims Inc | F5: =VLOOKUP(A5,'f Excel formulas for calculatio'!A:G,6,FALSE) -> 0 | G5: =VLOOKUP(A5,'f Excel formulas for calculatio'!A:G,7,FALSE) -> 352 | I5: PROD2 | J5: =_xlfn.XLOOKUP(I5,A5,B5) -> Women's Casual Hoodie | K5: =_xlfn.XLOOKUP(J5,B5,C5) -> Clothing | L5: =_xlfn.XLOOKUP(K5,C5,D5) -> Outerwear | M5: =_xlfn.XLOOKUP(L5,D5,E5) -> Sims Inc | N5: =_xlfn.XLOOKUP(M5,E5,F5) -> 0 | O5: =_xlfn.XLOOKUP(N5,F5,G5) -> 352
A6: PROD3 | B6: =VLOOKUP(A6,'f Excel formulas for calculatio'!A:G,2,FALSE) -> Men's Running Jacket | C6: =VLOOKUP(A6,'f Excel formulas for calculatio'!A:G,3,FALSE) -> Clothing | D6: =VLOOKUP(A6,'f Excel formulas for calculatio'!A:G,4,FALSE) -> Outerwear | E6: =VLOOKUP(A6,'f Excel formulas for calculatio'!A:G,5,FALSE) -> Pineda Ltd | F6: =VLOOKUP(A6,'f Excel formulas for calculatio'!A:G,6,FALSE) -> 364.67 | G6: =VLOOKUP(A6,'f Excel formulas for calculatio'!A:G,7,FALSE) -> 452 | I6: PROD3 | J6: =_xlfn.XLOOKUP(I6,A6,B6) -> Men's Running Jacket | K6: =_xlfn.XLOOKUP(J6,B6,C6) -> Clothing | L6: =_xlfn.XLOOKUP(K6,C6,D6) -> Outerwear | M6: =_xlfn.XLOOKUP(L6,D6,E6) -> Pineda Ltd | N6: =_xlfn.XLOOKUP(M6,E6,F6) -> 364.67 | O6: =_xlfn.XLOOKUP(N6,F6,G6) -> 452
A7: PROD4 | B7: =VLOOKUP(A7,'f Excel formulas for calculatio'!A:G,2,FALSE) -> Women's Yoga Pants | C7: =VLOOKUP(A7,'f Excel formulas for calculatio'!A:G,3,FALSE) -> Clothing | D7: =VLOOKUP(A7,'f Excel formulas for calculatio'!A:G,4,FALSE) -> Bottoms | E7: =VLOOKUP(A7,'f Excel formulas for calculatio'!A:G,5,FALSE) -> Gonzales-Davis | F7: =VLOOKUP(A7,'f Excel formulas for calculatio'!A:G,6,FALSE) -> 306.46 | G7: =VLOOKUP(A7,'f Excel formulas for calculatio'!A:G,7,FALSE) -> 487 | I7: PROD4 | J7: =_xlfn.XLOOKUP(I7,A7,B7) -> Women's Yoga Pants | K7: =_xlfn.XLOOKUP(J7,B7,C7) -> Clothing | L7: =_xlfn.XLOOKUP(K7,C7,D7) -> Bottoms | M7: =_xlfn.XLOOKUP(L7,D7,E7) -> Gonzales-Davis | N7: =_xlfn.XLOOKUP(M7,E7,F7) -> 306.46 | O7: =_xlfn.XLOOKUP(N7,F7,G7) -> 487
A8: PROD5 | B8: =VLOOKUP(A8,'f Excel formulas for calculatio'!A:G,2,FALSE) -> Men's Leather Belt | C8: =VLOOKUP(A8,'f Excel formulas for calculatio'!A:G,3,FALSE) -> Clothing | D8: =VLOOKUP(A8,'f Excel formulas for calculatio'!A:G,4,FALSE) -> Accessories | E8: =VLOOKUP(A8,'f Excel formulas for calculatio'!A:G,5,FALSE) -> Baldwin, Garza and Gonzalez | F8: =VLOOKUP(A8,'f Excel formulas for calculatio'!A:G,6,FALSE) -> 261 | G8: =VLOOKUP(A8,'f Excel formulas for calculatio'!A:G,7,FALSE) -> 59 | I8: PROD5 | J8: =_xlfn.XLOOKUP(I8,A8,B8) -> Men's Leather Belt | K8: =_xlfn.XLOOKUP(J8,B8,C8) -> Clothing | L8: =_xlfn.XLOOKUP(K8,C8,D8) -> Accessories | M8: =_xlfn.XLOOKUP(L8,D8,E8) -> Baldwin, Garza and Gonzalez | N8: =_xlfn.XLOOKUP(M8,E8,F8) -> 261 | O8: =_xlfn.XLOOKUP(N8,F8,G8) -> 59
A9: PROD6 | B9: =VLOOKUP(A9,'f Excel formulas for calculatio'!A:G,2,FALSE) -> Herbal Face Moisturizer | C9: =VLOOKUP(A9,'f Excel formulas for calculatio'!A:G,3,FALSE) -> Beauty | D9: =VLOOKUP(A9,'f Excel formulas for calculatio'!A:G,4,FALSE) -> Skincare | E9: =VLOOKUP(A9,'f Excel formulas for calculatio'!A:G,5,FALSE) -> Davidson PLC | F9: =VLOOKUP(A9,'f Excel formulas for calculatio'!A:G,6,FALSE) -> 312.8 | G9: =VLOOKUP(A9,'f Excel formulas for calculatio'!A:G,7,FALSE) -> 350 | I9: PROD6 | J9: =_xlfn.XLOOKUP(I9,A9,B9) -> Herbal Face Moisturizer | K9: =_xlfn.XLOOKUP(J9,B9,C9) -> Beauty | L9: =_xlfn.XLOOKUP(K9,C9,D9) -> Skincare | M9: =_xlfn.XLOOKUP(L9,D9,E9) -> Davidson PLC | N9: =_xlfn.XLOOKUP(M9,E9,F9) -> 312.8 | O9: =_xlfn.XLOOKUP(N9,F9,G9) -> 350
A10: PROD7 | B10: =VLOOKUP(A10,'f Excel formulas for calculatio'!A:G,2,FALSE) -> LED Table Lamp | C10: =VLOOKUP(A10,'f Excel formulas for calculatio'!A:G,3,FALSE) -> Home | D10: =VLOOKUP(A10,'f Excel formulas for calculatio'!A:G,4,FALSE) -> Lighting | E10: =VLOOKUP(A10,'f Excel formulas for calculatio'!A:G,5,FALSE) -> Harrell LLC | F10: =VLOOKUP(A10,'f Excel formulas for calculatio'!A:G,6,FALSE) -> 218.86 | G10: =VLOOKUP(A10,'f Excel formulas for calculatio'!A:G,7,FALSE) -> 170 | I10: PROD7 | J10: =_xlfn.XLOOKUP(I10,A10,B10) -> LED Table Lamp | K10: =_xlfn.XLOOKUP(J10,B10,C10) -> Home | L10: =_xlfn.XLOOKUP(K10,C10,D10) -> Lighting | M10: =_xlfn.XLOOKUP(L10,D10,E10) -> Harrell LLC | N10: =_xlfn.XLOOKUP(M10,E10,F10) -> 218.86 | O10: =_xlfn.XLOOKUP(N10,F10,G10) -> 170
A11: PROD8 | B11: =VLOOKUP(A11,'f Excel formulas for calculatio'!A:G,2,FALSE) -> Wireless Bluetooth Earbuds | C11: =VLOOKUP(A11,'f Excel formulas for calculatio'!A:G,3,FALSE) -> Electronics | D11: =VLOOKUP(A11,'f Excel formulas for calculatio'!A:G,4,FALSE) -> Audio | E11: =VLOOKUP(A11,'f Excel formulas for calculatio'!A:G,5,FALSE) -> Perez-Johnston | F11: =VLOOKUP(A11,'f Excel formulas for calculatio'!A:G,6,FALSE) -> 439.07 | G11: =VLOOKUP(A11,'f Excel formulas for calculatio'!A:G,7,FALSE) -> 142 | I11: PROD8 | J11: =_xlfn.XLOOKUP(I11,A11,B11) -> Wireless Bluetooth Earbuds | K11: =_xlfn.XLOOKUP(J11,B11,C11) -> Electronics | L11: =_xlfn.XLOOKUP(K11,C11,D11) -> Audio | M11: =_xlfn.XLOOKUP(L11,D11,E11) -> Perez-Johnston | N11: =_xlfn.XLOOKUP(M11,E11,F11) -> 439.07 | O11: =_xlfn.XLOOKUP(N11,F11,G11) -> 142
A12: PROD9 | B12: =VLOOKUP(A12,'f Excel formulas for calculatio'!A:G,2,FALSE) -> Adjustable Dumbbell Set | C12: =VLOOKUP(A12,'f Excel formulas for calculatio'!A:G,3,FALSE) -> Sports | D12: =VLOOKUP(A12,'f Excel formulas for calculatio'!A:G,4,FALSE) -> Fitness | E12: =VLOOKUP(A12,'f Excel formulas for calculatio'!A:G,5,FALSE) -> Hill PLC | F12: =VLOOKUP(A12,'f Excel formulas for calculatio'!A:G,6,FALSE) -> 495.72 | G12: =VLOOKUP(A12,'f Excel formulas for calculatio'!A:G,7,FALSE) -> 323 | I12: PROD9 | J12: =_xlfn.XLOOKUP(I12,A12,B12) -> Adjustable Dumbbell Set | K12: =_xlfn.XLOOKUP(J12,B12,C12) -> Sports | L12: =_xlfn.XLOOKUP(K12,C12,D12) -> Fitness | M12: =_xlfn.XLOOKUP(L12,D12,E12) -> Hill PLC | N12: =_xlfn.XLOOKUP(M12,E12,F12) -> 495.72 | O12: =_xlfn.XLOOKUP(N12,F12,G12) -> 323
A13: PROD10 | B13: =VLOOKUP(A13,'f Excel formulas for calculatio'!A:G,2,FALSE) -> Ceramic Kitchen Bowl Set | C13: =VLOOKUP(A13,'f Excel formulas for calculatio'!A:G,3,FALSE) -> Home | D13: =VLOOKUP(A13,'f Excel formulas for calculatio'!A:G,4,FALSE) -> Kitchen | E13: =VLOOKUP(A13,'f Excel formulas for calculatio'!A:G,5,FALSE) -> Hamilton Group | F13: =VLOOKUP(A13,'f Excel formulas for calculatio'!A:G,6,FALSE) -> 298.86 | G13: =VLOOKUP(A13,'f Excel formulas for calculatio'!A:G,7,FALSE) -> 308 | I13: PROD10 | J13: =_xlfn.XLOOKUP(I13,A13,B13) -> Ceramic Kitchen Bowl Set | K13: =_xlfn.XLOOKUP(J13,B13,C13) -> Home | L13: =_xlfn.XLOOKUP(K13,C13,D13) -> Kitchen | M13: =_xlfn.XLOOKUP(L13,D13,E13) -> Hamilton Group | N13: =_xlfn.XLOOKUP(M13,E13,F13) -> 298.86 | O13: =_xlfn.XLOOKUP(N13,F13,G13) -> 308
A14: PROD11 | B14: =VLOOKUP(A14,'f Excel formulas for calculatio'!A:G,2,FALSE) -> HD Smart TV Stick | C14: =VLOOKUP(A14,'f Excel formulas for calculatio'!A:G,3,FALSE) -> Electronics | D14: =VLOOKUP(A14,'f Excel formulas for calculatio'!A:G,4,FALSE) -> Accessories | E14: =VLOOKUP(A14,'f Excel formulas for calculatio'!A:G,5,FALSE) -> Gibson, Hobbs and Weaver | F14: =VLOOKUP(A14,'f Excel formulas for calculatio'!A:G,6,FALSE) -> 449.4 | G14: =VLOOKUP(A14,'f Excel formulas for calculatio'!A:G,7,FALSE) -> 0 | I14: PROD11 | J14: =_xlfn.XLOOKUP(I14,A14,B14) -> HD Smart TV Stick | K14: =_xlfn.XLOOKUP(J14,B14,C14) -> Electronics | L14: =_xlfn.XLOOKUP(K14,C14,D14) -> Accessories | M14: =_xlfn.XLOOKUP(L14,D14,E14) -> Gibson, Hobbs and Weaver | N14: =_xlfn.XLOOKUP(M14,E14,F14) -> 449.4 | O14: =_xlfn.XLOOKUP(N14,F14,G14) -> 0
... A102: PROD99 | B102: =VLOOKUP(A102,'f Excel formulas for calculatio'!A:G,2,FALSE) -> Stainless Steel Cookware Set | C102: =VLOOKUP(A102,'f Excel formulas for calculatio'!A:G,3,FALSE) -> Home | D102: =VLOOKUP(A102,'f Excel formulas for calculatio'!A:G,4,FALSE) -> Kitchen | E102: =VLOOKUP(A102,'f Excel formulas for calculatio'!A:G,5,FALSE) -> Campbell Ltd | F102: =VLOOKUP(A102,'f Excel formulas for calculatio'!A:G,6,FALSE) -> 201.41 | G102: =VLOOKUP(A102,'f Excel formulas for calculatio'!A:G,7,FALSE) -> 146 | I102: PROD99 | J102: =_xlfn.XLOOKUP(I102,A102,B102) -> Stainless Steel Cookware Set | K102: =_xlfn.XLOOKUP(J102,B102,C102) -> Home | L102: =_xlfn.XLOOKUP(K102,C102,D102) -> Kitchen | M102: =_xlfn.XLOOKUP(L102,D102,E102) -> Campbell Ltd | N102: =_xlfn.XLOOKUP(M102,E102,F102) -> 201.41 | O102: =_xlfn.XLOOKUP(N102,F102,G102) -> 146

Sheet pivot table
A3: Row Labels | B3: Sum of Cost | C3: Sum of Stock
A4: Beauty | B4: 3255.41 | C4: 4816
A5: Clothing | B5: 3985.99 | C5: 4931
A6: Electronics | B6: 6647.66 | C6: 5494
A7: Home | B7: 4696.12 | C7: 4521
A8: Sports | B8: 5294.92 | C8: 6767
A9: Grand Total | B9: 23880.1 | C9: 26529

Sheet Descriptive statistics
B2: Product_ID | C2: Product_Name | D2: Category | E2: Sub_Category | F2: Brand | G2: Cost | H2: Stock
B3: PROD0 | C3: Brother Laser Printer | D3: Electronics | E3: Computer | F3: Hunt Inc | G3: 112.42 | H3: 416 | J3: Cost | M3: Stock
B4: PROD1 | C4: Men's Graphic T-Shirt | D4: Clothing | E4: Tops | F4: Terry-Moore | G4: 342.56 | H4: 181
B5: PROD2 | C5: Women's Casual Hoodie | D5: Clothing | E5: Outerwear | F5: Sims Inc | H5: 352 | J5: Mean | K5: 254.04362 | M5: Mean | N5: 273.49485
B6: PROD3 | C6: Men's Running Jacket | D6: Clothing | E6: Outerwear | F6: Pineda Ltd | G6: 364.67 | H6: 452 | J6: Standard Error | K6: 13.921543 | M6: Standard Error | N6: 13.399044
B7: PROD4 | C7: Women's Yoga Pants | D7: Clothing | E7: Bottoms | F7: Gonzales-Davis | G7: 306.46 | H7: 487 | J7: Median | K7: 242.965 | M7: Median | N7: 276
B8: PROD5 | C8: Men's Leather Belt | D8: Clothing | E8: Accessories | F8: Baldwin, Garza and Gonzalez | G8: 261 | H8: 59 | J8: Mode | K8: 358.47 | M8: Mode | N8: 82
B9: PROD6 | C9: Herbal Face Moisturizer | D9: Beauty | E9: Skincare | F9: Davidson PLC | G9: 312.8 | H9: 350 | J9: Standard Deviation | K9: 134.97437 | M9: Standard Deviation | N9: 131.96528
B10: PROD7 | C10: LED Table Lamp | D10: Home | E10: Lighting | F10: Harrell LLC | G10: 218.86 | H10: 170 | J10: Sample Variance | K10: 18218.079 | M10: Sample Variance | N10: 17414.836
B11: PROD8 | C11: Wireless Bluetooth Earbuds | D11: Electronics | E11: Audio | F11: Perez-Johnston | G11: 439.07 | H11: 142 | J11: Kurtosis | K11: -1.0773127 | M11: Kurtosis | N11: -1.2111477
B12: PROD9 | C12: Adjustable Dumbbell Set | D12: Sports | E12: Fitness | F12: Hill PLC | G12: 495.72 | H12: 323 | J12: Skewness | K12: 0.050774302 | M12: Skewness | N12: -0.0075786925
B13: PROD10 | C13: Ceramic Kitchen Bowl Set | D13: Home | E13: Kitchen | F13: Hamilton Group | G13: 298.86 | H13: 308 | J13: Range | K13: 478.41 | M13: Range | N13: 439
B14: PROD11 | C14: HD Smart TV Stick | D14: Electronics | E14: Accessories | F14: Gibson, Hobbs and Weaver | G14: 449.4 | J14: Minimum | K14: 17.31 | M14: Minimum | N14: 57
B15: PROD12 | C15: Hair Strengthening Shampoo | D15: Beauty | E15: Haircare | F15: Rice LLC | G15: 115.82 | H15: 460 | J15: Maximum | K15: 495.72 | M15: Maximum | N15: 496
B16: PROD13 | C16: USB-C Fast Charger | D16: Electronics | E16: Accessories | F16: Dawson-Perkins | G16: 242.23 | H16: 453 | J16: Sum | K16: 23880.1 | M16: Sum | N16: 26529
B17: PROD14 | C17: Decorative Wall Mirror | D17: Home | E17: Decor | F17: Luna, Anderson and Bowman | G17: 48.01 | H17: 439 | J17: Count | K17: 94 | M17: Count | N17: 97
B18: PROD15 | C18: 4K Home Projector | D18: Electronics | E18: Appliances | F18: Thomas LLC | G18: 465.34 | H18: 301
B19: PROD16 | C19: Beard Grooming Kit | D19: Beauty | E19: Grooming | F19: Erickson-Green | G19: 337.42 | H19: 256
B20: PROD17 | C20: Soccer Training Cone Set | D20: Sports | E20: Accessories | F20: Ford, Murphy and Wilson | G20: 144.53 | H20: 367
B21: PROD18 | C21: Women's Denim Jeans | D21: Clothing | E21: Bottoms | F21: Guerra-Hendrix | H21: 343
B22: PROD19 | C22: Knee Support Brace | D22: Sports | E22: Equipment | F22: May-Reese | G22: 21.34 | H22: 65
B23: PROD20 | C23: Outdoor Sports Water Bottle | D23: Sports | E23: Accessories | F23: Soto-Ellis | G23: 131.51
B24: PROD21 | C24: Multi-Purpose Storage Box | D24: Home | E24: Storage | F24: Gardner-Montes | G24: 123.46 | H24: 76
B25: PROD22 | C25: Carbon Fiber Tennis Racket | D25: Sports | E25: Equipment | F25: Flores, Pineda and Rodriguez | G25: 484.62 | H25: 432
B26: PROD23 | C26: Men's Formal Shirt | D26: Clothing | E26: Tops | F26: Moon, Mora and Santos | H26: 360
B27: PROD24 | C27: Foldable Camping Chair | D27: Sports | E27: Outdoor | F27: Cook Ltd | G27: 166.06 | H27: 340
B28: PROD25 | C28: Women's Scarf Set | D28: Clothing | E28: Accessories | F28: Brown and Sons | G28: 174.02 | H28: 268
B29: PROD26 | C29: Wireless Bluetooth Speaker | D29: Electronics | E29: Audio | F29: Reed-Schmidt | G29: 322.41 | H29: 213
B30: PROD27 | C30: Decorative Floor Vase | D30: Home | E30: Decor | F30: Khan, Jones and Paul | H30: 378
B31: PROD28 | C31: Sports Stopwatch Timer | D31: Sports | E31: Accessories | F31: Burns-Hansen | G31: 38.76 | H31: 137
B32: PROD29 | C32: Fabric Sofa Throw Blanket | D32: Home | E32: Decor | F32: Hoffman Group | G32: 218.48 | H32: 276
B33: PROD30 | C33: Stainless Steel Cutlery Set | D33: Home | E33: Kitchen | F33: Stevens, Fernandez and Martin | G33: 19.52 | H33: 57
B34: PROD31 | C34: Basketball | D34: Sports | E34: Team Sports | F34: Nolan-Snow | G34: 204.39 | H34: 281
B35: PROD32 | C35: Vitamin C Face Serum | D35: Beauty | E35: Skincare | F35: Griffin Ltd | G35: 283.83 | H35: 244
B36: PROD33 | C36: Modern Wall Clock | D36: Home | E36: Decor | F36: Weiss-Watson | G36: 179.77 | H36: 305
B37: PROD34 | C37: Gaming Mechanical Keyboard | D37: Electronics | E37: Computer | F37: Lucero LLC | G37: 419.28 | H37: 86
B38: PROD35 | C38: Bedroom Table Lamp | D38: Home | E38: Lighting | F38: Jones LLC | G38: 382.22 | H38: 329
B39: PROD36 | C39: Women's Summer Dress | D39: Clothing | E39: Tops | F39: Smith-Mills | G39: 223.43 | H39: 154
B40: PROD37 | C40: Men's Casual Sneakers | D40: Clothing | E40: Footwear | F40: Hogan-Lee | G40: 353.47 | H40: 214
B41: PROD38 | C41: Sports Water Hydration Pack | D41: Sports | E41: Outdoor | F41: Sims-Smith | G41: 135.61 | H41: 394
...

Sheet ●Data visualization
F1: Product_ID | G1: Product_Name | H1: Category | I1: Sub_Category | J1: Brand | K1: Cost | L1: Stock
F2: PROD0 | G2: Brother Laser Printer | H2: Electronics | I2: Computer | J2: Hunt Inc | K2: 112.42 | L2: 416
F3: PROD1 | G3: Men's Graphic T-Shirt | H3: Clothing | I3: Tops | J3: Terry-Moore | K3: 342.56 | L3: 181
F4: PROD2 | G4: Women's Casual Hoodie | H4: Clothing | I4: Outerwear | J4: Sims Inc | L4: 352
F5: PROD3 | G5: Men's Running Jacket | H5: Clothing | I5: Outerwear | J5: Pineda Ltd | K5: 364.67 | L5: 452
F6: PROD4 | G6: Women's Yoga Pants | H6: Clothing | I6: Bottoms | J6: Gonzales-Davis | K6: 306.46 | L6: 487
F7: PROD5 | G7: Men's Leather Belt | H7: Clothing | I7: Accessories | J7: Baldwin, Garza and Gonzalez | K7: 261 | L7: 59
F8: PROD6 | G8: Herbal Face Moisturizer | H8: Beauty | I8: Skincare | J8: Davidson PLC | K8: 312.8 | L8: 350
F9: PROD7 | G9: LED Table Lamp | H9: Home | I9: Lighting | J9: Harrell LLC | K9: 218.86 | L9: 170
F10: PROD8 | G10: Wireless Bluetooth Earbuds | H10: Electronics | I10: Audio | J10: Perez-Johnston | K10: 439.07 | L10: 142
F11: PROD9 | G11: Adjustable Dumbbell Set | H11: Sports | I11: Fitness | J11: Hill PLC | K11: 495.72 | L11: 323
F12: PROD10 | G12: Ceramic Kitchen Bowl Set | H12: Home | I12: Kitchen | J12: Hamilton Group | K12: 298.86 | L12: 308
F13: PROD11 | G13: HD Smart TV Stick | H13: Electronics | I13: Accessories | J13: Gibson, Hobbs and Weaver | K13: 449.4
F14: PROD12 | G14: Hair Strengthening Shampoo | H14: Beauty | I14: Haircare | J14: Rice LLC | K14: 115.82 | L14: 460
F15: PROD13 | G15: USB-C Fast Charger | H15: Electronics | I15: Accessories | J15: Dawson-Perkins | K15: 242.23 | L15: 453
F16: PROD14 | G16: Decorative Wall Mirror | H16: Home | I16: Decor | J16: Luna, Anderson and Bowman | K16: 48.01 | L16: 439
F17: PROD15 | G17: 4K Home Projector | H17: Electronics | I17: Appliances | J17: Thomas LLC | K17: 465.34 | L17: 301
F18: PROD16 | G18: Beard Grooming Kit | H18: Beauty | I18: Grooming | J18: Erickson-Green | K18: 337.42 | L18: 256
F19: PROD17 | G19: Soccer Training Cone Set | H19: Sports | I19: Accessories | J19: Ford, Murphy and Wilson | K19: 144.53 | L19: 367
F20: PROD18 | G20: Women's Denim Jeans | H20: Clothing | I20: Bottoms | J20: Guerra-Hendrix | L20: 343
F21: PROD19 | G21: Knee Support Brace | H21: Sports | I21: Equipment | J21: May-Reese | K21: 21.34 | L21: 65
F22: PROD20 | G22: Outdoor Sports Water Bottle | H22: Sports | I22: Accessories | J22: Soto-Ellis | K22: 131.51
F23: PROD21 | G23: Multi-Purpose Storage Box | H23: Home | I23: Storage | J23: Gardner-Montes | K23: 123.46 | L23: 76
F24: PROD22 | G24: Carbon Fiber Tennis Racket | H24: Sports | I24: Equipment | J24: Flores, Pineda and Rodriguez | K24: 484.62 | L24: 432
F25: PROD23 | G25: Men's Formal Shirt | H25: Clothing | I25: Tops | J25: Moon, Mora and Santos | L25: 360
F26: PROD24 | G26: Foldable Camping Chair | H26: Sports | I26: Outdoor | J26: Cook Ltd | K26: 166.06 | L26: 340
F27: PROD25 | G27: Women's Scarf Set | H27: Clothing | I27: Accessories | J27: Brown and Sons | K27: 174.02 | L27: 268
F28: PROD26 | G28: Wireless Bluetooth Speaker | H28: Electronics | I28: Audio | J28: Reed-Schmidt | K28: 322.41 | L28: 213
F29: PROD27 | G29: Decorative Floor Vase | H29: Home | I29: Decor | J29: Khan, Jones and Paul | L29: 378
F30: PROD28 | G30: Sports Stopwatch Timer | H30: Sports | I30: Accessories | J30: Burns-Hansen | K30: 38.76 | L30: 137
F31: PROD29 | G31: Fabric Sofa Throw Blanket | H31: Home | I31: Decor | J31: Hoffman Group | K31: 218.48 | L31: 276
F32: PROD30 | G32: Stainless Steel Cutlery Set | H32: Home | I32: Kitchen | J32: Stevens, Fernandez and Martin | K32: 19.52 | L32: 57
F33: PROD31 | G33: Basketball | H33: Sports | I33: Team Sports | J33: Nolan-Snow | K33: 204.39 | L33: 281
F34: PROD32 | G34: Vitamin C Face Serum | H34: Beauty | I34: Skincare | J34: Griffin Ltd | K34: 283.83 | L34: 244
F35: PROD33 | G35: Modern Wall Clock | H35: Home | I35: Decor | J35: Weiss-Watson | K35: 179.77 | L35: 305
F36: PROD34 | G36: Gaming Mechanical Keyboard | H36: Electronics | I36: Computer | J36: Lucero LLC | K36: 419.28 | L36: 86
F37: PROD35 | G37: Bedroom Table Lamp | H37: Home | I37: Lighting | J37: Jones LLC | K37: 382.22 | L37: 329
F38: PROD36 | G38: Women's Summer Dress | H38: Clothing | I38: Tops | J38: Smith-Mills | K38: 223.43 | L38: 154
F39: PROD37 | G39: Men's Casual Sneakers | H39: Clothing | I39: Footwear | J39: Hogan-Lee | K39: 353.47 | L39: 214
F40: PROD38 | G40: Sports Water Hydration Pack | H40: Sports | I40: Outdoor | J40: Sims-Smith | K40: 135.61 | L40: 394
...
