Workbook

Sheet Data 
A1: Customer_ID | B1: Name | C1: Age | D1: Gender | E1: City | F1: State | G1: Country | H1: Loyalty_Level
A2: CUST1000 | B2: sheena bonilla | C2: 55 | D2: Male | E2: Donaldton | F2: North Carolina | G2: USA
A3: CUST1001 | B3: Eugene Nelson | C3: 26 | D3: Female | E3: Phillipsmouth | F3: North Dakota | G3: USA | H3: Platinum | J3: 1. Data entry, import, and basic organization using tables
A4: CUST1002 | B4: dr. Benjamin Price | C4: 29 | D4: Female | E4: Kylebury | F4: Alabama | G4: USA | H4: Platinum
A5: CUST1003 | B5: jeremy harris | C5: 59 | D5: Female | E5: Thomastown | F5: Ohio | G5: USA | H5: Bronze
A6: CUST1004 | B6: Caroline Collins | C6: 64 | D6: Female | E6: Nicholasshire | F6: California | G6: USA | H6: Silver
A7: CUST1005 | B7: Christine Vaughn | C7: 24 | D7: Male | E7: East Amandamouth | F7: Oregon | G7: USA | H7: Bronze
A8: CUST1006 | B8: Amber Jackson | C8: 29 | D8: Female | E8: Deborahborough | F8: South Dakota | G8: USA | H8: Platinum
A9: CUST1007 | B9: Daniel Boyd | C9: 29 | D9: Female | E9: West Pamelafurt | F9: West Virginia | G9: USA | H9: Bronze
A10: CUST1008 | B10: Melissa Howard | C10: 53 | D10: Female | E10: Maynardton | F10: New Hampshire | G10: USA | H10: Gold
A11: CUST1009 | B11: Ms. Maria Leach | C11: 64 | D11: Male | E11: Melissashire | F11: Pennsylvania | G11: USA | H11: Platinum
A12: CUST1010 | B12: Dominic Page | C12: 53 | D12: Male | E12: Port Michaelburgh | F12: Pennsylvania | G12: USA | H12: Bronze
A13: CUST1011 | B13: Brian Lopez | C13: 28 | D13: Female | E13: East Krista | F13: New York | G13: USA | H13: Gold
A14: CUST1012 | B14: Kenneth Lambert | C14: 55 | D14: Female | E14: North Kathryn | F14: Kansas | G14: USA | H14: Platinum
A15: CUST1013 | B15: Nathan Hernandez | C15: 32 | D15: Female | E15: New Becky | F15: Montana | G15: USA | H15: Silver
... A19: CUST1017 | B19: Adam Cruz | C19: 60 | D19: Female | E19: Brandonville | F19: Georgia | G19: USA | H19: Platinum
A20: CUST1018 | B20: Rhonda Moss | C20: 43 | D20: Male | E20: South William | F20: Kansas | G20: USA
A21: CUST1019 | B21: Michael Torres | C21: 46 | D21: Female | E21: Gonzalezfort | F21: New Jersey | G21: USA | H21: Platinum
A22: CUST1020 | B22: Bridget Allen | C22: 59 | D22: Male | E22: Lake Shaneburgh | F22: Delaware | G22: USA | H22: Silver
A23: CUST1021 | B23: Jeff Martinez | C23: 36 | D23: Female | E23: Smithburgh | F23: Oklahoma | G23: USA | H23: Gold
A24: CUST1022 | B24: paul fox | C24: 33 | D24: Female | E24: Michaelton | F24: Hawaii | G24: USA | H24: Silver
A25: CUST1023 | B25: Jonathan Steele | C25: 52 | D25: Female | E25: Molinabury | F25: Oregon | G25: USA | H25: Silver
A26: CUST1024 | B26: Heather Collins | C26: 40 | D26: Male | E26: Rogerschester | F26: Idaho | G26: USA | H26: Platinum
A27: CUST1025 | B27: Diana Taylor | C27: 59 | D27: Female | E27: Vasqueztown | F27: California | G27: USA | H27: Bronze
A28: CUST1026 | B28: Amber Carlson | C28: 18 | D28: Female | E28: East Michellemouth | F28: Missouri | G28: USA | H28: Gold
A29: CUST1027 | B29: Leslie Johnson | C29: 31 | D29: Male | E29: Mollyshire | F29: Utah | G29: USA
A30: CUST1028 | B30: Joshua Ryan | C30: 27 | D30: Female | E30: New David | F30: New Jersey | G30: USA | H30: Platinum
A31: CUST1029 | B31: David Arnold | C31: 54 | D31: Female | E31: East Jennifer | F31: California | G31: USA | H31: Silver
A32: CUST1030 | B32: Jessica Acevedo | C32: 64 | D32: Female | E32: Amybury | F32: Pennsylvania | G32: USA | H32: Bronze
A33: CUST1031 | B33: Sarah Vance | C33: 41 | D33: Male | E33: Johnsonville | F33: Oregon | G33: USA | H33: Silver
A34: CUST1032 | B34: Mike Jennings | C34: 48 | D34: Female | E34: Fostermouth | F34: Arizona | G34: USA | H34: Gold
A35: CUST1033 | B35: Robert Jones DDS | C35: 25 | D35: Male | E35: Tristanton | F35: Oklahoma | G35: USA | H35: Platinum
A36: CUST1034 | B36: Christopher Olson | C36: 27 | D36: Female | E36: West Richard | F36: Maryland | G36: USA | H36: Platinum
A37: CUST1035 | B37: Rachel Myers | C37: 52 | D37: Male | E37: Robertberg | F37: North Dakota | G37: USA | H37: Silver
A38: CUST1036 | B38: Thomas Phillips | C38: 20 | D38: Female | E38: Luisfurt | F38: Georgia | G38: USA | H38: Gold
A39: CUST1037 | B39: Christopher Carter | C39: 27 | D39: Female | E39: Brendastad | F39: South Dakota | G39: USA
A40: CUST1038 | B40: Deanna Simpson | C40: 35 | D40: Female | E40: Brownport | F40: North Dakota | G40: USA | H40: Bronze
A41: CUST1039 | B41: Tonya Reynolds | C41: 55 | D41: Female | E41: Darleneton | F41: Michigan | G41: USA | H41: Gold
A42: CUST1040 | B42: Eric Vega | C42: 50 | D42: Male | E42: Williamsonland | F42: Kansas | G42: USA | H42: Gold
A43: CUST1041 | B43: James Gibbs | C43: 21 | D43: Male | E43: Mooneyshire | F43: Alaska | G43: USA | H43: Platinum
...

Sheet Data cleaning
A1: 2 | B1: find/remove duplicates - No duplicate / 4 replaced | F1: validate data | G1: handle missing/inconsistent data
J2: Trim | S2: Upper
A3: Customer_ID | B3: Name | C3: Age | D3: Gender | E3: City | F3: State | G3: Country | H3: Loyalty_Level | J3: {=TRIM(Table13[#All])} -> Customer_ID | K3: Name | L3: Age | M3: Gender | N3: City | O3: State | P3: Country | Q3: Loyalty_Level | S3: {=UPPER(_xlfn.ANCHORARRAY(J3))} -> CUSTOMER_ID | T3: NAME | U3: AGE | V3: GENDER | W3: CITY | X3: STATE | Y3: COUNTRY | Z3: LOYALTY_LEVEL
A4: CUST1000 | B4: sheena bonilla | C4: 55 | D4: Male | E4: Donaldton | F4: North Carolina | G4: USA | J4: CUST1000 | K4: sheena bonilla | L4: 55 | M4: Male | N4: Donaldton | O4: North Carolina | P4: USA | S4: CUST1000 | T4: SHEENA BONILLA | U4: 55 | V4: MALE | W4: DONALDTON | X4: NORTH CAROLINA | Y4: USA
A5: CUST1001 | B5: Eugene Nelson | C5: 26 | D5: Female | E5: Phillipsmouth | F5: North Dakota | G5: USA | H5: Platinum | J5: CUST1001 | K5: Eugene Nelson | L5: 26 | M5: Female | N5: Phillipsmouth | O5: North Dakota | P5: USA | Q5: Platinum | S5: CUST1001 | T5: EUGENE NELSON | U5: 26 | V5: FEMALE | W5: PHILLIPSMOUTH | X5: NORTH DAKOTA | Y5: USA | Z5: PLATINUM
A6: CUST1002 | B6: dr. Benjamin Price | C6: 29 | D6: Female | E6: Kylebury | F6: Alabama | G6: USA | H6: Platinum | J6: CUST1002 | K6: dr. Benjamin Price | L6: 29 | M6: Female | N6: Kylebury | O6: Alabama | P6: USA | Q6: Platinum | S6: CUST1002 | T6: DR. BENJAMIN PRICE | U6: 29 | V6: FEMALE | W6: KYLEBURY | X6: ALABAMA | Y6: USA | Z6: PLATINUM
A7: CUST1003 | B7: jeremy harris | C7: 59 | D7: Female | E7: Thomastown | F7: Ohio | G7: USA | H7: Bronze | J7: CUST1003 | K7: jeremy harris | L7: 59 | M7: Female | N7: Thomastown | O7: Ohio | P7: USA | Q7: Bronze | S7: CUST1003 | T7: JEREMY HARRIS | U7: 59 | V7: FEMALE | W7: THOMASTOWN | X7: OHIO | Y7: USA | Z7: BRONZE
A8: CUST1004 | B8: Caroline Collins | C8: 64 | D8: Female | E8: Nicholasshire | F8: California | G8: USA | H8: Silver | J8: CUST1004 | K8: Caroline Collins | L8: 64 | M8: Female | N8: Nicholasshire | O8: California | P8: USA | Q8: Silver | S8: CUST1004 | T8: CAROLINE COLLINS | U8: 64 | V8: FEMALE | W8: NICHOLASSHIRE | X8: CALIFORNIA | Y8: USA | Z8: SILVER
A9: CUST1005 | B9: Christine Vaughn | C9: 24 | D9: Male | E9: East Amandamouth | F9: Oregon | G9: USA | H9: Bronze | J9: CUST1005 | K9: Christine Vaughn | L9: 24 | M9: Male | N9: East Amandamouth | O9: Oregon | P9: USA | Q9: Bronze | S9: CUST1005 | T9: CHRISTINE VAUGHN | U9: 24 | V9: MALE | W9: EAST AMANDAMOUTH | X9: OREGON | Y9: USA | Z9: BRONZE
A10: CUST1006 | B10: Amber Jackson | C10: 29 | D10: Female | E10: Deborahborough | F10: South Dakota | G10: USA | H10: Platinum | J10: CUST1006 | K10: Amber Jackson | L10: 29 | M10: Female | N10: Deborahborough | O10: South Dakota | P10: USA | Q10: Platinum | S10: CUST1006 | T10: AMBER JACKSON | U10: 29 | V10: FEMALE | W10: DEBORAHBOROUGH | X10: SOUTH DAKOTA | Y10: USA | Z10: PLATINUM
A11: CUST1007 | B11: Daniel Boyd | C11: 29 | D11: Female | E11: West Pamelafurt | F11: West Virginia | G11: USA | H11: Bronze | J11: CUST1007 | K11: Daniel Boyd | L11: 29 | M11: Female | N11: West Pamelafurt | O11: West Virginia | P11: USA | Q11: Bronze | S11: CUST1007 | T11: DANIEL BOYD | U11: 29 | V11: FEMALE | W11: WEST PAMELAFURT | X11: WEST VIRGINIA | Y11: USA | Z11: BRONZE
A12: CUST1008 | B12: Melissa Howard | C12: 53 | D12: Female | E12: Maynardton | F12: New Hampshire | G12: USA | H12: Gold | J12: CUST1008 | K12: Melissa Howard | L12: 53 | M12: Female | N12: Maynardton | O12: New Hampshire | P12: USA | Q12: Gold | S12: CUST1008 | T12: MELISSA HOWARD | U12: 53 | V12: FEMALE | W12: MAYNARDTON | X12: NEW HAMPSHIRE | Y12: USA | Z12: GOLD
A13: CUST1009 | B13: Ms. Maria Leach | C13: 64 | D13: Male | E13: Melissashire | F13: Pennsylvania | G13: USA | H13: Platinum | J13: CUST1009 | K13: Ms. Maria Leach | L13: 64 | M13: Male | N13: Melissashire | O13: Pennsylvania | P13: USA | Q13: Platinum | S13: CUST1009 | T13: MS. MARIA LEACH | U13: 64 | V13: MALE | W13: MELISSASHIRE | X13: PENNSYLVANIA | Y13: USA | Z13: PLATINUM
A14: CUST1010 | B14: Dominic Page | C14: 53 | D14: Male | E14: Port Michaelburgh | F14: Pennsylvania | G14: USA | H14: Bronze | J14: CUST1010 | K14: Dominic Page | L14: 53 | M14: Male | N14: Port Michaelburgh | O14: Pennsylvania | P14: USA | Q14: Bronze | S14: CUST1010 | T14: DOMINIC PAGE | U14: 53 | V14: MALE | W14: PORT MICHAELBURGH | X14: PENNSYLVANIA | Y14: USA | Z14: BRONZE
A15: CUST1011 | B15: Brian Lopez | C15: 28 | D15: Female | E15: East Krista | F15: New York | G15: USA | H15: Gold | J15: CUST1011 | K15: Brian Lopez | L15: 28 | M15: Female | N15: East Krista | O15: New York | P15: USA | Q15: Gold | S15: CUST1011 | T15: BRIAN LOPEZ | U15: 28 | V15: FEMALE | W15: EAST KRISTA | X15: NEW YORK | Y15: USA | Z15: GOLD
A16: CUST1012 | B16: Kenneth Lambert | C16: 55 | D16: Female | E16: North Kathryn | F16: Kansas | G16: USA | H16: Platinum | J16: CUST1012 | K16: Kenneth Lambert | L16: 55 | M16: Female | N16: North Kathryn | O16: Kansas | P16: USA | Q16: Platinum | S16: CUST1012 | T16: KENNETH LAMBERT | U16: 55 | V16: FEMALE | W16: NORTH KATHRYN | X16: KANSAS | Y16: USA | Z16: PLATINUM
... A21: CUST1017 | B21: Adam Cruz | C21: 60 | D21: Female | E21: Brandonville | F21: Georgia | G21: USA | H21: Platinum | J21: CUST1017 | K21: Adam Cruz | L21: 60 | M21: Female | N21: Brandonville | O21: Georgia | P21: USA | Q21: Platinum | S21: CUST1017 | T21: ADAM CRUZ | U21: 60 | V21: FEMALE | W21: BRANDONVILLE | X21: GEORGIA | Y21: USA | Z21: PLATINUM
A22: CUST1018 | B22: Rhonda Moss | C22: 43 | D22: Male | E22: South William | F22: Kansas | G22: USA | J22: CUST1018 | K22: Rhonda Moss | L22: 43 | M22: Male | N22: South William | O22: Kansas | P22: USA | S22: CUST1018 | T22: RHONDA MOSS | U22: 43 | V22: MALE | W22: SOUTH WILLIAM | X22: KANSAS | Y22: USA
A23: CUST1019 | B23: Michael Torres | C23: 46 | D23: Female | E23: Gonzalezfort | F23: New Jersey | G23: USA | H23: Platinum | J23: CUST1019 | K23: Michael Torres | L23: 46 | M23: Female | N23: Gonzalezfort | O23: New Jersey | P23: USA | Q23: Platinum | S23: CUST1019 | T23: MICHAEL TORRES | U23: 46 | V23: FEMALE | W23: GONZALEZFORT | X23: NEW JERSEY | Y23: USA | Z23: PLATINUM
A24: CUST1020 | B24: Bridget Allen | C24: 59 | D24: Male | E24: Lake Shaneburgh | F24: Delaware | G24: USA | H24: Silver | J24: CUST1020 | K24: Bridget Allen | L24: 59 | M24: Male | N24: Lake Shaneburgh | O24: Delaware | P24: USA | Q24: Silver | S24: CUST1020 | T24: BRIDGET ALLEN | U24: 59 | V24: MALE | W24: LAKE SHANEBURGH | X24: DELAWARE | Y24: USA | Z24: SILVER
A25: CUST1021 | B25: Jeff Martinez | C25: 36 | D25: Female | E25: Smithburgh | F25: Oklahoma | G25: USA | H25: Gold | J25: CUST1021 | K25: Jeff Martinez | L25: 36 | M25: Female | N25: Smithburgh | O25: Oklahoma | P25: USA | Q25: Gold | S25: CUST1021 | T25: JEFF MARTINEZ | U25: 36 | V25: FEMALE | W25: SMITHBURGH | X25: OKLAHOMA | Y25: USA | Z25: GOLD
A26: CUST1022 | B26: paul fox | C26: 33 | D26: Female | E26: Michaelton | F26: Hawaii | G26: USA | H26: Silver | J26: CUST1022 | K26: paul fox | L26: 33 | M26: Female | N26: Michaelton | O26: Hawaii | P26: USA | Q26: Silver | S26: CUST1022 | T26: PAUL FOX | U26: 33 | V26: FEMALE | W26: MICHAELTON | X26: HAWAII | Y26: USA | Z26: SILVER
A27: CUST1023 | B27: Jonathan Steele | C27: 52 | D27: Female | E27: Molinabury | F27: Oregon | G27: USA | H27: Silver | J27: CUST1023 | K27: Jonathan Steele | L27: 52 | M27: Female | N27: Molinabury | O27: Oregon | P27: USA | Q27: Silver | S27: CUST1023 | T27: JONATHAN STEELE | U27: 52 | V27: FEMALE | W27: MOLINABURY | X27: OREGON | Y27: USA | Z27: SILVER
A28: CUST1024 | B28: Heather Collins | C28: 40 | D28: Male | E28: Rogerschester | F28: Idaho | G28: USA | H28: Platinum | J28: CUST1024 | K28: Heather Collins | L28: 40 | M28: Male | N28: Rogerschester | O28: Idaho | P28: USA | Q28: Platinum | S28: CUST1024 | T28: HEATHER COLLINS | U28: 40 | V28: MALE | W28: ROGERSCHESTER | X28: IDAHO | Y28: USA | Z28: PLATINUM
A29: CUST1025 | B29: Diana Taylor | C29: 59 | D29: Female | E29: Vasqueztown | F29: California | G29: USA | H29: Bronze | J29: CUST1025 | K29: Diana Taylor | L29: 59 | M29: Female | N29: Vasqueztown | O29: California | P29: USA | Q29: Bronze | S29: CUST1025 | T29: DIANA TAYLOR | U29: 59 | V29: FEMALE | W29: VASQUEZTOWN | X29: CALIFORNIA | Y29: USA | Z29: BRONZE
A30: CUST1026 | B30: Amber Carlson | C30: 18 | D30: Female | E30: East Michellemouth | F30: Missouri | G30: USA | H30: Gold | J30: CUST1026 | K30: Amber Carlson | L30: 18 | M30: Female | N30: East Michellemouth | O30: Missouri | P30: USA | Q30: Gold | S30: CUST1026 | T30: AMBER CARLSON | U30: 18 | V30: FEMALE | W30: EAST MICHELLEMOUTH | X30: MISSOURI | Y30: USA | Z30: GOLD
A31: CUST1027 | B31: Leslie Johnson | C31: 31 | D31: Male | E31: Mollyshire | F31: Utah | G31: USA | J31: CUST1027 | K31: Leslie Johnson | L31: 31 | M31: Male | N31: Mollyshire | O31: Utah | P31: USA | S31: CUST1027 | T31: LESLIE JOHNSON | U31: 31 | V31: MALE | W31: MOLLYSHIRE | X31: UTAH | Y31: USA
A32: CUST1028 | B32: Joshua Ryan | C32: 27 | D32: Female | E32: New David | F32: New Jersey | G32: USA | H32: Platinum | J32: CUST1028 | K32: Joshua Ryan | L32: 27 | M32: Female | N32: New David | O32: New Jersey | P32: USA | Q32: Platinum | S32: CUST1028 | T32: JOSHUA RYAN | U32: 27 | V32: FEMALE | W32: NEW DAVID | X32: NEW JERSEY | Y32: USA | Z32: PLATINUM
A33: CUST1029 | B33: David Arnold | C33: 54 | D33: Female | E33: East Jennifer | F33: California | G33: USA | H33: Silver | J33: CUST1029 | K33: David Arnold | L33: 54 | M33: Female | N33: East Jennifer | O33: California | P33: USA | Q33: Silver | S33: CUST1029 | T33: DAVID ARNOLD | U33: 54 | V33: FEMALE | W33: EAST JENNIFER | X33: CALIFORNIA | Y33: USA | Z33: SILVER
A34: CUST1030 | B34: Jessica Acevedo | C34: 64 | D34: Female | E34: Amybury | F34: Pennsylvania | G34: USA | H34: Bronze | J34: CUST1030 | K34: Jessica Acevedo | L34: 64 | M34: Female | N34: Amybury | O34: Pennsylvania | P34: USA | Q34: Bronze | S34: CUST1030 | T34: JESSICA ACEVEDO | U34: 64 | V34: FEMALE | W34: AMYBURY | X34: PENNSYLVANIA | Y34: USA | Z34: BRONZE
A35: CUST1031 | B35: Sarah Vance | C35: 41 | D35: Male | E35: Johnsonville | F35: Oregon | G35: USA | H35: Silver | J35: CUST1031 | K35: Sarah Vance | L35: 41 | M35: Male | N35: Johnsonville | O35: Oregon | P35: USA | Q35: Silver | S35: CUST1031 | T35: SARAH VANCE | U35: 41 | V35: MALE | W35: JOHNSONVILLE | X35: OREGON | Y35: USA | Z35: SILVER
A36: CUST1032 | B36: Mike Jennings | C36: 48 | D36: Female | E36: Fostermouth | F36: Arizona | G36: USA | H36: Gold | J36: CUST1032 | K36: Mike Jennings | L36: 48 | M36: Female | N36: Fostermouth | O36: Arizona | P36: USA | Q36: Gold | S36: CUST1032 | T36: MIKE JENNINGS | U36: 48 | V36: FEMALE | W36: FOSTERMOUTH | X36: ARIZONA | Y36: USA | Z36: GOLD
A37: CUST1033 | B37: Robert Jones DDS | C37: 25 | D37: Male | E37: Tristanton | F37: Oklahoma | G37: USA | H37: Platinum | J37: CUST1033 | K37: Robert Jones DDS | L37: 25 | M37: Male | N37: Tristanton | O37: Oklahoma | P37: USA | Q37: Platinum | S37: CUST1033 | T37: ROBERT JONES DDS | U37: 25 | V37: MALE | W37: TRISTANTON | X37: OKLAHOMA | Y37: USA | Z37: PLATINUM
A38: CUST1034 | B38: Christopher Olson | C38: 27 | D38: Female | E38: West Richard | F38: Maryland | G38: USA | H38: Platinum | J38: CUST1034 | K38: Christopher Olson | L38: 27 | M38: Female | N38: West Richard | O38: Maryland | P38: USA | Q38: Platinum | S38: CUST1034 | T38: CHRISTOPHER OLSON | U38: 27 | V38: FEMALE | W38: WEST RICHARD | X38: MARYLAND | Y38: USA | Z38: PLATINUM
A39: CUST1035 | B39: Rachel Myers | C39: 52 | D39: Male | E39: Robertberg | F39: North Dakota | G39: USA | H39: Silver | J39: CUST1035 | K39: Rachel Myers | L39: 52 | M39: Male | N39: Robertberg | O39: North Dakota | P39: USA | Q39: Silver | S39: CUST1035 | T39: RACHEL MYERS | U39: 52 | V39: MALE | W39: ROBERTBERG | X39: NORTH DAKOTA | Y39: USA | Z39: SILVER
A40: CUST1036 | B40: Thomas Phillips | C40: 20 | D40: Female | E40: Luisfurt | F40: Georgia | G40: USA | H40: Gold | J40: CUST1036 | K40: Thomas Phillips | L40: 20 | M40: Female | N40: Luisfurt | O40: Georgia | P40: USA | Q40: Gold | S40: CUST1036 | T40: THOMAS PHILLIPS | U40: 20 | V40: FEMALE | W40: LUISFURT | X40: GEORGIA | Y40: USA | Z40: GOLD
A41: CUST1037 | B41: Christopher Carter | C41: 27 | D41: Female | E41: Brendastad | F41: South Dakota | G41: USA | J41: CUST1037 | K41: Christopher Carter | L41: 27 | M41: Female | N41: Brendastad | O41: South Dakota | P41: USA | S41: CUST1037 | T41: CHRISTOPHER CARTER | U41: 27 | V41: FEMALE | W41: BRENDASTAD | X41: SOUTH DAKOTA | Y41: USA
A42: CUST1038 | B42: Deanna Simpson | C42: 35 | D42: Female | E42: Brownport | F42: North Dakota | G42: USA | H42: Bronze | J42: CUST1038 | K42: Deanna Simpson | L42: 35 | M42: Female | N42: Brownport | O42: North Dakota | P42: USA | Q42: Bronze | S42: CUST1038 | T42: DEANNA SIMPSON | U42: 35 | V42: FEMALE | W42: BROWNPORT | X42: NORTH DAKOTA | Y42: USA | Z42: BRONZE
A43: CUST1039 | B43: Tonya Reynolds | C43: 55 | D43: Female | E43: Darleneton | F43: Michigan | G43: USA | H43: Gold | J43: CUST1039 | K43: Tonya Reynolds | L43: 55 | M43: Female | N43: Darleneton | O43: Michigan | P43: USA | Q43: Gold | S43: CUST1039 | T43: TONYA REYNOLDS | U43: 55 | V43: FEMALE | W43: DARLENETON | X43: MICHIGAN | Y43: USA | Z43: GOLD
A44: CUST1040 | B44: Eric Vega | C44: 50 | D44: Male | E44: Williamsonland | F44: Kansas | G44: USA | H44: Gold | J44: CUST1040 | K44: Eric Vega | L44: 50 | M44: Male | N44: Williamsonland | O44: Kansas | P44: USA | Q44: Gold | S44: CUST1040 | T44: ERIC VEGA | U44: 50 | V44: MALE | W44: WILLIAMSONLAND | X44: KANSAS | Y44: USA | Z44: GOLD
...

Sheet f Excel formulas for calculatio
A1: Customer_ID | B1: Name | C1: Age | D1: Gender | E1: City | F1: State | G1: Country | H1: Loyalty_Level
A2: CUST1000 | B2: sheena bonilla | C2: 55 | D2: Male | E2: Donaldton | F2: North Carolina | G2: USA
A3: CUST1001 | B3: Eugene Nelson | C3: 26 | D3: Female | E3: Phillipsmouth | F3: North Dakota | G3: USA | H3: Platinum
A4: CUST1002 | B4: dr. Benjamin Price | C4: 29 | D4: Female | E4: Kylebury | F4: Alabama | G4: USA | H4: Platinum
A5: CUST1003 | B5: jeremy harris | C5: 59 | D5: Female | E5: Thomastown | F5: Ohio | G5: USA | H5: Bronze
A6: CUST1004 | B6: Caroline Collins | C6: 64 | D6: Female | E6: Nicholasshire | F6: California | G6: USA | H6: Silver
A7: CUST1005 | B7: Christine Vaughn | C7: 24 | D7: Male | E7: East Amandamouth | F7: Oregon | G7: USA | H7: Bronze
A8: CUST1006 | B8: Amber Jackson | C8: 29 | D8: Female | E8: Deborahborough | F8: South Dakota | G8: USA | H8: Platinum
A9: CUST1007 | B9: Daniel Boyd | C9: 29 | D9: Female | E9: West Pamelafurt | F9: West Virginia | G9: USA | H9: Bronze
A10: CUST1008 | B10: Melissa Howard | C10: 53 | D10: Female | E10: Maynardton | F10: New Hampshire | G10: USA | H10: Gold
A11: CUST1009 | B11: Ms. Maria Leach | C11: 64 | D11: Male | E11: Melissashire | F11: Pennsylvania | G11: USA | H11: Platinum
A12: CUST1010 | B12: Dominic Page | C12: 53 | D12: Male | E12: Port Michaelburgh | F12: Pennsylvania | G12: USA | H12: Bronze
A13: CUST1011 | B13: Brian Lopez | C13: 28 | D13: Female | E13: East Krista | F13: New York | G13: USA | H13: Gold
A14: CUST1012 | B14: Kenneth Lambert | C14: 55 | D14: Female | E14: North Kathryn | F14: Kansas | G14: USA | H14: Platinum
... A19: CUST1017 | B19: Adam Cruz | C19: 60 | D19: Female | E19: Brandonville | F19: Georgia | G19: USA | H19: Platinum
A20: CUST1018 | B20: Rhonda Moss | C20: 43 | D20: Male | E20: South William | F20: Kansas | G20: USA
A21: CUST1019 | B21: Michael Torres | C21: 46 | D21: Female | E21: Gonzalezfort | F21: New Jersey | G21: USA | H21: Platinum
A22: CUST1020 | B22: Bridget Allen | C22: 59 | D22: Male | E22: Lake Shaneburgh | F22: Delaware | G22: USA | H22: Silver
A23: CUST1021 | B23: Jeff Martinez | C23: 36 | D23: Female | E23: Smithburgh | F23: Oklahoma | G23: USA | H23: Gold
A24: CUST1022 | B24: paul fox | C24: 33 | D24: Female | E24: Michaelton | F24: Hawaii | G24: USA | H24: Silver
A25: CUST1023 | B25: Jonathan Steele | C25: 52 | D25: Female | E25: Molinabury | F25: Oregon | G25: USA | H25: Silver
A26: CUST1024 | B26: Heather Collins | C26: 40 | D26: Male | E26: Rogerschester | F26: Idaho | G26: USA | H26: Platinum
A27: CUST1025 | B27: Diana Taylor | C27: 59 | D27: Female | E27: Vasqueztown | F27: California | G27: USA | H27: Bronze
A28: CUST1026 | B28: Amber Carlson | C28: 18 | D28: Female | E28: East Michellemouth | F28: Missouri | G28: USA | H28: Gold
A29: CUST1027 | B29: Leslie Johnson | C29: 31 | D29: Male | E29: Mollyshire | F29: Utah | G29: USA
A30: CUST1028 | B30: Joshua Ryan | C30: 27 | D30: Female | E30: New David | F30: New Jersey | G30: USA | H30: Platinum
A31: CUST1029 | B31: David Arnold | C31: 54 | D31: Female | E31: East Jennifer | F31: California | G31: USA | H31: Silver
A32: CUST1030 | B32: Jessica Acevedo | C32: 64 | D32: Female | E32: Amybury | F32: Pennsylvania | G32: USA | H32: Bronze
A33: CUST1031 | B33: Sarah Vance | C33: 41 | D33: Male | E33: Johnsonville | F33: Oregon | G33: USA | H33: Silver
A34: CUST1032 | B34: Mike Jennings | C34: 48 | D34: Female | E34: Fostermouth | F34: Arizona | G34: USA | H34: Gold
A35: CUST1033 | B35: Robert Jones DDS | C35: 25 | D35: Male | E35: Tristanton | F35: Oklahoma | G35: USA | H35: Platinum
A36: CUST1034 | B36: Christopher Olson | C36: 27 | D36: Female | E36: West Richard | F36: Maryland | G36: USA | H36: Platinum
A37: CUST1035 | B37: Rachel Myers | C37: 52 | D37: Male | E37: Robertberg | F37: North Dakota | G37: USA | H37: Silver
A38: CUST1036 | B38: Thomas Phillips | C38: 20 | D38: Female | E38: Luisfurt | F38: Georgia | G38: USA | H38: Gold
A39: CUST1037 | B39: Christopher Carter | C39: 27 | D39: Female | E39: Brendastad | F39: South Dakota | G39: USA
A40: CUST1038 | B40: Deanna Simpson | C40: 35 | D40: Female | E40: Brownport | F40: North Dakota | G40: USA | H40: Bronze
A41: CUST1039 | B41: Tonya Reynolds | C41: 55 | D41: Female | E41: Darleneton | F41: Michigan | G41: USA | H41: Gold
A42: CUST1040 | B42: Eric Vega | C42: 50 | D42: Male | E42: Williamsonland | F42: Kansas | G42: USA | H42: Gold
A43: CUST1041 | B43: James Gibbs | C43: 21 | D43: Male | E43: Mooneyshire | F43: Alaska | G43: USA | H43: Platinum
A44: CUST1042 | B44: William Martin | C44: 19 | D44: Male | E44: Ryanburgh | F44: Connecticut | G44: USA | H44: Platinum
...

Sheet  XLOOKUP VLOOKUP 
A1: Vlookup
A2: Customer_ID | B2: Name | C2: Age | D2: Gender | E2: City | F2: State | G2: Country | H2: Loyalty_Level
A3: CUST1000 | B3: =VLOOKUP(A3,'f Excel formulas for calculatio'!A:H,2,FALSE) -> sheena bonilla | C3: =VLOOKUP(A3,'f Excel formulas for calculatio'!A:H,3,FALSE) -> 55 | D3: =VLOOKUP(A3,'f Excel formulas for calculatio'!A:H,4,FALSE) -> Male | E3: =VLOOKUP(A3,'f Excel formulas for calculatio'!A:H,5,FALSE) -> Donaldton | F3: =VLOOKUP(A3,'f Excel formulas for calculatio'!A:H,6,FALSE) -> North Carolina | G3: =VLOOKUP(A3,'f Excel formulas for calculatio'!A:H,7,FALSE) -> USA | H3: =VLOOKUP(A3,'f Excel formulas for calculatio'!A:H,8,FALSE) -> 0
A4: CUST1001 | B4: =VLOOKUP(A4,'f Excel formulas for calculatio'!A:H,2,FALSE) -> Eugene Nelson | C4: =VLOOKUP(A4,'f Excel formulas for calculatio'!A:H,3,FALSE) -> 26 | D4: =VLOOKUP(A4,'f Excel formulas for calculatio'!A:H,4,FALSE) -> Female | E4: =VLOOKUP(A4,'f Excel formulas for calculatio'!A:H,5,FALSE) -> Phillipsmouth | F4: =VLOOKUP(A4,'f Excel formulas for calculatio'!A:H,6,FALSE) -> North Dakota | G4: =VLOOKUP(A4,'f Excel formulas for calculatio'!A:H,7,FALSE) -> USA | H4: =VLOOKUP(A4,'f Excel formulas for calculatio'!A:H,8,FALSE) -> Platinum
A5: CUST1002 | B5: =VLOOKUP(A5,'f Excel formulas for calculatio'!A:H,2,FALSE) -> dr. Benjamin Price | C5: =VLOOKUP(A5,'f Excel formulas for calculatio'!A:H,3,FALSE) -> 29 | D5: =VLOOKUP(A5,'f Excel formulas for calculatio'!A:H,4,FALSE) -> Female | E5: =VLOOKUP(A5,'f Excel formulas for calculatio'!A:H,5,FALSE) -> Kylebury | F5: =VLOOKUP(A5,'f Excel formulas for calculatio'!A:H,6,FALSE) -> Alabama | G5: =VLOOKUP(A5,'f Excel formulas for calculatio'!A:H,7,FALSE) -> USA | H5: =VLOOKUP(A5,'f Excel formulas for calculatio'!A:H,8,FALSE) -> Platinum
A6: CUST1003 | B6: =VLOOKUP(A6,'f Excel formulas for calculatio'!A:H,2,FALSE) -> jeremy harris | C6: =VLOOKUP(A6,'f Excel formulas for calculatio'!A:H,3,FALSE) -> 59 | D6: =VLOOKUP(A6,'f Excel formulas for calculatio'!A:H,4,FALSE) -> Female | E6: =VLOOKUP(A6,'f Excel formulas for calculatio'!A:H,5,FALSE) -> Thomastown | F6: =VLOOKUP(A6,'f Excel formulas for calculatio'!A:H,6,FALSE) -> Ohio | G6: =VLOOKUP(A6,'f Excel formulas for calculatio'!A:H,7,FALSE) -> USA | H6: =VLOOKUP(A6,'f Excel formulas for calculatio'!A:H,8,FALSE) -> Bronze
A7: CUST1004 | B7: =VLOOKUP(A7,'f Excel formulas for calculatio'!A:H,2,FALSE) -> Caroline Collins | C7: =VLOOKUP(A7,'f Excel formulas for calculatio'!A:H,3,FALSE) -> 64 | D7: =VLOOKUP(A7,'f Excel formulas for calculatio'!A:H,4,FALSE) -> Female | E7: =VLOOKUP(A7,'f Excel formulas for calculatio'!A:H,5,FALSE) -> Nicholasshire | F7: =VLOOKUP(A7,'f Excel formulas for calculatio'!A:H,6,FALSE) -> California | G7: =VLOOKUP(A7,'f Excel formulas for calculatio'!A:H,7,FALSE) -> USA | H7: =VLOOKUP(A7,'f Excel formulas for calculatio'!A:H,8,FALSE) -> Silver
A8: CUST1005 | B8: =VLOOKUP(A8,'f Excel formulas for calculatio'!A:H,2,FALSE) -> Christine Vaughn | C8: =VLOOKUP(A8,'f Excel formulas for calculatio'!A:H,3,FALSE) -> 24 | D8: =VLOOKUP(A8,'f Excel formulas for calculatio'!A:H,4,FALSE) -> Male | E8: =VLOOKUP(A8,'f Excel formulas for calculatio'!A:H,5,FALSE) -> East Amandamouth | F8: =VLOOKUP(A8,'f Excel formulas for calculatio'!A:H,6,FALSE) -> Oregon | G8: =VLOOKUP(A8,'f Excel formulas for calculatio'!A:H,7,FALSE) -> USA | H8: =VLOOKUP(A8,'f Excel formulas for calculatio'!A:H,8,FALSE) -> Bronze
A9: CUST1006 | B9: =VLOOKUP(A9,'f Excel formulas for calculatio'!A:H,2,FALSE) -> Amber Jackson | C9: =VLOOKUP(A9,'f Excel formulas for calculatio'!A:H,3,FALSE) -> 29 | D9: =VLOOKUP(A9,'f Excel formulas for calculatio'!A:H,4,FALSE) -> Female | E9: =VLOOKUP(A9,'f Excel formulas for calculatio'!A:H,5,FALSE) -> Deborahborough | F9: =VLOOKUP(A9,'f Excel formulas for calculatio'!A:H,6,FALSE) -> South Dakota | G9: =VLOOKUP(A9,'f Excel formulas for calculatio'!A:H,7,FALSE) -> USA | H9: =VLOOKUP(A9,'f Excel formulas for calculatio'!A:H,8,FALSE) -> Platinum
A10: CUST1007 | B10: =VLOOKUP(A10,'f Excel formulas for calculatio'!A:H,2,FALSE) -> Daniel Boyd | C10: =VLOOKUP(A10,'f Excel formulas for calculatio'!A:H,3,FALSE) -> 29 | D10: =VLOOKUP(A10,'f Excel formulas for calculatio'!A:H,4,FALSE) -> Female | E10: =VLOOKUP(A10,'f Excel formulas for calculatio'!A:H,5,FALSE) -> West Pamelafurt | F10: =VLOOKUP(A10,'f Excel formulas for calculatio'!A:H,6,FALSE) -> West Virginia | G10: =VLOOKUP(A10,'f Excel formulas for calculatio'!A:H,7,FALSE) -> USA | H10: =VLOOKUP(A10,'f Excel formulas for calculatio'!A:H,8,FALSE) -> Bronze
A11: CUST1008 | B11: =VLOOKUP(A11,'f Excel formulas for calculatio'!A:H,2,FALSE) -> Melissa Howard | C11: =VLOOKUP(A11,'f Excel formulas for calculatio'!A:H,3,FALSE) -> 53 | D11: =VLOOKUP(A11,'f Excel formulas for calculatio'!A:H,4,FALSE) -> Female | E11: =VLOOKUP(A11,'f Excel formulas for calculatio'!A:H,5,FALSE) -> Maynardton | F11: =VLOOKUP(A11,'f Excel formulas for calculatio'!A:H,6,FALSE) -> New Hampshire | G11: =VLOOKUP(A11,'f Excel formulas for calculatio'!A:H,7,FALSE) -> USA | H11: =VLOOKUP(A11,'f Excel formulas for calculatio'!A:H,8,FALSE) -> Gold
A12: CUST1009 | B12: =VLOOKUP(A12,'f Excel formulas for calculatio'!A:H,2,FALSE) -> Ms. Maria Leach | C12: =VLOOKUP(A12,'f Excel formulas for calculatio'!A:H,3,FALSE) -> 64 | D12: =VLOOKUP(A12,'f Excel formulas for calculatio'!A:H,4,FALSE) -> Male | E12: =VLOOKUP(A12,'f Excel formulas for calculatio'!A:H,5,FALSE) -> Melissashire | F12: =VLOOKUP(A12,'f Excel formulas for calculatio'!A:H,6,FALSE) -> Pennsylvania | G12: =VLOOKUP(A12,'f Excel formulas for calculatio'!A:H,7,FALSE) -> USA | H12: =VLOOKUP(A12,'f Excel formulas for calculatio'!A:H,8,FALSE) -> Platinum
A13: CUST1010 | B13: =VLOOKUP(A13,'f Excel formulas for calculatio'!A:H,2,FALSE) -> Dominic Page | C13: =VLOOKUP(A13,'f Excel formulas for calculatio'!A:H,3,FALSE) -> 53 | D13: =VLOOKUP(A13,'f Excel formulas for calculatio'!A:H,4,FALSE) -> Male | E13: =VLOOKUP(A13,'f Excel formulas for calculatio'!A:H,5,FALSE) -> Port Michaelburgh | F13: =VLOOKUP(A13,'f Excel formulas for calculatio'!A:H,6,FALSE) -> Pennsylvania | G13: =VLOOKUP(A13,'f Excel formulas for calculatio'!A:H,7,FALSE) -> USA | H13: =VLOOKUP(A13,'f Excel formulas for calculatio'!A:H,8,FALSE) -> Bronze
A14: CUST1011 | B14: =VLOOKUP(A14,'f Excel formulas for calculatio'!A:H,2,FALSE) -> Brian Lopez | C14: =VLOOKUP(A14,'f Excel formulas for calculatio'!A:H,3,FALSE) -> 28 | D14: =VLOOKUP(A14,'f Excel formulas for calculatio'!A:H,4,FALSE) -> Female | E14: =VLOOKUP(A14,'f Excel formulas for calculatio'!A:H,5,FALSE) -> East Krista | F14: =VLOOKUP(A14,'f Excel formulas for calculatio'!A:H,6,FALSE) -> New York | G14: =VLOOKUP(A14,'f Excel formulas for calculatio'!A:H,7,FALSE) -> USA | H14: =VLOOKUP(A14,'f Excel formulas for calculatio'!A:H,8,FALSE) -> Gold
... A502: CUST1499 | B502: =VLOOKUP(A502,'f Excel formulas for calculatio'!A:H,2,FALSE) -> Philip Pennington | C502: =VLOOKUP(A502,'f Excel formulas for calculatio'!A:H,3,FALSE) -> 27 | D502: =VLOOKUP(A502,'f Excel formulas for calculatio'!A:H,4,FALSE) -> Female | E502: =VLOOKUP(A502,'f Excel formulas for calculatio'!A:H,5,FALSE) -> East Valerieview | F502: =VLOOKUP(A502,'f Excel formulas for calculatio'!A:H,6,FALSE) -> Oregon | G502: =VLOOKUP(A502,'f Excel formulas for calculatio'!A:H,7,FALSE) -> USA | H502: =VLOOKUP(A502,'f Excel formulas for calculatio'!A:H,8,FALSE) -> Platinum

Sheet Pivot Tables
A3: Row Labels | B3: Count of Customer_ID
A4: Alabama
A5: Female
A6: 29 | B6: 1
A7: 34 | B7: 1
A8: 40 | B8: 1
A9: 56 | B9: 1
A10: 60 | B10: 1
A11: Male
A12: 28 | B12: 1
A13: 46 | B13: 1
A14: 50 | B14: 1
A15: 64 | B15: 1
A16: Alaska
A17: Female
A18: 18 | B18: 1
A19: 22 | B19: 1
A20: 26 | B20: 1
A21: 49 | B21: 1
A22: 63 | B22: 1
A23: Male
A24: 21 | B24: 1
A25: 24 | B25: 1
A26: 31 | B26: 1
A27: 34 | B27: 1
A28: 54 | B28: 1
A29: 60 | B29: 1
A30: Arizona
A31: Female
A32: 18 | B32: 2
A33: 29 | B33: 1
A34: 34 | B34: 1
A35: 48 | B35: 1
A36: 52 | B36: 1
A37: 62 | B37: 1
A38: 63 | B38: 1
A39: Male
A40: 33 | B40: 1
A41: 36 | B41: 1
A42: 54 | B42: 1
...

Sheet Descriptive statistics
B2: Customer_ID | C2: Name | D2: Age | E2: Gender | F2: City | G2: State | H2: Country | I2: Loyalty_Level | K2: Age
B3: CUST1000 | C3: sheena bonilla | D3: 55 | E3: Male | F3: Donaldton | G3: North Carolina | H3: USA
B4: CUST1001 | C4: Eugene Nelson | D4: 26 | E4: Female | F4: Phillipsmouth | G4: North Dakota | H4: USA | I4: Platinum | K4: Mean | L4: 41.562
B5: CUST1002 | C5: dr. Benjamin Price | D5: 29 | E5: Female | F5: Kylebury | G5: Alabama | H5: USA | I5: Platinum | K5: Standard Error | L5: 0.61138523
B6: CUST1003 | C6: jeremy harris | D6: 59 | E6: Female | F6: Thomastown | G6: Ohio | H6: USA | I6: Bronze | K6: Median | L6: 42
B7: CUST1004 | C7: Caroline Collins | D7: 64 | E7: Female | F7: Nicholasshire | G7: California | H7: USA | I7: Silver | K7: Mode | L7: 46
B8: CUST1005 | C8: Christine Vaughn | D8: 24 | E8: Male | F8: East Amandamouth | G8: Oregon | H8: USA | I8: Bronze | K8: Standard Deviation | L8: 13.670989
B9: CUST1006 | C9: Amber Jackson | D9: 29 | E9: Female | F9: Deborahborough | G9: South Dakota | H9: USA | I9: Platinum | K9: Sample Variance | L9: 186.89595
B10: CUST1007 | C10: Daniel Boyd | D10: 29 | E10: Female | F10: West Pamelafurt | G10: West Virginia | H10: USA | I10: Bronze | K10: Kurtosis | L10: -1.219392
B11: CUST1008 | C11: Melissa Howard | D11: 53 | E11: Female | F11: Maynardton | G11: New Hampshire | H11: USA | I11: Gold | K11: Skewness | L11: -0.03654853
B12: CUST1009 | C12: Ms. Maria Leach | D12: 64 | E12: Male | F12: Melissashire | G12: Pennsylvania | H12: USA | I12: Platinum | K12: Range | L12: 46
B13: CUST1010 | C13: Dominic Page | D13: 53 | E13: Male | F13: Port Michaelburgh | G13: Pennsylvania | H13: USA | I13: Bronze | K13: Minimum | L13: 18
B14: CUST1011 | C14: Brian Lopez | D14: 28 | E14: Female | F14: East Krista | G14: New York | H14: USA | I14: Gold | K14: Maximum | L14: 64
B15: CUST1012 | C15: Kenneth Lambert | D15: 55 | E15: Female | F15: North Kathryn | G15: Kansas | H15: USA | I15: Platinum | K15: Sum | L15: 20781
B16: CUST1013 | C16: Nathan Hernandez | D16: 32 | E16: Female | F16: New Becky | G16: Montana | H16: USA | I16: Silver | K16: Count | L16: 500
B17: CUST1014 | C17: Ashley Cohen | D17: 53 | E17: Female | F17: Lake Kristamouth | G17: Nebraska | H17: USA | I17: Silver
B18: CUST1015 | C18: Laura Alvarez | D18: 49 | E18: Female | F18: Lawsonhaven | G18: Washington | H18: USA | I18: Platinum
B19: CUST1016 | C19: John Scott | D19: 24 | E19: Female | F19: South Christopher | G19: Pennsylvania | H19: USA | I19: Bronze
B20: CUST1017 | C20: Adam Cruz | D20: 60 | E20: Female | F20: Brandonville | G20: Georgia | H20: USA | I20: Platinum
B21: CUST1018 | C21: Rhonda Moss | D21: 43 | E21: Male | F21: South William | G21: Kansas | H21: USA
B22: CUST1019 | C22: Michael Torres | D22: 46 | E22: Female | F22: Gonzalezfort | G22: New Jersey | H22: USA | I22: Platinum
B23: CUST1020 | C23: Bridget Allen | D23: 59 | E23: Male | F23: Lake Shaneburgh | G23: Delaware | H23: USA | I23: Silver
B24: CUST1021 | C24: Jeff Martinez | D24: 36 | E24: Female | F24: Smithburgh | G24: Oklahoma | H24: USA | I24: Gold
B25: CUST1022 | C25: paul fox | D25: 33 | E25: Female | F25: Michaelton | G25: Hawaii | H25: USA | I25: Silver
B26: CUST1023 | C26: Jonathan Steele | D26: 52 | E26: Female | F26: Molinabury | G26: Oregon | H26: USA | I26: Silver
B27: CUST1024 | C27: Heather Collins | D27: 40 | E27: Male | F27: Rogerschester | G27: Idaho | H27: USA | I27: Platinum
B28: CUST1025 | C28: Diana Taylor | D28: 59 | E28: Female | F28: Vasqueztown | G28: California | H28: USA | I28: Bronze
B29: CUST1026 | C29: Amber Carlson | D29: 18 | E29: Female | F29: East Michellemouth | G29: Missouri | H29: USA | I29: Gold
B30: CUST1027 | C30: Leslie Johnson | D30: 31 | E30: Male | F30: Mollyshire | G30: Utah | H30: USA
B31: CUST1028 | C31: Joshua Ryan | D31: 27 | E31: Female | F31: New David | G31: New Jersey | H31: USA | I31: Platinum
B32: CUST1029 | C32: David Arnold | D32: 54 | E32: Female | F32: East Jennifer | G32: California | H32: USA | I32: Silver
B33: CUST1030 | C33: Jessica Acevedo | D33: 64 | E33: Female | F33: Amybury | G33: Pennsylvania | H33: USA | I33: Bronze
B34: CUST1031 | C34: Sarah Vance | D34: 41 | E34: Male | F34: Johnsonville | G34: Oregon | H34: USA | I34: Silver
B35: CUST1032 | C35: Mike Jennings | D35: 48 | E35: Female | F35: Fostermouth | G35: Arizona | H35: USA | I35: Gold
B36: CUST1033 | C36: Robert Jones DDS | D36: 25 | E36: Male | F36: Tristanton | G36: Oklahoma | H36: USA | I36: Platinum
B37: CUST1034 | C37: Christopher Olson | D37: 27 | E37: Female | F37: West Richard | G37: Maryland | H37: USA | I37: Platinum
B38: CUST1035 | C38: Rachel Myers | D38: 52 | E38: Male | F38: Robertberg | G38: North Dakota | H38: USA | I38: Silver
B39: CUST1036 | C39: Thomas Phillips | D39: 20 | E39: Female | F39: Luisfurt | G39: Georgia | H39: USA | I39: Gold
B40: CUST1037 | C40: Christopher Carter | D40: 27 | E40: Female | F40: Brendastad | G40: South Dakota | H40: USA
B41: CUST1038 | C41: Deanna Simpson | D41: 35 | E41: Female | F41: Brownport | G41: North Dakota | H41: USA | I41: Bronze
...

Sheet pivt chart
A1: Row Labels | B1: Sum of Age
A2: Bronze | B2: 5137
A3: Female | B3: 2490
A4: Male | B4: 2647
A5: Gold | B5: 4956
A6: Female | B6: 2849
A7: Male | B7: 2107
A8: Platinum | B8: 6265
A9: Female | B9: 3515
A10: Male | B10: 2750
A11: Silver | B11: 4267
A12: Female | B12: 2060
A13: Male | B13: 2207
... A17: Grand Total | B17: 20781

Sheet ●Data visualization
S1: Customer_ID | T1: Name | U1: Age | V1: Gender | W1: City | X1: State | Y1: Country | Z1: Loyalty_Level
S2: CUST1000 | T2: sheena bonilla | U2: 55 | V2: Male | W2: Donaldton | X2: North Carolina | Y2: USA
S3: CUST1001 | T3: Eugene Nelson | U3: 26 | V3: Female | W3: Phillipsmouth | X3: North Dakota | Y3: USA | Z3: Platinum
S4: CUST1002 | T4: dr. Benjamin Price | U4: 29 | V4: Female | W4: Kylebury | X4: Alabama | Y4: USA | Z4: Platinum
S5: CUST1003 | T5: jeremy harris | U5: 59 | V5: Female | W5: Thomastown | X5: Ohio | Y5: USA | Z5: Bronze
S6: CUST1004 | T6: Caroline Collins | U6: 64 | V6: Female | W6: Nicholasshire | X6: California | Y6: USA | Z6: Silver
S7: CUST1005 | T7: Christine Vaughn | U7: 24 | V7: Male | W7: East Amandamouth | X7: Oregon | Y7: USA | Z7: Bronze
S8: CUST1006 | T8: Amber Jackson | U8: 29 | V8: Female | W8: Deborahborough | X8: South Dakota | Y8: USA | Z8: Platinum
S9: CUST1007 | T9: Daniel Boyd | U9: 29 | V9: Female | W9: West Pamelafurt | X9: West Virginia | Y9: USA | Z9: Bronze
S10: CUST1008 | T10: Melissa Howard | U10: 53 | V10: Female | W10: Maynardton | X10: New Hampshire | Y10: USA | Z10: Gold
S11: CUST1009 | T11: Ms. Maria Leach | U11: 64 | V11: Male | W11: Melissashire | X11: Pennsylvania | Y11: USA | Z11: Platinum
S12: CUST1010 | T12: Dominic Page | U12: 53 | V12: Male | W12: Port Michaelburgh | X12: Pennsylvania | Y12: USA | Z12: Bronze
S13: CUST1011 | T13: Brian Lopez | U13: 28 | V13: Female | W13: East Krista | X13: New York | Y13: USA | Z13: Gold
S14: CUST1012 | T14: Kenneth Lambert | U14: 55 | V14: Female | W14: North Kathryn | X14: Kansas | Y14: USA | Z14: Platinum
... S19: CUST1017 | T19: Adam Cruz | U19: 60 | V19: Female | W19: Brandonville | X19: Georgia | Y19: USA | Z19: Platinum
S20: CUST1018 | T20: Rhonda Moss | U20: 43 | V20: Male | W20: South William | X20: Kansas | Y20: USA
S21: CUST1019 | T21: Michael Torres | U21: 46 | V21: Female | W21: Gonzalezfort | X21: New Jersey | Y21: USA | Z21: Platinum
S22: CUST1020 | T22: Bridget Allen | U22: 59 | V22: Male | W22: Lake Shaneburgh | X22: Delaware | Y22: USA | Z22: Silver
S23: CUST1021 | T23: Jeff Martinez | U23: 36 | V23: Female | W23: Smithburgh | X23: Oklahoma | Y23: USA | Z23: Gold
S24: CUST1022 | T24: paul fox | U24: 33 | V24: Female | W24: Michaelton | X24: Hawaii | Y24: USA | Z24: Silver
S25: CUST1023 | T25: Jonathan Steele | U25: 52 | V25: Female | W25: Molinabury | X25: Oregon | Y25: USA | Z25: Silver
S26: CUST1024 | T26: Heather Collins | U26: 40 | V26: Male | W26: Rogerschester | X26: Idaho | Y26: USA | Z26: Platinum
S27: CUST1025 | T27: Diana Taylor | U27: 59 | V27: Female | W27: Vasqueztown | X27: California | Y27: USA | Z27: Bronze
S28: CUST1026 | T28: Amber Carlson | U28: 18 | V28: Female | W28: East Michellemouth | X28: Missouri | Y28: USA | Z28: Gold
S29: CUST1027 | T29: Leslie Johnson | U29: 31 | V29: Male | W29: Mollyshire | X29: Utah | Y29: USA
S30: CUST1028 | T30: Joshua Ryan | U30: 27 | V30: Female | W30: New David | X30: New Jersey | Y30: USA | Z30: Platinum
S31: CUST1029 | T31: David Arnold | U31: 54 | V31: Female | W31: East Jennifer | X31: California | Y31: USA | Z31: Silver
S32: CUST1030 | T32: Jessica Acevedo | U32: 64 | V32: Female | W32: Amybury | X32: Pennsylvania | Y32: USA | Z32: Bronze
S33: CUST1031 | T33: Sarah Vance | U33: 41 | V33: Male | W33: Johnsonville | X33: Oregon | Y33: USA | Z33: Silver
S34: CUST1032 | T34: Mike Jennings | U34: 48 | V34: Female | W34: Fostermouth | X34: Arizona | Y34: USA | Z34: Gold
S35: CUST1033 | T35: Robert Jones DDS | U35: 25 | V35: Male | W35: Tristanton | X35: Oklahoma | Y35: USA | Z35: Platinum
S36: CUST1034 | T36: Christopher Olson | U36: 27 | V36: Female | W36: West Richard | X36: Maryland | Y36: USA | Z36: Platinum
S37: CUST1035 | T37: Rachel Myers | U37: 52 | V37: Male | W37: Robertberg | X37: North Dakota | Y37: USA | Z37: Silver
S38: CUST1036 | T38: Thomas Phillips | U38: 20 | V38: Female | W38: Luisfurt | X38: Georgia | Y38: USA | Z38: Gold
S39: CUST1037 | T39: Christopher Carter | U39: 27 | V39: Female | W39: Brendastad | X39: South Dakota | Y39: USA
S40: CUST1038 | T40: Deanna Simpson | U40: 35 | V40: Female | W40: Brownport | X40: North Dakota | Y40: USA | Z40: Bronze
S41: CUST1039 | T41: Tonya Reynolds | U41: 55 | V41: Female | W41: Darleneton | X41: Michigan | Y41: USA | Z41: Gold
S42: CUST1040 | T42: Eric Vega | U42: 50 | V42: Male | W42: Williamsonland | X42: Kansas | Y42: USA | Z42: Gold
S43: CUST1041 | T43: James Gibbs | U43: 21 | V43: Male | W43: Mooneyshire | X43: Alaska | Y43: USA | Z43: Platinum
S44: CUST1042 | T44: William Martin | U44: 19 | V44: Male | W44: Ryanburgh | X44: Connecticut | Y44: USA | Z44: Platinum
...
