Workbook
Name Slicer_Payment_Type: #N/A
Name Slicer_Quantity: #N/A

Sheet Data 
A1: Sales_ID | B1: Order_Date | C1: Customer_ID | D1: Product_ID | E1: Store_ID | F1: Quantity | G1: Unit_Price | H1: Discount | I1: Payment_Type | J1: Total_Amount
A2: SALE0 | B2: 45480 | C2: CUST1409 | D2: PROD97 | E2: STORE3 | F2: 1 | G2: 218.04 | H2: 0.09 | I2: Credit Card | J2: 198.4164
A3: SALE1 | B3: 45285 | C3: CUST1467 | D3: PROD74 | E3: STORE17 | F3: 3 | G3: 104.47 | H3: 0.27 | I3: PayPal | J3: 228.7893
A4: SALE2 | B4: 45446 | C4: CUST1056 | D4: PROD49 | E4: STORE8 | F4: 4 | G4: 914.05 | H4: 0.25 | I4: Credit Card | J4: 2742.15
A5: SALE3 | B5: 45259 | C5: CUST1346 | D5: PROD76 | E5: STORE8 | F5: 1 | G5: 921.51 | H5: 0.16 | I5: COD | J5: 774.0684
A6: SALE4 | B6: 45297 | C6: CUST1493 | D6: PROD59 | E6: STORE5 | F6: 3 | G6: 745.3 | H6: 0.18 | I6: Credit Card | J6: 1833.438
A7: SALE5 | B7: 45499 | C7: CUST1116 | D7: PROD15 | E7: STORE7 | F7: 3 | G7: 147.01 | H7: 0.19 | I7: COD | J7: 357.2343
A8: SALE6 | B8: 45850 | C8: CUST1016 | D8: PROD56 | E8: STORE4 | F8: 2 | G8: 785.31 | H8: 0.15 | I8: PayPal | J8: 1335.027
A9: SALE7 | B9: 45248 | C9: CUST1152 | D9: PROD70 | E9: STORE8 | F9: 4 | G9: 342.39 | H9: 0.23 | I9: PayPal | J9: 1054.5612
A10: SALE8 | B10: 45781 | C10: CUST1187 | D10: PROD99 | E10: STORE5 | G10: 448.25 | H10: 0.07 | I10: PayPal | J10: 1250.6175
A11: SALE9 | B11: 45869 | C11: CUST1464 | D11: PROD33 | E11: STORE0 | F11: 2 | G11: 873.17 | H11: 0.23 | I11: PayPal | J11: 1344.6818
A12: SALE10 | B12: 45335 | C12: CUST1065 | D12: PROD24 | E12: STORE14 | F12: 1 | G12: 278.63 | H12: 0.07 | I12: Credit Card | J12: 259.1259
A13: SALE11 | B13: 45801 | C13: CUST1320 | D13: PROD39 | E13: STORE1 | F13: 4 | G13: 286.92 | H13: 0.17 | I13: Credit Card | J13: 952.5744
A14: SALE12 | B14: 45528 | C14: CUST1237 | D14: PROD88 | E14: STORE4 | F14: 4 | G14: 644.58 | H14: 0.01 | I14: Credit Card | J14: 2552.5368
A15: SALE13 | B15: 45875 | C15: CUST1443 | D15: PROD34 | E15: STORE16 | F15: 2 | G15: 316.9 | H15: 0.3 | I15: PayPal | J15: 443.66
A16: SALE14 | B16: 45829 | C16: CUST1348 | D16: PROD24 | E16: STORE15 | F16: 4 | G16: 403.47 | H16: 0.29 | I16: PayPal | J16: 1145.8548
A17: SALE15 | B17: 45636 | C17: CUST1435 | D17: PROD36 | E17: STORE9 | G17: 871.34 | H17: 0.04 | I17: COD | J17: 2509.4592
A18: SALE16 | B18: 45913 | C18: CUST1276 | D18: PROD65 | E18: STORE19 | F18: 2 | G18: 451.98 | H18: 0.25 | I18: Credit Card | J18: 677.97
A19: SALE17 | B19: 45637 | C19: CUST1079 | D19: PROD27 | E19: STORE4 | F19: 2 | G19: 502.69 | H19: 0.23 | I19: Credit Card | J19: 774.1426
A20: SALE18 | B20: 45517 | C20: CUST1094 | D20: PROD39 | E20: STORE4 | F20: 2 | G20: 559.23 | H20: 0.25 | I20: COD | J20: 838.845
A21: SALE19 | B21: 45369 | C21: CUST1239 | D21: PROD60 | E21: STORE13 | F21: 4 | H21: 0.04 | I21: COD | J21: 1782.4512
A22: SALE20 | B22: 45843 | C22: CUST1144 | D22: PROD72 | E22: STORE17 | F22: 3 | G22: 986.04 | H22: 0.27 | I22: COD | J22: 2159.4276
A23: SALE21 | B23: 45447 | C23: CUST1396 | D23: PROD43 | E23: STORE18 | F23: 1 | G23: 589.56 | H23: 0.22 | I23: Credit Card | J23: 459.8568
A24: SALE22 | B24: 45394 | C24: CUST1476 | D24: PROD69 | E24: STORE10 | F24: 3 | G24: 979.42 | H24: 0.03 | I24: PayPal | J24: 2850.1122
A25: SALE23 | B25: 45466 | C25: CUST1368 | D25: PROD12 | E25: STORE8 | F25: 1 | G25: 719.28 | H25: 0.08 | I25: Credit Card | J25: 661.7376
A26: SALE24 | B26: 45908 | C26: CUST1186 | D26: PROD67 | E26: STORE6 | F26: 3 | G26: 77.6 | H26: 0.07 | I26: Credit Card | J26: 216.504
A27: SALE25 | B27: 45552 | C27: CUST1381 | D27: PROD5 | E27: STORE3 | F27: 4 | G27: 852.71 | H27: 0.14 | I27: PayPal | J27: 2933.3224
A28: SALE26 | B28: 45294 | C28: CUST1213 | D28: PROD98 | E28: STORE8 | F28: 4 | G28: 156.16 | I28: Credit Card | J28: 599.6544
A29: SALE27 | B29: 45710 | C29: CUST1200 | D29: PROD77 | E29: STORE8 | F29: 3 | G29: 815.49 | H29: 0.17 | I29: Credit Card | J29: 2030.5701
A30: SALE28 | B30: 45923 | C30: CUST1148 | D30: PROD13 | E30: STORE2 | F30: 2 | G30: 74.21 | H30: 0.11 | I30: PayPal | J30: 132.0938
A31: SALE29 | B31: 45302 | C31: CUST1348 | D31: PROD99 | E31: STORE3 | G31: 451.67 | H31: 0.15 | I31: Credit Card | J31: 1535.678
A32: SALE30 | B32: 45217 | C32: CUST1028 | D32: PROD5 | E32: STORE19 | F32: 1 | G32: 429.38 | H32: 0.13 | I32: PayPal | J32: 373.5606
A33: SALE31 | B33: 45593 | C33: CUST1412 | D33: PROD53 | E33: STORE12 | F33: 2 | G33: 148.96 | H33: 0.03 | I33: COD | J33: 288.9824
A34: SALE32 | B34: 45597 | C34: CUST1398 | D34: PROD75 | E34: STORE8 | F34: 4 | G34: 313.83 | H34: 0.08 | I34: Credit Card | J34: 1154.8944
A35: SALE33 | B35: 45620 | C35: CUST1453 | D35: PROD12 | E35: STORE6 | F35: 2 | G35: 717.31 | H35: 0.15 | I35: Credit Card | J35: 1219.427
A36: SALE34 | B36: 45215 | C36: CUST1344 | D36: PROD79 | E36: STORE1 | G36: 873.22 | H36: 0.18 | I36: Credit Card | J36: 2148.1212
A37: SALE35 | B37: 45878 | C37: CUST1218 | D37: PROD16 | E37: STORE3 | F37: 4 | G37: 109.36 | H37: 0.19 | I37: COD | J37: 354.3264
A38: SALE36 | B38: 45635 | C38: CUST1086 | D38: PROD5 | E38: STORE7 | F38: 3 | G38: 559.52 | H38: 0.16 | I38: PayPal | J38: 1409.9904
A39: SALE37 | B39: 45329 | C39: CUST1492 | D39: PROD10 | E39: STORE17 | F39: 3 | G39: 121.76 | H39: 0.27 | I39: PayPal | J39: 266.6544
A40: SALE38 | B40: 45378 | C40: CUST1189 | D40: PROD33 | E40: STORE13 | F40: 4 | G40: 735.32 | H40: 0.06 | I40: COD | J40: 2764.8032
...

Sheet Data cleaning
A1: 2 | B1: find/remove duplicates - No duplicate | J1: validate data | K1: handle missing/inconsistent data
A3: Sales_ID | B3: Order_Date | C3: Customer_ID | D3: Product_ID | E3: Store_ID | F3: Quantity | G3: Unit_Price | H3: Discount | I3: Payment_Type | J3: Total_Amount | L3: {=TRIM(Table14[#All])} -> Sales_ID | M3: Order_Date | N3: Customer_ID | O3: Product_ID | P3: Store_ID | Q3: Quantity | R3: Unit_Price | S3: Discount | T3: Payment_Type | U3: Total_Amount | W3: {=PROPER(L3:U2003)} -> Sales_Id | X3: Order_Date | Y3: Customer_Id | Z3: Product_Id | AA3: Store_Id | AB3: Quantity | AC3: Unit_Price | AD3: Discount | AE3: Payment_Type | AF3: Total_Amount
A4: SALE0 | B4: 45480 | C4: CUST1409 | D4: PROD97 | E4: STORE3 | F4: 1 | G4: 218.04 | H4: 0.09 | I4: Credit Card | J4: 198.4164 | L4: SALE0 | M4: 45480 | N4: CUST1409 | O4: PROD97 | P4: STORE3 | Q4: 1 | R4: 218.04 | S4: 0.09 | T4: Credit Card | U4: 198.4164 | W4: Sale0 | X4: 45480 | Y4: Cust1409 | Z4: Prod97 | AA4: Store3 | AB4: 1 | AC4: 218.04 | AD4: 0.09 | AE4: Credit Card | AF4: 198.4164
A5: SALE1 | B5: 45285 | C5: CUST1467 | D5: PROD74 | E5: STORE17 | F5: 3 | G5: 104.47 | H5: 0.27 | I5: PayPal | J5: 228.7893 | L5: SALE1 | M5: 45285 | N5: CUST1467 | O5: PROD74 | P5: STORE17 | Q5: 3 | R5: 104.47 | S5: 0.27 | T5: PayPal | U5: 228.7893 | W5: Sale1 | X5: 45285 | Y5: Cust1467 | Z5: Prod74 | AA5: Store17 | AB5: 3 | AC5: 104.47 | AD5: 0.27 | AE5: Paypal | AF5: 228.7893
A6: SALE2 | B6: 45446 | C6: CUST1056 | D6: PROD49 | E6: STORE8 | F6: 4 | G6: 914.05 | H6: 0.25 | I6: Credit Card | J6: 2742.15 | L6: SALE2 | M6: 45446 | N6: CUST1056 | O6: PROD49 | P6: STORE8 | Q6: 4 | R6: 914.05 | S6: 0.25 | T6: Credit Card | U6: 2742.15 | W6: Sale2 | X6: 45446 | Y6: Cust1056 | Z6: Prod49 | AA6: Store8 | AB6: 4 | AC6: 914.05 | AD6: 0.25 | AE6: Credit Card | AF6: 2742.15
A7: SALE3 | B7: 45259 | C7: CUST1346 | D7: PROD76 | E7: STORE8 | F7: 1 | G7: 921.51 | H7: 0.16 | I7: COD | J7: 774.0684 | L7: SALE3 | M7: 45259 | N7: CUST1346 | O7: PROD76 | P7: STORE8 | Q7: 1 | R7: 921.51 | S7: 0.16 | T7: COD | U7: 774.0684 | W7: Sale3 | X7: 45259 | Y7: Cust1346 | Z7: Prod76 | AA7: Store8 | AB7: 1 | AC7: 921.51 | AD7: 0.16 | AE7: Cod | AF7: 774.0684
A8: SALE4 | B8: 45297 | C8: CUST1493 | D8: PROD59 | E8: STORE5 | F8: 3 | G8: 745.3 | H8: 0.18 | I8: Credit Card | J8: 1833.438 | L8: SALE4 | M8: 45297 | N8: CUST1493 | O8: PROD59 | P8: STORE5 | Q8: 3 | R8: 745.3 | S8: 0.18 | T8: Credit Card | U8: 1833.438 | W8: Sale4 | X8: 45297 | Y8: Cust1493 | Z8: Prod59 | AA8: Store5 | AB8: 3 | AC8: 745.3 | AD8: 0.18 | AE8: Credit Card | AF8: 1833.438
A9: SALE5 | B9: 45499 | C9: CUST1116 | D9: PROD15 | E9: STORE7 | F9: 3 | G9: 147.01 | H9: 0.19 | I9: COD | J9: 357.2343 | L9: SALE5 | M9: 45499 | N9: CUST1116 | O9: PROD15 | P9: STORE7 | Q9: 3 | R9: 147.01 | S9: 0.19 | T9: COD | U9: 357.2343 | W9: Sale5 | X9: 45499 | Y9: Cust1116 | Z9: Prod15 | AA9: Store7 | AB9: 3 | AC9: 147.01 | AD9: 0.19 | AE9: Cod | AF9: 357.2343
A10: SALE6 | B10: 45850 | C10: CUST1016 | D10: PROD56 | E10: STORE4 | F10: 2 | G10: 785.31 | H10: 0.15 | I10: PayPal | J10: 1335.027 | L10: SALE6 | M10: 45850 | N10: CUST1016 | O10: PROD56 | P10: STORE4 | Q10: 2 | R10: 785.31 | S10: 0.15 | T10: PayPal | U10: 1335.027 | W10: Sale6 | X10: 45850 | Y10: Cust1016 | Z10: Prod56 | AA10: Store4 | AB10: 2 | AC10: 785.31 | AD10: 0.15 | AE10: Paypal | AF10: 1335.027
A11: SALE7 | B11: 45248 | C11: CUST1152 | D11: PROD70 | E11: STORE8 | F11: 4 | G11: 342.39 | H11: 0.23 | I11: PayPal | J11: 1054.5612 | L11: SALE7 | M11: 45248 | N11: CUST1152 | O11: PROD70 | P11: STORE8 | Q11: 4 | R11: 342.39 | S11: 0.23 | T11: PayPal | U11: 1054.5612 | W11: Sale7 | X11: 45248 | Y11: Cust1152 | Z11: Prod70 | AA11: Store8 | AB11: 4 | AC11: 342.39 | AD11: 0.23 | AE11: Paypal | AF11: 1054.5612
A12: SALE8 | B12: 45781 | C12: CUST1187 | D12: PROD99 | E12: STORE5 | G12: 448.25 | H12: 0.07 | I12: PayPal | J12: 1250.6175 | L12: SALE8 | M12: 45781 | N12: CUST1187 | O12: PROD99 | P12: STORE5 | R12: 448.25 | S12: 0.07 | T12: PayPal | U12: 1250.6175 | W12: Sale8 | X12: 45781 | Y12: Cust1187 | Z12: Prod99 | AA12: Store5 | AC12: 448.25 | AD12: 0.07 | AE12: Paypal | AF12: 1250.6175
A13: SALE9 | B13: 45869 | C13: CUST1464 | D13: PROD33 | E13: STORE0 | F13: 2 | G13: 873.17 | H13: 0.23 | I13: PayPal | J13: 1344.6818 | L13: SALE9 | M13: 45869 | N13: CUST1464 | O13: PROD33 | P13: STORE0 | Q13: 2 | R13: 873.17 | S13: 0.23 | T13: PayPal | U13: 1344.6818 | W13: Sale9 | X13: 45869 | Y13: Cust1464 | Z13: Prod33 | AA13: Store0 | AB13: 2 | AC13: 873.17 | AD13: 0.23 | AE13: Paypal | AF13: 1344.6818
A14: SALE10 | B14: 45335 | C14: CUST1065 | D14: PROD24 | E14: STORE14 | F14: 1 | G14: 278.63 | H14: 0.07 | I14: Credit Card | J14: 259.1259 | L14: SALE10 | M14: 45335 | N14: CUST1065 | O14: PROD24 | P14: STORE14 | Q14: 1 | R14: 278.63 | S14: 0.07 | T14: Credit Card | U14: 259.1259 | W14: Sale10 | X14: 45335 | Y14: Cust1065 | Z14: Prod24 | AA14: Store14 | AB14: 1 | AC14: 278.63 | AD14: 0.07 | AE14: Credit Card | AF14: 259.1259
A15: SALE11 | B15: 45801 | C15: CUST1320 | D15: PROD39 | E15: STORE1 | F15: 4 | G15: 286.92 | H15: 0.17 | I15: Credit Card | J15: 952.5744 | L15: SALE11 | M15: 45801 | N15: CUST1320 | O15: PROD39 | P15: STORE1 | Q15: 4 | R15: 286.92 | S15: 0.17 | T15: Credit Card | U15: 952.5744 | W15: Sale11 | X15: 45801 | Y15: Cust1320 | Z15: Prod39 | AA15: Store1 | AB15: 4 | AC15: 286.92 | AD15: 0.17 | AE15: Credit Card | AF15: 952.5744
A16: SALE12 | B16: 45528 | C16: CUST1237 | D16: PROD88 | E16: STORE4 | F16: 4 | G16: 644.58 | H16: 0.01 | I16: Credit Card | J16: 2552.5368 | L16: SALE12 | M16: 45528 | N16: CUST1237 | O16: PROD88 | P16: STORE4 | Q16: 4 | R16: 644.58 | S16: 0.01 | T16: Credit Card | U16: 2552.5368 | W16: Sale12 | X16: 45528 | Y16: Cust1237 | Z16: Prod88 | AA16: Store4 | AB16: 4 | AC16: 644.58 | AD16: 0.01 | AE16: Credit Card | AF16: 2552.5368
A17: SALE13 | B17: 45875 | C17: CUST1443 | D17: PROD34 | E17: STORE16 | F17: 2 | G17: 316.9 | H17: 0.3 | I17: PayPal | J17: 443.66 | L17: SALE13 | M17: 45875 | N17: CUST1443 | O17: PROD34 | P17: STORE16 | Q17: 2 | R17: 316.9 | S17: 0.3 | T17: PayPal | U17: 443.66 | W17: Sale13 | X17: 45875 | Y17: Cust1443 | Z17: Prod34 | AA17: Store16 | AB17: 2 | AC17: 316.9 | AD17: 0.3 | AE17: Paypal | AF17: 443.66
A18: SALE14 | B18: 45829 | C18: CUST1348 | D18: PROD24 | E18: STORE15 | F18: 4 | G18: 403.47 | H18: 0.29 | I18: PayPal | J18: 1145.8548 | L18: SALE14 | M18: 45829 | N18: CUST1348 | O18: PROD24 | P18: STORE15 | Q18: 4 | R18: 403.47 | S18: 0.29 | T18: PayPal | U18: 1145.8548 | W18: Sale14 | X18: 45829 | Y18: Cust1348 | Z18: Prod24 | AA18: Store15 | AB18: 4 | AC18: 403.47 | AD18: 0.29 | AE18: Paypal | AF18: 1145.8548
A19: SALE15 | B19: 45636 | C19: CUST1435 | D19: PROD36 | E19: STORE9 | G19: 871.34 | H19: 0.04 | I19: COD | J19: 2509.4592 | L19: SALE15 | M19: 45636 | N19: CUST1435 | O19: PROD36 | P19: STORE9 | R19: 871.34 | S19: 0.04 | T19: COD | U19: 2509.4592 | W19: Sale15 | X19: 45636 | Y19: Cust1435 | Z19: Prod36 | AA19: Store9 | AC19: 871.34 | AD19: 0.04 | AE19: Cod | AF19: 2509.4592
A20: SALE16 | B20: 45913 | C20: CUST1276 | D20: PROD65 | E20: STORE19 | F20: 2 | G20: 451.98 | H20: 0.25 | I20: Credit Card | J20: 677.97 | L20: SALE16 | M20: 45913 | N20: CUST1276 | O20: PROD65 | P20: STORE19 | Q20: 2 | R20: 451.98 | S20: 0.25 | T20: Credit Card | U20: 677.97 | W20: Sale16 | X20: 45913 | Y20: Cust1276 | Z20: Prod65 | AA20: Store19 | AB20: 2 | AC20: 451.98 | AD20: 0.25 | AE20: Credit Card | AF20: 677.97
A21: SALE17 | B21: 45637 | C21: CUST1079 | D21: PROD27 | E21: STORE4 | F21: 2 | G21: 502.69 | H21: 0.23 | I21: Credit Card | J21: 774.1426 | L21: SALE17 | M21: 45637 | N21: CUST1079 | O21: PROD27 | P21: STORE4 | Q21: 2 | R21: 502.69 | S21: 0.23 | T21: Credit Card | U21: 774.1426 | W21: Sale17 | X21: 45637 | Y21: Cust1079 | Z21: Prod27 | AA21: Store4 | AB21: 2 | AC21: 502.69 | AD21: 0.23 | AE21: Credit Card | AF21: 774.1426
A22: SALE18 | B22: 45517 | C22: CUST1094 | D22: PROD39 | E22: STORE4 | F22: 2 | G22: 559.23 | H22: 0.25 | I22: COD | J22: 838.845 | L22: SALE18 | M22: 45517 | N22: CUST1094 | O22: PROD39 | P22: STORE4 | Q22: 2 | R22: 559.23 | S22: 0.25 | T22: COD | U22: 838.845 | W22: Sale18 | X22: 45517 | Y22: Cust1094 | Z22: Prod39 | AA22: Store4 | AB22: 2 | AC22: 559.23 | AD22: 0.25 | AE22: Cod | AF22: 838.845
A23: SALE19 | B23: 45369 | C23: CUST1239 | D23: PROD60 | E23: STORE13 | F23: 4 | H23: 0.04 | I23: COD | J23: 1782.4512 | L23: SALE19 | M23: 45369 | N23: CUST1239 | O23: PROD60 | P23: STORE13 | Q23: 4 | S23: 0.04 | T23: COD | U23: 1782.4512 | W23: Sale19 | X23: 45369 | Y23: Cust1239 | Z23: Prod60 | AA23: Store13 | AB23: 4 | AD23: 0.04 | AE23: Cod | AF23: 1782.4512
A24: SALE20 | B24: 45843 | C24: CUST1144 | D24: PROD72 | E24: STORE17 | F24: 3 | G24: 986.04 | H24: 0.27 | I24: COD | J24: 2159.4276 | L24: SALE20 | M24: 45843 | N24: CUST1144 | O24: PROD72 | P24: STORE17 | Q24: 3 | R24: 986.04 | S24: 0.27 | T24: COD | U24: 2159.4276 | W24: Sale20 | X24: 45843 | Y24: Cust1144 | Z24: Prod72 | AA24: Store17 | AB24: 3 | AC24: 986.04 | AD24: 0.27 | AE24: Cod | AF24: 2159.4276
A25: SALE21 | B25: 45447 | C25: CUST1396 | D25: PROD43 | E25: STORE18 | F25: 1 | G25: 589.56 | H25: 0.22 | I25: Credit Card | J25: 459.8568 | L25: SALE21 | M25: 45447 | N25: CUST1396 | O25: PROD43 | P25: STORE18 | Q25: 1 | R25: 589.56 | S25: 0.22 | T25: Credit Card | U25: 459.8568 | W25: Sale21 | X25: 45447 | Y25: Cust1396 | Z25: Prod43 | AA25: Store18 | AB25: 1 | AC25: 589.56 | AD25: 0.22 | AE25: Credit Card | AF25: 459.8568
A26: SALE22 | B26: 45394 | C26: CUST1476 | D26: PROD69 | E26: STORE10 | F26: 3 | G26: 979.42 | H26: 0.03 | I26: PayPal | J26: 2850.1122 | L26: SALE22 | M26: 45394 | N26: CUST1476 | O26: PROD69 | P26: STORE10 | Q26: 3 | R26: 979.42 | S26: 0.03 | T26: PayPal | U26: 2850.1122 | W26: Sale22 | X26: 45394 | Y26: Cust1476 | Z26: Prod69 | AA26: Store10 | AB26: 3 | AC26: 979.42 | AD26: 0.03 | AE26: Paypal | AF26: 2850.1122
A27: SALE23 | B27: 45466 | C27: CUST1368 | D27: PROD12 | E27: STORE8 | F27: 1 | G27: 719.28 | H27: 0.08 | I27: Credit Card | J27: 661.7376 | L27: SALE23 | M27: 45466 | N27: CUST1368 | O27: PROD12 | P27: STORE8 | Q27: 1 | R27: 719.28 | S27: 0.08 | T27: Credit Card | U27: 661.7376 | W27: Sale23 | X27: 45466 | Y27: Cust1368 | Z27: Prod12 | AA27: Store8 | AB27: 1 | AC27: 719.28 | AD27: 0.08 | AE27: Credit Card | AF27: 661.7376
A28: SALE24 | B28: 45908 | C28: CUST1186 | D28: PROD67 | E28: STORE6 | F28: 3 | G28: 77.6 | H28: 0.07 | I28: Credit Card | J28: 216.504 | L28: SALE24 | M28: 45908 | N28: CUST1186 | O28: PROD67 | P28: STORE6 | Q28: 3 | R28: 77.6 | S28: 0.07 | T28: Credit Card | U28: 216.504 | W28: Sale24 | X28: 45908 | Y28: Cust1186 | Z28: Prod67 | AA28: Store6 | AB28: 3 | AC28: 77.6 | AD28: 0.07 | AE28: Credit Card | AF28: 216.504
A29: SALE25 | B29: 45552 | C29: CUST1381 | D29: PROD5 | E29: STORE3 | F29: 4 | G29: 852.71 | H29: 0.14 | I29: PayPal | J29: 2933.3224 | L29: SALE25 | M29: 45552 | N29: CUST1381 | O29: PROD5 | P29: STORE3 | Q29: 4 | R29: 852.71 | S29: 0.14 | T29: PayPal | U29: 2933.3224 | W29: Sale25 | X29: 45552 | Y29: Cust1381 | Z29: Prod5 | AA29: Store3 | AB29: 4 | AC29: 852.71 | AD29: 0.14 | AE29: Paypal | AF29: 2933.3224
A30: SALE26 | B30: 45294 | C30: CUST1213 | D30: PROD98 | E30: STORE8 | F30: 4 | G30: 156.16 | I30: Credit Card | J30: 599.6544 | L30: SALE26 | M30: 45294 | N30: CUST1213 | O30: PROD98 | P30: STORE8 | Q30: 4 | R30: 156.16 | T30: Credit Card | U30: 599.6544 | W30: Sale26 | X30: 45294 | Y30: Cust1213 | Z30: Prod98 | AA30: Store8 | AB30: 4 | AC30: 156.16 | AE30: Credit Card | AF30: 599.6544
A31: SALE27 | B31: 45710 | C31: CUST1200 | D31: PROD77 | E31: STORE8 | F31: 3 | G31: 815.49 | H31: 0.17 | I31: Credit Card | J31: 2030.5701 | L31: SALE27 | M31: 45710 | N31: CUST1200 | O31: PROD77 | P31: STORE8 | Q31: 3 | R31: 815.49 | S31: 0.17 | T31: Credit Card | U31: 2030.5701 | W31: Sale27 | X31: 45710 | Y31: Cust1200 | Z31: Prod77 | AA31: Store8 | AB31: 3 | AC31: 815.49 | AD31: 0.17 | AE31: Credit Card | AF31: 2030.5701
A32: SALE28 | B32: 45923 | C32: CUST1148 | D32: PROD13 | E32: STORE2 | F32: 2 | G32: 74.21 | H32: 0.11 | I32: PayPal | J32: 132.0938 | L32: SALE28 | M32: 45923 | N32: CUST1148 | O32: PROD13 | P32: STORE2 | Q32: 2 | R32: 74.21 | S32: 0.11 | T32: PayPal | U32: 132.0938 | W32: Sale28 | X32: 45923 | Y32: Cust1148 | Z32: Prod13 | AA32: Store2 | AB32: 2 | AC32: 74.21 | AD32: 0.11 | AE32: Paypal | AF32: 132.0938
A33: SALE29 | B33: 45302 | C33: CUST1348 | D33: PROD99 | E33: STORE3 | G33: 451.67 | H33: 0.15 | I33: Credit Card | J33: 1535.678 | L33: SALE29 | M33: 45302 | N33: CUST1348 | O33: PROD99 | P33: STORE3 | R33: 451.67 | S33: 0.15 | T33: Credit Card | U33: 1535.678 | W33: Sale29 | X33: 45302 | Y33: Cust1348 | Z33: Prod99 | AA33: Store3 | AC33: 451.67 | AD33: 0.15 | AE33: Credit Card | AF33: 1535.678
A34: SALE30 | B34: 45217 | C34: CUST1028 | D34: PROD5 | E34: STORE19 | F34: 1 | G34: 429.38 | H34: 0.13 | I34: PayPal | J34: 373.5606 | L34: SALE30 | M34: 45217 | N34: CUST1028 | O34: PROD5 | P34: STORE19 | Q34: 1 | R34: 429.38 | S34: 0.13 | T34: PayPal | U34: 373.5606 | W34: Sale30 | X34: 45217 | Y34: Cust1028 | Z34: Prod5 | AA34: Store19 | AB34: 1 | AC34: 429.38 | AD34: 0.13 | AE34: Paypal | AF34: 373.5606
A35: SALE31 | B35: 45593 | C35: CUST1412 | D35: PROD53 | E35: STORE12 | F35: 2 | G35: 148.96 | H35: 0.03 | I35: COD | J35: 288.9824 | L35: SALE31 | M35: 45593 | N35: CUST1412 | O35: PROD53 | P35: STORE12 | Q35: 2 | R35: 148.96 | S35: 0.03 | T35: COD | U35: 288.9824 | W35: Sale31 | X35: 45593 | Y35: Cust1412 | Z35: Prod53 | AA35: Store12 | AB35: 2 | AC35: 148.96 | AD35: 0.03 | AE35: Cod | AF35: 288.9824
A36: SALE32 | B36: 45597 | C36: CUST1398 | D36: PROD75 | E36: STORE8 | F36: 4 | G36: 313.83 | H36: 0.08 | I36: Credit Card | J36: 1154.8944 | L36: SALE32 | M36: 45597 | N36: CUST1398 | O36: PROD75 | P36: STORE8 | Q36: 4 | R36: 313.83 | S36: 0.08 | T36: Credit Card | U36: 1154.8944 | W36: Sale32 | X36: 45597 | Y36: Cust1398 | Z36: Prod75 | AA36: Store8 | AB36: 4 | AC36: 313.83 | AD36: 0.08 | AE36: Credit Card | AF36: 1154.8944
A37: SALE33 | B37: 45620 | C37: CUST1453 | D37: PROD12 | E37: STORE6 | F37: 2 | G37: 717.31 | H37: 0.15 | I37: Credit Card | J37: 1219.427 | L37: SALE33 | M37: 45620 | N37: CUST1453 | O37: PROD12 | P37: STORE6 | Q37: 2 | R37: 717.31 | S37: 0.15 | T37: Credit Card | U37: 1219.427 | W37: Sale33 | X37: 45620 | Y37: Cust1453 | Z37: Prod12 | AA37: Store6 | AB37: 2 | AC37: 717.31 | AD37: 0.15 | AE37: Credit Card | AF37: 1219.427
A38: SALE34 | B38: 45215 | C38: CUST1344 | D38: PROD79 | E38: STORE1 | G38: 873.22 | H38: 0.18 | I38: Credit Card | J38: 2148.1212 | L38: SALE34 | M38: 45215 | N38: CUST1344 | O38: PROD79 | P38: STORE1 | R38: 873.22 | S38: 0.18 | T38: Credit Card | U38: 2148.1212 | W38: Sale34 | X38: 45215 | Y38: Cust1344 | Z38: Prod79 | AA38: Store1 | AC38: 873.22 | AD38: 0.18 | AE38: Credit Card | AF38: 2148.1212
A39: SALE35 | B39: 45878 | C39: CUST1218 | D39: PROD16 | E39: STORE3 | F39: 4 | G39: 109.36 | H39: 0.19 | I39: COD | J39: 354.3264 | L39: SALE35 | M39: 45878 | N39: CUST1218 | O39: PROD16 | P39: STORE3 | Q39: 4 | R39: 109.36 | S39: 0.19 | T39: COD | U39: 354.3264 | W39: Sale35 | X39: 45878 | Y39: Cust1218 | Z39: Prod16 | AA39: Store3 | AB39: 4 | AC39: 109.36 | AD39: 0.19 | AE39: Cod | AF39: 354.3264
A40: SALE36 | B40: 45635 | C40: CUST1086 | D40: PROD5 | E40: STORE7 | F40: 3 | G40: 559.52 | H40: 0.16 | I40: PayPal | J40: 1409.9904 | L40: SALE36 | M40: 45635 | N40: CUST1086 | O40: PROD5 | P40: STORE7 | Q40: 3 | R40: 559.52 | S40: 0.16 | T40: PayPal | U40: 1409.9904 | W40: Sale36 | X40: 45635 | Y40: Cust1086 | Z40: Prod5 | AA40: Store7 | AB40: 3 | AC40: 559.52 | AD40: 0.16 | AE40: Paypal | AF40: 1409.9904
A41: SALE37 | B41: 45329 | C41: CUST1492 | D41: PROD10 | E41: STORE17 | F41: 3 | G41: 121.76 | H41: 0.27 | I41: PayPal | J41: 266.6544 | L41: SALE37 | M41: 45329 | N41: CUST1492 | O41: PROD10 | P41: STORE17 | Q41: 3 | R41: 121.76 | S41: 0.27 | T41: PayPal | U41: 266.6544 | W41: Sale37 | X41: 45329 | Y41: Cust1492 | Z41: Prod10 | AA41: Store17 | AB41: 3 | AC41: 121.76 | AD41: 0.27 | AE41: Paypal | AF41: 266.6544
...

Sheet f Excel formulas for calculatio
A1: Sales_ID | B1: Order_Date | C1: Customer_ID | D1: Product_ID | E1: Store_ID | F1: Quantity | G1: Unit_Price | H1: Discount | I1: Payment_Type | J1: Total_Amount
A2: SALE0 | B2: 45480 | C2: CUST1409 | D2: PROD97 | E2: STORE3 | F2: 1 | G2: 218.04 | H2: 0.09 | I2: Credit Card | J2: 198.4164
A3: SALE1 | B3: 45285 | C3: CUST1467 | D3: PROD74 | E3: STORE17 | F3: 3 | G3: 104.47 | H3: 0.27 | I3: PayPal | J3: 228.7893
A4: SALE2 | B4: 45446 | C4: CUST1056 | D4: PROD49 | E4: STORE8 | F4: 4 | G4: 914.05 | H4: 0.25 | I4: Credit Card | J4: 2742.15
A5: SALE3 | B5: 45259 | C5: CUST1346 | D5: PROD76 | E5: STORE8 | F5: 1 | G5: 921.51 | H5: 0.16 | I5: COD | J5: 774.0684
A6: SALE4 | B6: 45297 | C6: CUST1493 | D6: PROD59 | E6: STORE5 | F6: 3 | G6: 745.3 | H6: 0.18 | I6: Credit Card | J6: 1833.438
A7: SALE5 | B7: 45499 | C7: CUST1116 | D7: PROD15 | E7: STORE7 | F7: 3 | G7: 147.01 | H7: 0.19 | I7: COD | J7: 357.2343
A8: SALE6 | B8: 45850 | C8: CUST1016 | D8: PROD56 | E8: STORE4 | F8: 2 | G8: 785.31 | H8: 0.15 | I8: PayPal | J8: 1335.027
A9: SALE7 | B9: 45248 | C9: CUST1152 | D9: PROD70 | E9: STORE8 | F9: 4 | G9: 342.39 | H9: 0.23 | I9: PayPal | J9: 1054.5612
A10: SALE8 | B10: 45781 | C10: CUST1187 | D10: PROD99 | E10: STORE5 | G10: 448.25 | H10: 0.07 | I10: PayPal | J10: 1250.6175
A11: SALE9 | B11: 45869 | C11: CUST1464 | D11: PROD33 | E11: STORE0 | F11: 2 | G11: 873.17 | H11: 0.23 | I11: PayPal | J11: 1344.6818
A12: SALE10 | B12: 45335 | C12: CUST1065 | D12: PROD24 | E12: STORE14 | F12: 1 | G12: 278.63 | H12: 0.07 | I12: Credit Card | J12: 259.1259
A13: SALE11 | B13: 45801 | C13: CUST1320 | D13: PROD39 | E13: STORE1 | F13: 4 | G13: 286.92 | H13: 0.17 | I13: Credit Card | J13: 952.5744
A14: SALE12 | B14: 45528 | C14: CUST1237 | D14: PROD88 | E14: STORE4 | F14: 4 | G14: 644.58 | H14: 0.01 | I14: Credit Card | J14: 2552.5368
A15: SALE13 | B15: 45875 | C15: CUST1443 | D15: PROD34 | E15: STORE16 | F15: 2 | G15: 316.9 | H15: 0.3 | I15: PayPal | J15: 443.66
A16: SALE14 | B16: 45829 | C16: CUST1348 | D16: PROD24 | E16: STORE15 | F16: 4 | G16: 403.47 | H16: 0.29 | I16: PayPal | J16: 1145.8548
A17: SALE15 | B17: 45636 | C17: CUST1435 | D17: PROD36 | E17: STORE9 | G17: 871.34 | H17: 0.04 | I17: COD | J17: 2509.4592
A18: SALE16 | B18: 45913 | C18: CUST1276 | D18: PROD65 | E18: STORE19 | F18: 2 | G18: 451.98 | H18: 0.25 | I18: Credit Card | J18: 677.97
A19: SALE17 | B19: 45637 | C19: CUST1079 | D19: PROD27 | E19: STORE4 | F19: 2 | G19: 502.69 | H19: 0.23 | I19: Credit Card | J19: 774.1426
A20: SALE18 | B20: 45517 | C20: CUST1094 | D20: PROD39 | E20: STORE4 | F20: 2 | G20: 559.23 | H20: 0.25 | I20: COD | J20: 838.845
A21: SALE19 | B21: 45369 | C21: CUST1239 | D21: PROD60 | E21: STORE13 | F21: 4 | H21: 0.04 | I21: COD | J21: 1782.4512
A22: SALE20 | B22: 45843 | C22: CUST1144 | D22: PROD72 | E22: STORE17 | F22: 3 | G22: 986.04 | H22: 0.27 | I22: COD | J22: 2159.4276
A23: SALE21 | B23: 45447 | C23: CUST1396 | D23: PROD43 | E23: STORE18 | F23: 1 | G23: 589.56 | H23: 0.22 | I23: Credit Card | J23: 459.8568
A24: SALE22 | B24: 45394 | C24: CUST1476 | D24: PROD69 | E24: STORE10 | F24: 3 | G24: 979.42 | H24: 0.03 | I24: PayPal | J24: 2850.1122
A25: SALE23 | B25: 45466 | C25: CUST1368 | D25: PROD12 | E25: STORE8 | F25: 1 | G25: 719.28 | H25: 0.08 | I25: Credit Card | J25: 661.7376
A26: SALE24 | B26: 45908 | C26: CUST1186 | D26: PROD67 | E26: STORE6 | F26: 3 | G26: 77.6 | H26: 0.07 | I26: Credit Card | J26: 216.504
A27: SALE25 | B27: 45552 | C27: CUST1381 | D27: PROD5 | E27: STORE3 | F27: 4 | G27: 852.71 | H27: 0.14 | I27: PayPal | J27: 2933.3224
A28: SALE26 | B28: 45294 | C28: CUST1213 | D28: PROD98 | E28: STORE8 | F28: 4 | G28: 156.16 | I28: Credit Card | J28: 599.6544
A29: SALE27 | B29: 45710 | C29: CUST1200 | D29: PROD77 | E29: STORE8 | F29: 3 | G29: 815.49 | H29: 0.17 | I29: Credit Card | J29: 2030.5701
A30: SALE28 | B30: 45923 | C30: CUST1148 | D30: PROD13 | E30: STORE2 | F30: 2 | G30: 74.21 | H30: 0.11 | I30: PayPal | J30: 132.0938
A31: SALE29 | B31: 45302 | C31: CUST1348 | D31: PROD99 | E31: STORE3 | G31: 451.67 | H31: 0.15 | I31: Credit Card | J31: 1535.678
A32: SALE30 | B32: 45217 | C32: CUST1028 | D32: PROD5 | E32: STORE19 | F32: 1 | G32: 429.38 | H32: 0.13 | I32: PayPal | J32: 373.5606
A33: SALE31 | B33: 45593 | C33: CUST1412 | D33: PROD53 | E33: STORE12 | F33: 2 | G33: 148.96 | H33: 0.03 | I33: COD | J33: 288.9824
A34: SALE32 | B34: 45597 | C34: CUST1398 | D34: PROD75 | E34: STORE8 | F34: 4 | G34: 313.83 | H34: 0.08 | I34: Credit Card | J34: 1154.8944
A35: SALE33 | B35: 45620 | C35: CUST1453 | D35: PROD12 | E35: STORE6 | F35: 2 | G35: 717.31 | H35: 0.15 | I35: Credit Card | J35: 1219.427
A36: SALE34 | B36: 45215 | C36: CUST1344 | D36: PROD79 | E36: STORE1 | G36: 873.22 | H36: 0.18 | I36: Credit Card | J36: 2148.1212
A37: SALE35 | B37: 45878 | C37: CUST1218 | D37: PROD16 | E37: STORE3 | F37: 4 | G37: 109.36 | H37: 0.19 | I37: COD | J37: 354.3264
A38: SALE36 | B38: 45635 | C38: CUST1086 | D38: PROD5 | E38: STORE7 | F38: 3 | G38: 559.52 | H38: 0.16 | I38: PayPal | J38: 1409.9904
A39: SALE37 | B39: 45329 | C39: CUST1492 | D39: PROD10 | E39: STORE17 | F39: 3 | G39: 121.76 | H39: 0.27 | I39: PayPal | J39: 266.6544
A40: SALE38 | B40: 45378 | C40: CUST1189 | D40: PROD33 | E40: STORE13 | F40: 4 | G40: 735.32 | H40: 0.06 | I40: COD | J40: 2764.8032
...

Sheet  XLOOKUP VLOOKUP 
A1: Vlookup | L1: Xlookup
A2: Sales_ID | B2: Order_Date | C2: Customer_ID | D2: Product_ID | E2: Store_ID | F2: Quantity | G2: Unit_Price | H2: Discount | I2: Payment_Type | J2: Total_Amount | L2: Sales_ID | M2: Order_Date | N2: Customer_ID | O2: Product_ID | P2: Store_ID | Q2: Quantity | R2: Unit_Price | S2: Discount | T2: Payment_Type | U2: Total_Amount
A3: SALE0 | B3: =IFERROR(VLOOKUP(A3,'f Excel formulas for calculatio'!A:E,2,FALSE)," ") -> 45480 | C3: =IFERROR(VLOOKUP(B3,'f Excel formulas for calculatio'!B:F,2,FALSE),"0") -> CUST1409 | D3: =IFERROR(VLOOKUP(C3,'f Excel formulas for calculatio'!C:G,2,FALSE),"0") -> PROD97 | E3: =IFERROR(VLOOKUP(D3,'f Excel formulas for calculatio'!D:H,2,FALSE),"0") -> STORE3 | F3: =IFERROR(VLOOKUP(E3,'f Excel formulas for calculatio'!E:I,2,FALSE),"0") -> 1 | G3: =IFERROR(VLOOKUP(F3,'f Excel formulas for calculatio'!F:J,2,FALSE),"0") -> 218.04 | H3: =IFERROR(VLOOKUP(G3,'f Excel formulas for calculatio'!G:K,2,FALSE),"0") -> 0.09 | I3: =IFERROR(VLOOKUP(H3,'f Excel formulas for calculatio'!H:L,2,FALSE),"0") -> Credit Card | J3: =IFERROR(VLOOKUP(I3,'f Excel formulas for calculatio'!I:M,2,FALSE),"0") -> 198.4164 | L3: SALE0 | M3: =_xlfn.XLOOKUP(L3,A3,B3) -> 45480 | N3: =_xlfn.XLOOKUP(M3,B3,C3) -> CUST1409 | O3: =_xlfn.XLOOKUP(N3,C3,D3) -> PROD97 | P3: =_xlfn.XLOOKUP(O3,D3,E3) -> STORE3 | Q3: =_xlfn.XLOOKUP(P3,E3,F3) -> 1 | R3: =_xlfn.XLOOKUP(Q3,F3,G3) -> 218.04 | S3: =_xlfn.XLOOKUP(R3,G3,H3) -> 0.09 | T3: =_xlfn.XLOOKUP(S3,H3,I3) -> Credit Card | U3: =_xlfn.XLOOKUP(T3,I3,J3) -> 198.4164
A4: SALE1 | B4: =IFERROR(VLOOKUP(A4,'f Excel formulas for calculatio'!A:E,2,FALSE)," ") -> 45285 | C4: =IFERROR(VLOOKUP(B4,'f Excel formulas for calculatio'!B:F,2,FALSE),"0") -> CUST1467 | D4: =IFERROR(VLOOKUP(C4,'f Excel formulas for calculatio'!C:G,2,FALSE),"0") -> PROD74 | E4: =IFERROR(VLOOKUP(D4,'f Excel formulas for calculatio'!D:H,2,FALSE),"0") -> STORE17 | F4: =IFERROR(VLOOKUP(E4,'f Excel formulas for calculatio'!E:I,2,FALSE),"0") -> 3 | G4: =IFERROR(VLOOKUP(F4,'f Excel formulas for calculatio'!F:J,2,FALSE),"0") -> 104.47 | H4: =IFERROR(VLOOKUP(G4,'f Excel formulas for calculatio'!G:K,2,FALSE),"0") -> 0.27 | I4: =IFERROR(VLOOKUP(H4,'f Excel formulas for calculatio'!H:L,2,FALSE),"0") -> PayPal | J4: =IFERROR(VLOOKUP(I4,'f Excel formulas for calculatio'!I:M,2,FALSE),"0") -> 228.7893 | L4: SALE1 | M4: =_xlfn.XLOOKUP(L4,A4,B4) -> 45285 | N4: =_xlfn.XLOOKUP(M4,B4,C4) -> CUST1467 | O4: =_xlfn.XLOOKUP(N4,C4,D4) -> PROD74 | P4: =_xlfn.XLOOKUP(O4,D4,E4) -> STORE17 | Q4: =_xlfn.XLOOKUP(P4,E4,F4) -> 3 | R4: =_xlfn.XLOOKUP(Q4,F4,G4) -> 104.47 | S4: =_xlfn.XLOOKUP(R4,G4,H4) -> 0.27 | T4: =_xlfn.XLOOKUP(S4,H4,I4) -> PayPal | U4: =_xlfn.XLOOKUP(T4,I4,J4) -> 228.7893
A5: SALE2 | B5: =IFERROR(VLOOKUP(A5,'f Excel formulas for calculatio'!A:E,2,FALSE)," ") -> 45446 | C5: =IFERROR(VLOOKUP(B5,'f Excel formulas for calculatio'!B:F,2,FALSE),"0") -> CUST1056 | D5: =IFERROR(VLOOKUP(C5,'f Excel formulas for calculatio'!C:G,2,FALSE),"0") -> PROD49 | E5: =IFERROR(VLOOKUP(D5,'f Excel formulas for calculatio'!D:H,2,FALSE),"0") -> STORE8 | F5: =IFERROR(VLOOKUP(E5,'f Excel formulas for calculatio'!E:I,2,FALSE),"0") -> 4 | G5: =IFERROR(VLOOKUP(F5,'f Excel formulas for calculatio'!F:J,2,FALSE),"0") -> 914.05 | H5: =IFERROR(VLOOKUP(G5,'f Excel formulas for calculatio'!G:K,2,FALSE),"0") -> 0.25 | I5: =IFERROR(VLOOKUP(H5,'f Excel formulas for calculatio'!H:L,2,FALSE),"0") -> Credit Card | J5: =IFERROR(VLOOKUP(I5,'f Excel formulas for calculatio'!I:M,2,FALSE),"0") -> 198.4164 | L5: SALE2 | M5: =_xlfn.XLOOKUP(L5,A5,B5) -> 45446 | N5: =_xlfn.XLOOKUP(M5,B5,C5) -> CUST1056 | O5: =_xlfn.XLOOKUP(N5,C5,D5) -> PROD49 | P5: =_xlfn.XLOOKUP(O5,D5,E5) -> STORE8 | Q5: =_xlfn.XLOOKUP(P5,E5,F5) -> 4 | R5: =_xlfn.XLOOKUP(Q5,F5,G5) -> 914.05 | S5: =_xlfn.XLOOKUP(R5,G5,H5) -> 0.25 | T5: =_xlfn.XLOOKUP(S5,H5,I5) -> Credit Card | U5: =_xlfn.XLOOKUP(T5,I5,J5) -> 198.4164
A6: SALE3 | B6: =IFERROR(VLOOKUP(A6,'f Excel formulas for calculatio'!A:E,2,FALSE)," ") -> 45259 | C6: =IFERROR(VLOOKUP(B6,'f Excel formulas for calculatio'!B:F,2,FALSE),"0") -> CUST1346 | D6: =IFERROR(VLOOKUP(C6,'f Excel formulas for calculatio'!C:G,2,FALSE),"0") -> PROD76 | E6: =IFERROR(VLOOKUP(D6,'f Excel formulas for calculatio'!D:H,2,FALSE),"0") -> STORE8 | F6: =IFERROR(VLOOKUP(E6,'f Excel formulas for calculatio'!E:I,2,FALSE),"0") -> 4 | G6: =IFERROR(VLOOKUP(F6,'f Excel formulas for calculatio'!F:J,2,FALSE),"0") -> 914.05 | H6: =IFERROR(VLOOKUP(G6,'f Excel formulas for calculatio'!G:K,2,FALSE),"0") -> 0.25 | I6: =IFERROR(VLOOKUP(H6,'f Excel formulas for calculatio'!H:L,2,FALSE),"0") -> Credit Card | J6: =IFERROR(VLOOKUP(I6,'f Excel formulas for calculatio'!I:M,2,FALSE),"0") -> 198.4164 | L6: SALE3 | M6: =_xlfn.XLOOKUP(L6,A6,B6) -> 45259 | N6: =_xlfn.XLOOKUP(M6,B6,C6) -> CUST1346 | O6: =_xlfn.XLOOKUP(N6,C6,D6) -> PROD76 | P6: =_xlfn.XLOOKUP(O6,D6,E6) -> STORE8 | Q6: =_xlfn.XLOOKUP(P6,E6,F6) -> 4 | R6: =_xlfn.XLOOKUP(Q6,F6,G6) -> 914.05 | S6: =_xlfn.XLOOKUP(R6,G6,H6) -> 0.25 | T6: =_xlfn.XLOOKUP(S6,H6,I6) -> Credit Card | U6: =_xlfn.XLOOKUP(T6,I6,J6) -> 198.4164
A7: SALE4 | B7: =IFERROR(VLOOKUP(A7,'f Excel formulas for calculatio'!A:E,2,FALSE)," ") -> 45297 | C7: =IFERROR(VLOOKUP(B7,'f Excel formulas for calculatio'!B:F,2,FALSE),"0") -> CUST1493 | D7: =IFERROR(VLOOKUP(C7,'f Excel formulas for calculatio'!C:G,2,FALSE),"0") -> PROD59 | E7: =IFERROR(VLOOKUP(D7,'f Excel formulas for calculatio'!D:H,2,FALSE),"0") -> STORE5 | F7: =IFERROR(VLOOKUP(E7,'f Excel formulas for calculatio'!E:I,2,FALSE),"0") -> 3 | G7: =IFERROR(VLOOKUP(F7,'f Excel formulas for calculatio'!F:J,2,FALSE),"0") -> 104.47 | H7: =IFERROR(VLOOKUP(G7,'f Excel formulas for calculatio'!G:K,2,FALSE),"0") -> 0.27 | I7: =IFERROR(VLOOKUP(H7,'f Excel formulas for calculatio'!H:L,2,FALSE),"0") -> PayPal | J7: =IFERROR(VLOOKUP(I7,'f Excel formulas for calculatio'!I:M,2,FALSE),"0") -> 228.7893 | L7: SALE4 | M7: =_xlfn.XLOOKUP(L7,A7,B7) -> 45297 | N7: =_xlfn.XLOOKUP(M7,B7,C7) -> CUST1493 | O7: =_xlfn.XLOOKUP(N7,C7,D7) -> PROD59 | P7: =_xlfn.XLOOKUP(O7,D7,E7) -> STORE5 | Q7: =_xlfn.XLOOKUP(P7,E7,F7) -> 3 | R7: =_xlfn.XLOOKUP(Q7,F7,G7) -> 104.47 | S7: =_xlfn.XLOOKUP(R7,G7,H7) -> 0.27 | T7: =_xlfn.XLOOKUP(S7,H7,I7) -> PayPal | U7: =_xlfn.XLOOKUP(T7,I7,J7) -> 228.7893
A8: SALE5 | B8: =IFERROR(VLOOKUP(A8,'f Excel formulas for calculatio'!A:E,2,FALSE)," ") -> 45499 | C8: =IFERROR(VLOOKUP(B8,'f Excel formulas for calculatio'!B:F,2,FALSE),"0") -> CUST1116 | D8: =IFERROR(VLOOKUP(C8,'f Excel formulas for calculatio'!C:G,2,FALSE),"0") -> PROD15 | E8: =IFERROR(VLOOKUP(D8,'f Excel formulas for calculatio'!D:H,2,FALSE),"0") -> STORE7 | F8: =IFERROR(VLOOKUP(E8,'f Excel formulas for calculatio'!E:I,2,FALSE),"0") -> 3 | G8: =IFERROR(VLOOKUP(F8,'f Excel formulas for calculatio'!F:J,2,FALSE),"0") -> 104.47 | H8: =IFERROR(VLOOKUP(G8,'f Excel formulas for calculatio'!G:K,2,FALSE),"0") -> 0.27 | I8: =IFERROR(VLOOKUP(H8,'f Excel formulas for calculatio'!H:L,2,FALSE),"0") -> PayPal | J8: =IFERROR(VLOOKUP(I8,'f Excel formulas for calculatio'!I:M,2,FALSE),"0") -> 228.7893 | L8: SALE5 | M8: =_xlfn.XLOOKUP(L8,A8,B8) -> 45499 | N8: =_xlfn.XLOOKUP(M8,B8,C8) -> CUST1116 | O8: =_xlfn.XLOOKUP(N8,C8,D8) -> PROD15 | P8: =_xlfn.XLOOKUP(O8,D8,E8) -> STORE7 | Q8: =_xlfn.XLOOKUP(P8,E8,F8) -> 3 | R8: =_xlfn.XLOOKUP(Q8,F8,G8) -> 104.47 | S8: =_xlfn.XLOOKUP(R8,G8,H8) -> 0.27 | T8: =_xlfn.XLOOKUP(S8,H8,I8) -> PayPal | U8: =_xlfn.XLOOKUP(T8,I8,J8) -> 228.7893
A9: SALE6 | B9: =IFERROR(VLOOKUP(A9,'f Excel formulas for calculatio'!A:E,2,FALSE)," ") -> 45850 | C9: =IFERROR(VLOOKUP(B9,'f Excel formulas for calculatio'!B:F,2,FALSE),"0") -> CUST1016 | D9: =IFERROR(VLOOKUP(C9,'f Excel formulas for calculatio'!C:G,2,FALSE),"0") -> PROD56 | E9: =IFERROR(VLOOKUP(D9,'f Excel formulas for calculatio'!D:H,2,FALSE),"0") -> STORE4 | F9: =IFERROR(VLOOKUP(E9,'f Excel formulas for calculatio'!E:I,2,FALSE),"0") -> 2 | G9: =IFERROR(VLOOKUP(F9,'f Excel formulas for calculatio'!F:J,2,FALSE),"0") -> 785.31 | H9: =IFERROR(VLOOKUP(G9,'f Excel formulas for calculatio'!G:K,2,FALSE),"0") -> 0.15 | I9: =IFERROR(VLOOKUP(H9,'f Excel formulas for calculatio'!H:L,2,FALSE),"0") -> PayPal | J9: =IFERROR(VLOOKUP(I9,'f Excel formulas for calculatio'!I:M,2,FALSE),"0") -> 228.7893 | L9: SALE6 | M9: =_xlfn.XLOOKUP(L9,A9,B9) -> 45850 | N9: =_xlfn.XLOOKUP(M9,B9,C9) -> CUST1016 | O9: =_xlfn.XLOOKUP(N9,C9,D9) -> PROD56 | P9: =_xlfn.XLOOKUP(O9,D9,E9) -> STORE4 | Q9: =_xlfn.XLOOKUP(P9,E9,F9) -> 2 | R9: =_xlfn.XLOOKUP(Q9,F9,G9) -> 785.31 | S9: =_xlfn.XLOOKUP(R9,G9,H9) -> 0.15 | T9: =_xlfn.XLOOKUP(S9,H9,I9) -> PayPal | U9: =_xlfn.XLOOKUP(T9,I9,J9) -> 228.7893
A10: SALE7 | B10: =IFERROR(VLOOKUP(A10,'f Excel formulas for calculatio'!A:E,2,FALSE)," ") -> 45248 | C10: =IFERROR(VLOOKUP(B10,'f Excel formulas for calculatio'!B:F,2,FALSE),"0") -> CUST1152 | D10: =IFERROR(VLOOKUP(C10,'f Excel formulas for calculatio'!C:G,2,FALSE),"0") -> PROD70 | E10: =IFERROR(VLOOKUP(D10,'f Excel formulas for calculatio'!D:H,2,FALSE),"0") -> STORE8 | F10: =IFERROR(VLOOKUP(E10,'f Excel formulas for calculatio'!E:I,2,FALSE),"0") -> 4 | G10: =IFERROR(VLOOKUP(F10,'f Excel formulas for calculatio'!F:J,2,FALSE),"0") -> 914.05 | H10: =IFERROR(VLOOKUP(G10,'f Excel formulas for calculatio'!G:K,2,FALSE),"0") -> 0.25 | I10: =IFERROR(VLOOKUP(H10,'f Excel formulas for calculatio'!H:L,2,FALSE),"0") -> Credit Card | J10: =IFERROR(VLOOKUP(I10,'f Excel formulas for calculatio'!I:M,2,FALSE),"0") -> 198.4164 | L10: SALE7 | M10: =_xlfn.XLOOKUP(L10,A10,B10) -> 45248 | N10: =_xlfn.XLOOKUP(M10,B10,C10) -> CUST1152 | O10: =_xlfn.XLOOKUP(N10,C10,D10) -> PROD70 | P10: =_xlfn.XLOOKUP(O10,D10,E10) -> STORE8 | Q10: =_xlfn.XLOOKUP(P10,E10,F10) -> 4 | R10: =_xlfn.XLOOKUP(Q10,F10,G10) -> 914.05 | S10: =_xlfn.XLOOKUP(R10,G10,H10) -> 0.25 | T10: =_xlfn.XLOOKUP(S10,H10,I10) -> Credit Card | U10: =_xlfn.XLOOKUP(T10,I10,J10) -> 198.4164
A11: SALE8 | B11: =IFERROR(VLOOKUP(A11,'f Excel formulas for calculatio'!A:E,2,FALSE)," ") -> 45781 | C11: =IFERROR(VLOOKUP(B11,'f Excel formulas for calculatio'!B:F,2,FALSE),"0") -> CUST1187 | D11: =IFERROR(VLOOKUP(C11,'f Excel formulas for calculatio'!C:G,2,FALSE),"0") -> PROD99 | E11: =IFERROR(VLOOKUP(D11,'f Excel formulas for calculatio'!D:H,2,FALSE),"0") -> STORE5 | F11: =IFERROR(VLOOKUP(E11,'f Excel formulas for calculatio'!E:I,2,FALSE),"0") -> 3 | G11: =IFERROR(VLOOKUP(F11,'f Excel formulas for calculatio'!F:J,2,FALSE),"0") -> 104.47 | H11: =IFERROR(VLOOKUP(G11,'f Excel formulas for calculatio'!G:K,2,FALSE),"0") -> 0.27 | I11: =IFERROR(VLOOKUP(H11,'f Excel formulas for calculatio'!H:L,2,FALSE),"0") -> PayPal | J11: =IFERROR(VLOOKUP(I11,'f Excel formulas for calculatio'!I:M,2,FALSE),"0") -> 228.7893 | L11: SALE8 | M11: =_xlfn.XLOOKUP(L11,A11,B11) -> 45781 | N11: =_xlfn.XLOOKUP(M11,B11,C11) -> CUST1187 | O11: =_xlfn.XLOOKUP(N11,C11,D11) -> PROD99 | P11: =_xlfn.XLOOKUP(O11,D11,E11) -> STORE5 | Q11: =_xlfn.XLOOKUP(P11,E11,F11) -> 3 | R11: =_xlfn.XLOOKUP(Q11,F11,G11) -> 104.47 | S11: =_xlfn.XLOOKUP(R11,G11,H11) -> 0.27 | T11: =_xlfn.XLOOKUP(S11,H11,I11) -> PayPal | U11: =_xlfn.XLOOKUP(T11,I11,J11) -> 228.7893
A12: SALE9 | B12: =IFERROR(VLOOKUP(A12,'f Excel formulas for calculatio'!A:E,2,FALSE)," ") -> 45869 | C12: =IFERROR(VLOOKUP(B12,'f Excel formulas for calculatio'!B:F,2,FALSE),"0") -> CUST1464 | D12: =IFERROR(VLOOKUP(C12,'f Excel formulas for calculatio'!C:G,2,FALSE),"0") -> PROD33 | E12: =IFERROR(VLOOKUP(D12,'f Excel formulas for calculatio'!D:H,2,FALSE),"0") -> STORE0 | F12: =IFERROR(VLOOKUP(E12,'f Excel formulas for calculatio'!E:I,2,FALSE),"0") -> 2 | G12: =IFERROR(VLOOKUP(F12,'f Excel formulas for calculatio'!F:J,2,FALSE),"0") -> 785.31 | H12: =IFERROR(VLOOKUP(G12,'f Excel formulas for calculatio'!G:K,2,FALSE),"0") -> 0.15 | I12: =IFERROR(VLOOKUP(H12,'f Excel formulas for calculatio'!H:L,2,FALSE),"0") -> PayPal | J12: =IFERROR(VLOOKUP(I12,'f Excel formulas for calculatio'!I:M,2,FALSE),"0") -> 228.7893 | L12: SALE9 | M12: =_xlfn.XLOOKUP(L12,A12,B12) -> 45869 | N12: =_xlfn.XLOOKUP(M12,B12,C12) -> CUST1464 | O12: =_xlfn.XLOOKUP(N12,C12,D12) -> PROD33 | P12: =_xlfn.XLOOKUP(O12,D12,E12) -> STORE0 | Q12: =_xlfn.XLOOKUP(P12,E12,F12) -> 2 | R12: =_xlfn.XLOOKUP(Q12,F12,G12) -> 785.31 | S12: =_xlfn.XLOOKUP(R12,G12,H12) -> 0.15 | T12: =_xlfn.XLOOKUP(S12,H12,I12) -> PayPal | U12: =_xlfn.XLOOKUP(T12,I12,J12) -> 228.7893
A13: SALE10 | B13: =IFERROR(VLOOKUP(A13,'f Excel formulas for calculatio'!A:E,2,FALSE)," ") -> 45335 | C13: =IFERROR(VLOOKUP(B13,'f Excel formulas for calculatio'!B:F,2,FALSE),"0") -> CUST1065 | D13: =IFERROR(VLOOKUP(C13,'f Excel formulas for calculatio'!C:G,2,FALSE),"0") -> PROD24 | E13: =IFERROR(VLOOKUP(D13,'f Excel formulas for calculatio'!D:H,2,FALSE),"0") -> STORE14 | F13: =IFERROR(VLOOKUP(E13,'f Excel formulas for calculatio'!E:I,2,FALSE),"0") -> 1 | G13: =IFERROR(VLOOKUP(F13,'f Excel formulas for calculatio'!F:J,2,FALSE),"0") -> 218.04 | H13: =IFERROR(VLOOKUP(G13,'f Excel formulas for calculatio'!G:K,2,FALSE),"0") -> 0.09 | I13: =IFERROR(VLOOKUP(H13,'f Excel formulas for calculatio'!H:L,2,FALSE),"0") -> Credit Card | J13: =IFERROR(VLOOKUP(I13,'f Excel formulas for calculatio'!I:M,2,FALSE),"0") -> 198.4164 | L13: SALE10 | M13: =_xlfn.XLOOKUP(L13,A13,B13) -> 45335 | N13: =_xlfn.XLOOKUP(M13,B13,C13) -> CUST1065 | O13: =_xlfn.XLOOKUP(N13,C13,D13) -> PROD24 | P13: =_xlfn.XLOOKUP(O13,D13,E13) -> STORE14 | Q13: =_xlfn.XLOOKUP(P13,E13,F13) -> 1 | R13: =_xlfn.XLOOKUP(Q13,F13,G13) -> 218.04 | S13: =_xlfn.XLOOKUP(R13,G13,H13) -> 0.09 | T13: =_xlfn.XLOOKUP(S13,H13,I13) -> Credit Card | U13: =_xlfn.XLOOKUP(T13,I13,J13) -> 198.4164
A14: SALE11 | B14: =IFERROR(VLOOKUP(A14,'f Excel formulas for calculatio'!A:E,2,FALSE)," ") -> 45801 | C14: =IFERROR(VLOOKUP(B14,'f Excel formulas for calculatio'!B:F,2,FALSE),"0") -> CUST1320 | D14: =IFERROR(VLOOKUP(C14,'f Excel formulas for calculatio'!C:G,2,FALSE),"0") -> PROD39 | E14: =IFERROR(VLOOKUP(D14,'f Excel formulas for calculatio'!D:H,2,FALSE),"0") -> STORE1 | F14: =IFERROR(VLOOKUP(E14,'f Excel formulas for calculatio'!E:I,2,FALSE),"0") -> 4 | G14: =IFERROR(VLOOKUP(F14,'f Excel formulas for calculatio'!F:J,2,FALSE),"0") -> 914.05 | H14: =IFERROR(VLOOKUP(G14,'f Excel formulas for calculatio'!G:K,2,FALSE),"0") -> 0.25 | I14: =IFERROR(VLOOKUP(H14,'f Excel formulas for calculatio'!H:L,2,FALSE),"0") -> Credit Card | J14: =IFERROR(VLOOKUP(I14,'f Excel formulas for calculatio'!I:M,2,FALSE),"0") -> 198.4164 | L14: SALE11 | M14: =_xlfn.XLOOKUP(L14,A14,B14) -> 45801 | N14: =_xlfn.XLOOKUP(M14,B14,C14) -> CUST1320 | O14: =_xlfn.XLOOKUP(N14,C14,D14) -> PROD39 | P14: =_xlfn.XLOOKUP(O14,D14,E14) -> STORE1 | Q14: =_xlfn.XLOOKUP(P14,E14,F14) -> 4 | R14: =_xlfn.XLOOKUP(Q14,F14,G14) -> 914.05 | S14: =_xlfn.XLOOKUP(R14,G14,H14) -> 0.25 | T14: =_xlfn.XLOOKUP(S14,H14,I14) -> Credit Card | U14: =_xlfn.XLOOKUP(T14,I14,J14) -> 198.4164
... A2002: SALE1999 | B2002: =IFERROR(VLOOKUP(A2002,'f Excel formulas for calculatio'!A:E,2,FALSE)," ") -> 45267 | C2002: =IFERROR(VLOOKUP(B2002,'f Excel formulas for calculatio'!B:F,2,FALSE),"0") -> CUST1344 | D2002: =IFERROR(VLOOKUP(C2002,'f Excel formulas for calculatio'!C:G,2,FALSE),"0") -> PROD79 | E2002: =IFERROR(VLOOKUP(D2002,'f Excel formulas for calculatio'!D:H,2,FALSE),"0") -> STORE1 | F2002: =IFERROR(VLOOKUP(E2002,'f Excel formulas for calculatio'!E:I,2,FALSE),"0") -> 4 | G2002: =IFERROR(VLOOKUP(F2002,'f Excel formulas for calculatio'!F:J,2,FALSE),"0") -> 914.05 | H2002: =IFERROR(VLOOKUP(G2002,'f Excel formulas for calculatio'!G:K,2,FALSE),"0") -> 0.25 | I2002: =IFERROR(VLOOKUP(H2002,'f Excel formulas for calculatio'!H:L,2,FALSE),"0") -> Credit Card | J2002: =IFERROR(VLOOKUP(I2002,'f Excel formulas for calculatio'!I:M,2,FALSE),"0") -> 198.4164 | L2002: SALE1999 | M2002: =_xlfn.XLOOKUP(L2002,A2002,B2002) -> 45267 | N2002: =_xlfn.XLOOKUP(M2002,B2002,C2002) -> CUST1344 | O2002: =_xlfn.XLOOKUP(N2002,C2002,D2002) -> PROD79 | P2002: =_xlfn.XLOOKUP(O2002,D2002,E2002) -> STORE1 | Q2002: =_xlfn.XLOOKUP(P2002,E2002,F2002) -> 4 | R2002: =_xlfn.XLOOKUP(Q2002,F2002,G2002) -> 914.05 | S2002: =_xlfn.XLOOKUP(R2002,G2002,H2002) -> 0.25 | T2002: =_xlfn.XLOOKUP(S2002,H2002,I2002) -> Credit Card | U2002: =_xlfn.XLOOKUP(T2002,I2002,J2002) -> 198.4164

Sheet pivot table
A1: Row Labels | B1: Sum of Total_Amount | C1: Sum of Quantity | D1: Sum of Discount
A2: COD | B2: 701525.29 | C2: 1642 | D2: 98.03
A3: Credit Card | B3: 713754.93 | C3: 1614 | D3: 96.73
A4: PayPal | B4: 755627.24 | C4: 1692 | D4: 100.82
A5: Grand Total | B5: 2170907.5 | C5: 4948 | D5: 295.58

Sheet Descriptive statistics
A1: Sales_ID | B1: Order_Date | C1: Customer_ID | D1: Product_ID | E1: Store_ID | F1: Quantity | G1: Unit_Price | H1: Discount | I1: Payment_Type | J1: Total_Amount
A2: SALE0 | B2: 45480 | C2: CUST1409 | D2: PROD97 | E2: STORE3 | F2: 1 | G2: 218.04 | H2: 0.09 | I2: Credit Card | J2: 198.4164 | L2: Quantity | O2: Total_Amount
A3: SALE1 | B3: 45285 | C3: CUST1467 | D3: PROD74 | E3: STORE17 | F3: 3 | G3: 104.47 | H3: 0.27 | I3: PayPal | J3: 228.7893
A4: SALE2 | B4: 45446 | C4: CUST1056 | D4: PROD49 | E4: STORE8 | F4: 4 | G4: 914.05 | H4: 0.25 | I4: Credit Card | J4: 2742.15 | L4: Mean | M4: 2.4802005 | O4: Mean | P4: 1087.629
A5: SALE3 | B5: 45259 | C5: CUST1346 | D5: PROD76 | E5: STORE8 | F5: 1 | G5: 921.51 | H5: 0.16 | I5: COD | J5: 774.0684 | L5: Standard Error | M5: 0.024897726 | O5: Standard Error | P5: 18.356936
A6: SALE4 | B6: 45297 | C6: CUST1493 | D6: PROD59 | E6: STORE5 | F6: 3 | G6: 745.3 | H6: 0.18 | I6: Credit Card | J6: 1833.438 | L6: Median | M6: 2 | O6: Median | P6: 868.7182
A7: SALE5 | B7: 45499 | C7: CUST1116 | D7: PROD15 | E7: STORE7 | F7: 3 | G7: 147.01 | H7: 0.19 | I7: COD | J7: 357.2343 | L7: Mode | M7: 2 | O7: Mode | P7: #N/A
A8: SALE6 | B8: 45850 | C8: CUST1016 | D8: PROD56 | E8: STORE4 | F8: 2 | G8: 785.31 | H8: 0.15 | I8: PayPal | J8: 1335.027 | L8: Standard Deviation | M8: 1.1120675 | O8: Standard Deviation | P8: 820.12576
A9: SALE7 | B9: 45248 | C9: CUST1152 | D9: PROD70 | E9: STORE8 | F9: 4 | G9: 342.39 | H9: 0.23 | I9: PayPal | J9: 1054.5612 | L9: Sample Variance | M9: 1.236694 | O9: Sample Variance | P9: 672606.27
A10: SALE8 | B10: 45781 | C10: CUST1187 | D10: PROD99 | E10: STORE5 | G10: 448.25 | H10: 0.07 | I10: PayPal | J10: 1250.6175 | L10: Kurtosis | M10: -1.3454153 | O10: Kurtosis | P10: 0.041826531
A11: SALE9 | B11: 45869 | C11: CUST1464 | D11: PROD33 | E11: STORE0 | F11: 2 | G11: 873.17 | H11: 0.23 | I11: PayPal | J11: 1344.6818 | L11: Skewness | M11: 0.025776009 | O11: Skewness | P11: 0.87824016
A12: SALE10 | B12: 45335 | C12: CUST1065 | D12: PROD24 | E12: STORE14 | F12: 1 | G12: 278.63 | H12: 0.07 | I12: Credit Card | J12: 259.1259 | L12: Range | M12: 3 | O12: Range | P12: 3889.7838
A13: SALE11 | B13: 45801 | C13: CUST1320 | D13: PROD39 | E13: STORE1 | F13: 4 | G13: 286.92 | H13: 0.17 | I13: Credit Card | J13: 952.5744 | L13: Minimum | M13: 1 | O13: Minimum | P13: 18.459
A14: SALE12 | B14: 45528 | C14: CUST1237 | D14: PROD88 | E14: STORE4 | F14: 4 | G14: 644.58 | H14: 0.01 | I14: Credit Card | J14: 2552.5368 | L14: Maximum | M14: 4 | O14: Maximum | P14: 3908.2428
A15: SALE13 | B15: 45875 | C15: CUST1443 | D15: PROD34 | E15: STORE16 | F15: 2 | G15: 316.9 | H15: 0.3 | I15: PayPal | J15: 443.66 | L15: Sum | M15: 4948 | O15: Sum | P15: 2170907.5
A16: SALE14 | B16: 45829 | C16: CUST1348 | D16: PROD24 | E16: STORE15 | F16: 4 | G16: 403.47 | H16: 0.29 | I16: PayPal | J16: 1145.8548 | L16: Count | M16: 1995 | O16: Count | P16: 1996
A17: SALE15 | B17: 45636 | C17: CUST1435 | D17: PROD36 | E17: STORE9 | G17: 871.34 | H17: 0.04 | I17: COD | J17: 2509.4592
A18: SALE16 | B18: 45913 | C18: CUST1276 | D18: PROD65 | E18: STORE19 | F18: 2 | G18: 451.98 | H18: 0.25 | I18: Credit Card | J18: 677.97 | L18: Unit_Price
A19: SALE17 | B19: 45637 | C19: CUST1079 | D19: PROD27 | E19: STORE4 | F19: 2 | G19: 502.69 | H19: 0.23 | I19: Credit Card | J19: 774.1426
A20: SALE18 | B20: 45517 | C20: CUST1094 | D20: PROD39 | E20: STORE4 | F20: 2 | G20: 559.23 | H20: 0.25 | I20: COD | J20: 838.845 | L20: Mean | M20: 513.98477
A21: SALE19 | B21: 45369 | C21: CUST1239 | D21: PROD60 | E21: STORE13 | F21: 4 | H21: 0.04 | I21: COD | J21: 1782.4512 | L21: Standard Error | M21: 6.3172736
A22: SALE20 | B22: 45843 | C22: CUST1144 | D22: PROD72 | E22: STORE17 | F22: 3 | G22: 986.04 | H22: 0.27 | I22: COD | J22: 2159.4276 | L22: Median | M22: 522.72
A23: SALE21 | B23: 45447 | C23: CUST1396 | D23: PROD43 | E23: STORE18 | F23: 1 | G23: 589.56 | H23: 0.22 | I23: Credit Card | J23: 459.8568 | L23: Mode | M23: 871.34
A24: SALE22 | B24: 45394 | C24: CUST1476 | D24: PROD69 | E24: STORE10 | F24: 3 | G24: 979.42 | H24: 0.03 | I24: PayPal | J24: 2850.1122 | L24: Standard Deviation | M24: 282.3051
A25: SALE23 | B25: 45466 | C25: CUST1368 | D25: PROD12 | E25: STORE8 | F25: 1 | G25: 719.28 | H25: 0.08 | I25: Credit Card | J25: 661.7376 | L25: Sample Variance | M25: 79696.168
A26: SALE24 | B26: 45908 | C26: CUST1186 | D26: PROD67 | E26: STORE6 | F26: 3 | G26: 77.6 | H26: 0.07 | I26: Credit Card | J26: 216.504 | L26: Kurtosis | M26: -1.1924285
A27: SALE25 | B27: 45552 | C27: CUST1381 | D27: PROD5 | E27: STORE3 | F27: 4 | G27: 852.71 | H27: 0.14 | I27: PayPal | J27: 2933.3224 | L27: Skewness | M27: -0.036741245
A28: SALE26 | B28: 45294 | C28: CUST1213 | D28: PROD98 | E28: STORE8 | F28: 4 | G28: 156.16 | I28: Credit Card | J28: 599.6544 | L28: Range | M28: 979.8
A29: SALE27 | B29: 45710 | C29: CUST1200 | D29: PROD77 | E29: STORE8 | F29: 3 | G29: 815.49 | H29: 0.17 | I29: Credit Card | J29: 2030.5701 | L29: Minimum | M29: 20.09
A30: SALE28 | B30: 45923 | C30: CUST1148 | D30: PROD13 | E30: STORE2 | F30: 2 | G30: 74.21 | H30: 0.11 | I30: PayPal | J30: 132.0938 | L30: Maximum | M30: 999.89
A31: SALE29 | B31: 45302 | C31: CUST1348 | D31: PROD99 | E31: STORE3 | G31: 451.67 | H31: 0.15 | I31: Credit Card | J31: 1535.678 | L31: Sum | M31: 1026427.6
A32: SALE30 | B32: 45217 | C32: CUST1028 | D32: PROD5 | E32: STORE19 | F32: 1 | G32: 429.38 | H32: 0.13 | I32: PayPal | J32: 373.5606 | L32: Count | M32: 1997
A33: SALE31 | B33: 45593 | C33: CUST1412 | D33: PROD53 | E33: STORE12 | F33: 2 | G33: 148.96 | H33: 0.03 | I33: COD | J33: 288.9824
A34: SALE32 | B34: 45597 | C34: CUST1398 | D34: PROD75 | E34: STORE8 | F34: 4 | G34: 313.83 | H34: 0.08 | I34: Credit Card | J34: 1154.8944
A35: SALE33 | B35: 45620 | C35: CUST1453 | D35: PROD12 | E35: STORE6 | F35: 2 | G35: 717.31 | H35: 0.15 | I35: Credit Card | J35: 1219.427
A36: SALE34 | B36: 45215 | C36: CUST1344 | D36: PROD79 | E36: STORE1 | G36: 873.22 | H36: 0.18 | I36: Credit Card | J36: 2148.1212
A37: SALE35 | B37: 45878 | C37: CUST1218 | D37: PROD16 | E37: STORE3 | F37: 4 | G37: 109.36 | H37: 0.19 | I37: COD | J37: 354.3264
A38: SALE36 | B38: 45635 | C38: CUST1086 | D38: PROD5 | E38: STORE7 | F38: 3 | G38: 559.52 | H38: 0.16 | I38: PayPal | J38: 1409.9904
A39: SALE37 | B39: 45329 | C39: CUST1492 | D39: PROD10 | E39: STORE17 | F39: 3 | G39: 121.76 | H39: 0.27 | I39: PayPal | J39: 266.6544
A40: SALE38 | B40: 45378 | C40: CUST1189 | D40: PROD33 | E40: STORE13 | F40: 4 | G40: 735.32 | H40: 0.06 | I40: COD | J40: 2764.8032
...

Sheet ●Data visualization
